INFO:root:Cola Vacia
INFO:apscheduler.executors.default:Job "job (trigger: interval[0:00:40], next run at: 2022-02-28 16:24:45 CST)" executed successfully
INFO:apscheduler.executors.default:Running job "job (trigger: interval[0:00:40], next run at: 2022-02-28 16:25:25 CST)" (scheduled at 2022-02-28 16:24:45.251714-06:00)
INFO:root:Cola Vacia
INFO:apscheduler.executors.default:Job "job (trigger: interval[0:00:40], next run at: 2022-02-28 16:25:25 CST)" executed successfully
INFO:apscheduler.executors.default:Running job "job (trigger: interval[0:00:40], next run at: 2022-02-28 16:26:05 CST)" (scheduled at 2022-02-28 16:25:25.251714-06:00)
INFO:root:Cola Vacia
INFO:apscheduler.executors.default:Job "job (trigger: interval[0:00:40], next run at: 2022-02-28 16:26:05 CST)" executed successfully
INFO:apscheduler.executors.default:Running job "job (trigger: interval[0:00:40], next run at: 2022-02-28 16:26:45 CST)" (scheduled at 2022-02-28 16:26:05.251714-06:00)
INFO:root:Cola Vacia
INFO:apscheduler.executors.default:Job "job (trigger: interval[0:00:40], next run at: 2022-02-28 16:26:45 CST)" executed successfully
INFO:apscheduler.executors.default:Running job "job (trigger: interval[0:00:40], next run at: 2022-02-28 16:27:25 CST)" (scheduled at 2022-02-28 16:26:45.251714-06:00)
INFO:root:Cola Vacia
INFO:apscheduler.executors.default:Job "job (trigger: interval[0:00:40], next run at: 2022-02-28 16:27:25 CST)" executed successfully
INFO:apscheduler.executors.default:Running job "job (trigger: interval[0:00:40], next run at: 2022-02-28 16:28:05 CST)" (scheduled at 2022-02-28 16:27:25.251714-06:00)
INFO:root:Cola Vacia
INFO:apscheduler.executors.default:Job "job (trigger: interval[0:00:40], next run at: 2022-02-28 16:28:05 CST)" executed successfully
INFO:werkzeug: * Detected change in '/home/roberto/Documents/Lytica/vico-analytics-server/src/apis/acquisition_api.py', reloading
INFO:root:Cola Vacia
INFO:apscheduler.executors.default:Job "job (trigger: interval[0:00:40], next run at: 2022-02-28 16:29:22 CST)" executed successfully
INFO:werkzeug: * Detected change in '/home/roberto/Documents/Lytica/vico-analytics-server/src/apis/acquisition_api.py', reloading
INFO:root:Empty queue
INFO:apscheduler.executors.default:Job "job (trigger: interval[0:00:40], next run at: 2022-02-28 16:30:27 CST)" executed successfully
INFO:werkzeug: * Detected change in '/home/roberto/Documents/Lytica/vico-analytics-server/app.py', reloading
INFO:root:Empty queue
INFO:root:Empty queue
INFO:root:Empty queue
INFO:root:Empty queue
INFO:root:Empty queue
INFO:root:Empty queue
INFO:root:Empty queue
INFO:root:Empty queue
INFO:root:Empty queue
INFO:root:Empty queue
INFO:root:Empty queue
INFO:root:Empty queue
INFO:root:Empty queue
INFO:root:Empty queue
INFO:root:Empty queue
INFO:root:Empty queue
INFO:root:Empty queue
INFO:root:Empty queue
INFO:root:Empty queue
INFO:root:Empty queue
INFO:root:Empty queue
INFO:root:Empty queue
INFO:werkzeug: * Running on http://127.0.0.1:5000/ (Press CTRL+C to quit)
INFO:werkzeug: * Restarting with stat
INFO:werkzeug:127.0.0.1 - - [28/Feb/2022 17:00:59] "[35m[1mPOST /acquisition/visitor-counter/ HTTP/1.1[0m" 500 -
ERROR:werkzeug:Error on request:
Traceback (most recent call last):
  File "/home/roberto/.cache/pypoetry/virtualenvs/vico-analytics-server-GoRiLKSi-py3.8/lib/python3.8/site-packages/urllib3/connection.py", line 174, in _new_conn
    conn = connection.create_connection(
  File "/home/roberto/.cache/pypoetry/virtualenvs/vico-analytics-server-GoRiLKSi-py3.8/lib/python3.8/site-packages/urllib3/util/connection.py", line 72, in create_connection
    for res in socket.getaddrinfo(host, port, family, socket.SOCK_STREAM):
  File "/usr/lib/python3.8/socket.py", line 918, in getaddrinfo
    for res in _socket.getaddrinfo(host, port, family, type, proto, flags):
socket.gaierror: [Errno -3] Temporary failure in name resolution

During handling of the above exception, another exception occurred:

Traceback (most recent call last):
  File "/home/roberto/.cache/pypoetry/virtualenvs/vico-analytics-server-GoRiLKSi-py3.8/lib/python3.8/site-packages/urllib3/connectionpool.py", line 703, in urlopen
    httplib_response = self._make_request(
  File "/home/roberto/.cache/pypoetry/virtualenvs/vico-analytics-server-GoRiLKSi-py3.8/lib/python3.8/site-packages/urllib3/connectionpool.py", line 386, in _make_request
    self._validate_conn(conn)
  File "/home/roberto/.cache/pypoetry/virtualenvs/vico-analytics-server-GoRiLKSi-py3.8/lib/python3.8/site-packages/urllib3/connectionpool.py", line 1040, in _validate_conn
    conn.connect()
  File "/home/roberto/.cache/pypoetry/virtualenvs/vico-analytics-server-GoRiLKSi-py3.8/lib/python3.8/site-packages/urllib3/connection.py", line 358, in connect
    conn = self._new_conn()
  File "/home/roberto/.cache/pypoetry/virtualenvs/vico-analytics-server-GoRiLKSi-py3.8/lib/python3.8/site-packages/urllib3/connection.py", line 186, in _new_conn
    raise NewConnectionError(
urllib3.exceptions.NewConnectionError: <urllib3.connection.HTTPSConnection object at 0x7fbc46d07790>: Failed to establish a new connection: [Errno -3] Temporary failure in name resolution

During handling of the above exception, another exception occurred:

Traceback (most recent call last):
  File "/home/roberto/.cache/pypoetry/virtualenvs/vico-analytics-server-GoRiLKSi-py3.8/lib/python3.8/site-packages/requests/adapters.py", line 440, in send
    resp = conn.urlopen(
  File "/home/roberto/.cache/pypoetry/virtualenvs/vico-analytics-server-GoRiLKSi-py3.8/lib/python3.8/site-packages/urllib3/connectionpool.py", line 785, in urlopen
    retries = retries.increment(
  File "/home/roberto/.cache/pypoetry/virtualenvs/vico-analytics-server-GoRiLKSi-py3.8/lib/python3.8/site-packages/urllib3/util/retry.py", line 592, in increment
    raise MaxRetryError(_pool, url, error or ResponseError(cause))
urllib3.exceptions.MaxRetryError: HTTPSConnectionPool(host='dev.vico.ai', port=443): Max retries exceeded with url: /acquisition/visitor-counter/ (Caused by NewConnectionError('<urllib3.connection.HTTPSConnection object at 0x7fbc46d07790>: Failed to establish a new connection: [Errno -3] Temporary failure in name resolution'))

During handling of the above exception, another exception occurred:

Traceback (most recent call last):
  File "/home/roberto/.cache/pypoetry/virtualenvs/vico-analytics-server-GoRiLKSi-py3.8/lib/python3.8/site-packages/werkzeug/serving.py", line 324, in run_wsgi
    execute(self.server.app)
  File "/home/roberto/.cache/pypoetry/virtualenvs/vico-analytics-server-GoRiLKSi-py3.8/lib/python3.8/site-packages/werkzeug/serving.py", line 313, in execute
    application_iter = app(environ, start_response)
  File "/home/roberto/.cache/pypoetry/virtualenvs/vico-analytics-server-GoRiLKSi-py3.8/lib/python3.8/site-packages/flask/app.py", line 2091, in __call__
    return self.wsgi_app(environ, start_response)
  File "/home/roberto/.cache/pypoetry/virtualenvs/vico-analytics-server-GoRiLKSi-py3.8/lib/python3.8/site-packages/flask/app.py", line 2076, in wsgi_app
    response = self.handle_exception(e)
  File "/home/roberto/.cache/pypoetry/virtualenvs/vico-analytics-server-GoRiLKSi-py3.8/lib/python3.8/site-packages/flask/app.py", line 2073, in wsgi_app
    response = self.full_dispatch_request()
  File "/home/roberto/.cache/pypoetry/virtualenvs/vico-analytics-server-GoRiLKSi-py3.8/lib/python3.8/site-packages/flask/app.py", line 1518, in full_dispatch_request
    rv = self.handle_user_exception(e)
  File "/home/roberto/.cache/pypoetry/virtualenvs/vico-analytics-server-GoRiLKSi-py3.8/lib/python3.8/site-packages/flask/app.py", line 1516, in full_dispatch_request
    rv = self.dispatch_request()
  File "/home/roberto/.cache/pypoetry/virtualenvs/vico-analytics-server-GoRiLKSi-py3.8/lib/python3.8/site-packages/flask/app.py", line 1502, in dispatch_request
    return self.ensure_sync(self.view_functions[rule.endpoint])(**req.view_args)
  File "/home/roberto/Documents/Lytica/vico-analytics-server/app.py", line 21, in main_acquisition
    response, status = cls_aquisition.main(data=payload_data, file_=payload_file, path=path)
  File "/home/roberto/Documents/Lytica/vico-analytics-server/src/apis/acquisition_api.py", line 80, in main
    response  = self.send_api_data(payload=data, path=path)
  File "/home/roberto/Documents/Lytica/vico-analytics-server/src/apis/acquisition_api.py", line 31, in send_api_data
    response = requests.post(url=url, files=payload,)
  File "/home/roberto/.cache/pypoetry/virtualenvs/vico-analytics-server-GoRiLKSi-py3.8/lib/python3.8/site-packages/requests/api.py", line 117, in post
    return request('post', url, data=data, json=json, **kwargs)
  File "/home/roberto/.cache/pypoetry/virtualenvs/vico-analytics-server-GoRiLKSi-py3.8/lib/python3.8/site-packages/requests/api.py", line 61, in request
    return session.request(method=method, url=url, **kwargs)
  File "/home/roberto/.cache/pypoetry/virtualenvs/vico-analytics-server-GoRiLKSi-py3.8/lib/python3.8/site-packages/requests/sessions.py", line 529, in request
    resp = self.send(prep, **send_kwargs)
  File "/home/roberto/.cache/pypoetry/virtualenvs/vico-analytics-server-GoRiLKSi-py3.8/lib/python3.8/site-packages/requests/sessions.py", line 645, in send
    r = adapter.send(request, **kwargs)
  File "/home/roberto/.cache/pypoetry/virtualenvs/vico-analytics-server-GoRiLKSi-py3.8/lib/python3.8/site-packages/requests/adapters.py", line 519, in send
    raise ConnectionError(e, request=request)
requests.exceptions.ConnectionError: HTTPSConnectionPool(host='dev.vico.ai', port=443): Max retries exceeded with url: /acquisition/visitor-counter/ (Caused by NewConnectionError('<urllib3.connection.HTTPSConnection object at 0x7fbc46d07790>: Failed to establish a new connection: [Errno -3] Temporary failure in name resolution'))
INFO:werkzeug:127.0.0.1 - - [28/Feb/2022 17:01:41] "[35m[1mPOST /acquisition/visitor-counter/ HTTP/1.1[0m" 500 -
ERROR:werkzeug:Error on request:
Traceback (most recent call last):
  File "/home/roberto/.cache/pypoetry/virtualenvs/vico-analytics-server-GoRiLKSi-py3.8/lib/python3.8/site-packages/urllib3/connection.py", line 174, in _new_conn
    conn = connection.create_connection(
  File "/home/roberto/.cache/pypoetry/virtualenvs/vico-analytics-server-GoRiLKSi-py3.8/lib/python3.8/site-packages/urllib3/util/connection.py", line 72, in create_connection
    for res in socket.getaddrinfo(host, port, family, socket.SOCK_STREAM):
  File "/usr/lib/python3.8/socket.py", line 918, in getaddrinfo
    for res in _socket.getaddrinfo(host, port, family, type, proto, flags):
socket.gaierror: [Errno -3] Temporary failure in name resolution

During handling of the above exception, another exception occurred:

Traceback (most recent call last):
  File "/home/roberto/.cache/pypoetry/virtualenvs/vico-analytics-server-GoRiLKSi-py3.8/lib/python3.8/site-packages/urllib3/connectionpool.py", line 703, in urlopen
    httplib_response = self._make_request(
  File "/home/roberto/.cache/pypoetry/virtualenvs/vico-analytics-server-GoRiLKSi-py3.8/lib/python3.8/site-packages/urllib3/connectionpool.py", line 386, in _make_request
    self._validate_conn(conn)
  File "/home/roberto/.cache/pypoetry/virtualenvs/vico-analytics-server-GoRiLKSi-py3.8/lib/python3.8/site-packages/urllib3/connectionpool.py", line 1040, in _validate_conn
    conn.connect()
  File "/home/roberto/.cache/pypoetry/virtualenvs/vico-analytics-server-GoRiLKSi-py3.8/lib/python3.8/site-packages/urllib3/connection.py", line 358, in connect
    conn = self._new_conn()
  File "/home/roberto/.cache/pypoetry/virtualenvs/vico-analytics-server-GoRiLKSi-py3.8/lib/python3.8/site-packages/urllib3/connection.py", line 186, in _new_conn
    raise NewConnectionError(
urllib3.exceptions.NewConnectionError: <urllib3.connection.HTTPSConnection object at 0x7fbc469d48b0>: Failed to establish a new connection: [Errno -3] Temporary failure in name resolution

During handling of the above exception, another exception occurred:

Traceback (most recent call last):
  File "/home/roberto/.cache/pypoetry/virtualenvs/vico-analytics-server-GoRiLKSi-py3.8/lib/python3.8/site-packages/requests/adapters.py", line 440, in send
    resp = conn.urlopen(
  File "/home/roberto/.cache/pypoetry/virtualenvs/vico-analytics-server-GoRiLKSi-py3.8/lib/python3.8/site-packages/urllib3/connectionpool.py", line 785, in urlopen
    retries = retries.increment(
  File "/home/roberto/.cache/pypoetry/virtualenvs/vico-analytics-server-GoRiLKSi-py3.8/lib/python3.8/site-packages/urllib3/util/retry.py", line 592, in increment
    raise MaxRetryError(_pool, url, error or ResponseError(cause))
urllib3.exceptions.MaxRetryError: HTTPSConnectionPool(host='dev.vico.ai', port=443): Max retries exceeded with url: /acquisition/visitor-counter/ (Caused by NewConnectionError('<urllib3.connection.HTTPSConnection object at 0x7fbc469d48b0>: Failed to establish a new connection: [Errno -3] Temporary failure in name resolution'))

During handling of the above exception, another exception occurred:

Traceback (most recent call last):
  File "/home/roberto/.cache/pypoetry/virtualenvs/vico-analytics-server-GoRiLKSi-py3.8/lib/python3.8/site-packages/werkzeug/serving.py", line 324, in run_wsgi
    execute(self.server.app)
  File "/home/roberto/.cache/pypoetry/virtualenvs/vico-analytics-server-GoRiLKSi-py3.8/lib/python3.8/site-packages/werkzeug/serving.py", line 313, in execute
    application_iter = app(environ, start_response)
  File "/home/roberto/.cache/pypoetry/virtualenvs/vico-analytics-server-GoRiLKSi-py3.8/lib/python3.8/site-packages/flask/app.py", line 2091, in __call__
    return self.wsgi_app(environ, start_response)
  File "/home/roberto/.cache/pypoetry/virtualenvs/vico-analytics-server-GoRiLKSi-py3.8/lib/python3.8/site-packages/flask/app.py", line 2076, in wsgi_app
    response = self.handle_exception(e)
  File "/home/roberto/.cache/pypoetry/virtualenvs/vico-analytics-server-GoRiLKSi-py3.8/lib/python3.8/site-packages/flask/app.py", line 2073, in wsgi_app
    response = self.full_dispatch_request()
  File "/home/roberto/.cache/pypoetry/virtualenvs/vico-analytics-server-GoRiLKSi-py3.8/lib/python3.8/site-packages/flask/app.py", line 1518, in full_dispatch_request
    rv = self.handle_user_exception(e)
  File "/home/roberto/.cache/pypoetry/virtualenvs/vico-analytics-server-GoRiLKSi-py3.8/lib/python3.8/site-packages/flask/app.py", line 1516, in full_dispatch_request
    rv = self.dispatch_request()
  File "/home/roberto/.cache/pypoetry/virtualenvs/vico-analytics-server-GoRiLKSi-py3.8/lib/python3.8/site-packages/flask/app.py", line 1502, in dispatch_request
    return self.ensure_sync(self.view_functions[rule.endpoint])(**req.view_args)
  File "/home/roberto/Documents/Lytica/vico-analytics-server/app.py", line 21, in main_acquisition
    response, status = cls_aquisition.main(data=payload_data, file_=payload_file, path=path)
  File "/home/roberto/Documents/Lytica/vico-analytics-server/src/apis/acquisition_api.py", line 80, in main
    response  = self.send_api_data(payload=data, path=path)
  File "/home/roberto/Documents/Lytica/vico-analytics-server/src/apis/acquisition_api.py", line 31, in send_api_data
    response = requests.post(url=url, files=payload,)
  File "/home/roberto/.cache/pypoetry/virtualenvs/vico-analytics-server-GoRiLKSi-py3.8/lib/python3.8/site-packages/requests/api.py", line 117, in post
    return request('post', url, data=data, json=json, **kwargs)
  File "/home/roberto/.cache/pypoetry/virtualenvs/vico-analytics-server-GoRiLKSi-py3.8/lib/python3.8/site-packages/requests/api.py", line 61, in request
    return session.request(method=method, url=url, **kwargs)
  File "/home/roberto/.cache/pypoetry/virtualenvs/vico-analytics-server-GoRiLKSi-py3.8/lib/python3.8/site-packages/requests/sessions.py", line 529, in request
    resp = self.send(prep, **send_kwargs)
  File "/home/roberto/.cache/pypoetry/virtualenvs/vico-analytics-server-GoRiLKSi-py3.8/lib/python3.8/site-packages/requests/sessions.py", line 645, in send
    r = adapter.send(request, **kwargs)
  File "/home/roberto/.cache/pypoetry/virtualenvs/vico-analytics-server-GoRiLKSi-py3.8/lib/python3.8/site-packages/requests/adapters.py", line 519, in send
    raise ConnectionError(e, request=request)
requests.exceptions.ConnectionError: HTTPSConnectionPool(host='dev.vico.ai', port=443): Max retries exceeded with url: /acquisition/visitor-counter/ (Caused by NewConnectionError('<urllib3.connection.HTTPSConnection object at 0x7fbc469d48b0>: Failed to establish a new connection: [Errno -3] Temporary failure in name resolution'))
INFO:werkzeug:127.0.0.1 - - [28/Feb/2022 17:02:37] "[35m[1mPOST /acquisition/visitor-counter/ HTTP/1.1[0m" 500 -
ERROR:werkzeug:Error on request:
Traceback (most recent call last):
  File "/home/roberto/.cache/pypoetry/virtualenvs/vico-analytics-server-GoRiLKSi-py3.8/lib/python3.8/site-packages/urllib3/connection.py", line 174, in _new_conn
    conn = connection.create_connection(
  File "/home/roberto/.cache/pypoetry/virtualenvs/vico-analytics-server-GoRiLKSi-py3.8/lib/python3.8/site-packages/urllib3/util/connection.py", line 72, in create_connection
    for res in socket.getaddrinfo(host, port, family, socket.SOCK_STREAM):
  File "/usr/lib/python3.8/socket.py", line 918, in getaddrinfo
    for res in _socket.getaddrinfo(host, port, family, type, proto, flags):
socket.gaierror: [Errno -3] Temporary failure in name resolution

During handling of the above exception, another exception occurred:

Traceback (most recent call last):
  File "/home/roberto/.cache/pypoetry/virtualenvs/vico-analytics-server-GoRiLKSi-py3.8/lib/python3.8/site-packages/urllib3/connectionpool.py", line 703, in urlopen
    httplib_response = self._make_request(
  File "/home/roberto/.cache/pypoetry/virtualenvs/vico-analytics-server-GoRiLKSi-py3.8/lib/python3.8/site-packages/urllib3/connectionpool.py", line 386, in _make_request
    self._validate_conn(conn)
  File "/home/roberto/.cache/pypoetry/virtualenvs/vico-analytics-server-GoRiLKSi-py3.8/lib/python3.8/site-packages/urllib3/connectionpool.py", line 1040, in _validate_conn
    conn.connect()
  File "/home/roberto/.cache/pypoetry/virtualenvs/vico-analytics-server-GoRiLKSi-py3.8/lib/python3.8/site-packages/urllib3/connection.py", line 358, in connect
    conn = self._new_conn()
  File "/home/roberto/.cache/pypoetry/virtualenvs/vico-analytics-server-GoRiLKSi-py3.8/lib/python3.8/site-packages/urllib3/connection.py", line 186, in _new_conn
    raise NewConnectionError(
urllib3.exceptions.NewConnectionError: <urllib3.connection.HTTPSConnection object at 0x7fbc469ea9a0>: Failed to establish a new connection: [Errno -3] Temporary failure in name resolution

During handling of the above exception, another exception occurred:

Traceback (most recent call last):
  File "/home/roberto/.cache/pypoetry/virtualenvs/vico-analytics-server-GoRiLKSi-py3.8/lib/python3.8/site-packages/requests/adapters.py", line 440, in send
    resp = conn.urlopen(
  File "/home/roberto/.cache/pypoetry/virtualenvs/vico-analytics-server-GoRiLKSi-py3.8/lib/python3.8/site-packages/urllib3/connectionpool.py", line 785, in urlopen
    retries = retries.increment(
  File "/home/roberto/.cache/pypoetry/virtualenvs/vico-analytics-server-GoRiLKSi-py3.8/lib/python3.8/site-packages/urllib3/util/retry.py", line 592, in increment
    raise MaxRetryError(_pool, url, error or ResponseError(cause))
urllib3.exceptions.MaxRetryError: HTTPSConnectionPool(host='dev.vico.ai', port=443): Max retries exceeded with url: /acquisition/visitor-counter/ (Caused by NewConnectionError('<urllib3.connection.HTTPSConnection object at 0x7fbc469ea9a0>: Failed to establish a new connection: [Errno -3] Temporary failure in name resolution'))

During handling of the above exception, another exception occurred:

Traceback (most recent call last):
  File "/home/roberto/.cache/pypoetry/virtualenvs/vico-analytics-server-GoRiLKSi-py3.8/lib/python3.8/site-packages/werkzeug/serving.py", line 324, in run_wsgi
    execute(self.server.app)
  File "/home/roberto/.cache/pypoetry/virtualenvs/vico-analytics-server-GoRiLKSi-py3.8/lib/python3.8/site-packages/werkzeug/serving.py", line 313, in execute
    application_iter = app(environ, start_response)
  File "/home/roberto/.cache/pypoetry/virtualenvs/vico-analytics-server-GoRiLKSi-py3.8/lib/python3.8/site-packages/flask/app.py", line 2091, in __call__
    return self.wsgi_app(environ, start_response)
  File "/home/roberto/.cache/pypoetry/virtualenvs/vico-analytics-server-GoRiLKSi-py3.8/lib/python3.8/site-packages/flask/app.py", line 2076, in wsgi_app
    response = self.handle_exception(e)
  File "/home/roberto/.cache/pypoetry/virtualenvs/vico-analytics-server-GoRiLKSi-py3.8/lib/python3.8/site-packages/flask/app.py", line 2073, in wsgi_app
    response = self.full_dispatch_request()
  File "/home/roberto/.cache/pypoetry/virtualenvs/vico-analytics-server-GoRiLKSi-py3.8/lib/python3.8/site-packages/flask/app.py", line 1518, in full_dispatch_request
    rv = self.handle_user_exception(e)
  File "/home/roberto/.cache/pypoetry/virtualenvs/vico-analytics-server-GoRiLKSi-py3.8/lib/python3.8/site-packages/flask/app.py", line 1516, in full_dispatch_request
    rv = self.dispatch_request()
  File "/home/roberto/.cache/pypoetry/virtualenvs/vico-analytics-server-GoRiLKSi-py3.8/lib/python3.8/site-packages/flask/app.py", line 1502, in dispatch_request
    return self.ensure_sync(self.view_functions[rule.endpoint])(**req.view_args)
  File "/home/roberto/Documents/Lytica/vico-analytics-server/app.py", line 21, in main_acquisition
    response, status = cls_aquisition.main(data=payload_data, file_=payload_file, path=path)
  File "/home/roberto/Documents/Lytica/vico-analytics-server/src/apis/acquisition_api.py", line 80, in main
    response  = self.send_api_data(payload=data, path=path)
  File "/home/roberto/Documents/Lytica/vico-analytics-server/src/apis/acquisition_api.py", line 31, in send_api_data
    response = requests.post(url=url, files=payload,)
  File "/home/roberto/.cache/pypoetry/virtualenvs/vico-analytics-server-GoRiLKSi-py3.8/lib/python3.8/site-packages/requests/api.py", line 117, in post
    return request('post', url, data=data, json=json, **kwargs)
  File "/home/roberto/.cache/pypoetry/virtualenvs/vico-analytics-server-GoRiLKSi-py3.8/lib/python3.8/site-packages/requests/api.py", line 61, in request
    return session.request(method=method, url=url, **kwargs)
  File "/home/roberto/.cache/pypoetry/virtualenvs/vico-analytics-server-GoRiLKSi-py3.8/lib/python3.8/site-packages/requests/sessions.py", line 529, in request
    resp = self.send(prep, **send_kwargs)
  File "/home/roberto/.cache/pypoetry/virtualenvs/vico-analytics-server-GoRiLKSi-py3.8/lib/python3.8/site-packages/requests/sessions.py", line 645, in send
    r = adapter.send(request, **kwargs)
  File "/home/roberto/.cache/pypoetry/virtualenvs/vico-analytics-server-GoRiLKSi-py3.8/lib/python3.8/site-packages/requests/adapters.py", line 519, in send
    raise ConnectionError(e, request=request)
requests.exceptions.ConnectionError: HTTPSConnectionPool(host='dev.vico.ai', port=443): Max retries exceeded with url: /acquisition/visitor-counter/ (Caused by NewConnectionError('<urllib3.connection.HTTPSConnection object at 0x7fbc469ea9a0>: Failed to establish a new connection: [Errno -3] Temporary failure in name resolution'))
INFO:werkzeug: * Detected change in '/home/roberto/Documents/Lytica/vico-analytics-server/src/apis/acquisition_api.py', reloading
INFO:werkzeug: * Restarting with stat
INFO:werkzeug:127.0.0.1 - - [28/Feb/2022 17:04:55] "[35m[1mPOST /acquisition/visitor-counter/ HTTP/1.1[0m" 500 -
ERROR:werkzeug:Error on request:
Traceback (most recent call last):
  File "/home/roberto/.cache/pypoetry/virtualenvs/vico-analytics-server-GoRiLKSi-py3.8/lib/python3.8/site-packages/urllib3/connection.py", line 174, in _new_conn
    conn = connection.create_connection(
  File "/home/roberto/.cache/pypoetry/virtualenvs/vico-analytics-server-GoRiLKSi-py3.8/lib/python3.8/site-packages/urllib3/util/connection.py", line 72, in create_connection
    for res in socket.getaddrinfo(host, port, family, socket.SOCK_STREAM):
  File "/usr/lib/python3.8/socket.py", line 918, in getaddrinfo
    for res in _socket.getaddrinfo(host, port, family, type, proto, flags):
socket.gaierror: [Errno -3] Temporary failure in name resolution

During handling of the above exception, another exception occurred:

Traceback (most recent call last):
  File "/home/roberto/.cache/pypoetry/virtualenvs/vico-analytics-server-GoRiLKSi-py3.8/lib/python3.8/site-packages/urllib3/connectionpool.py", line 703, in urlopen
    httplib_response = self._make_request(
  File "/home/roberto/.cache/pypoetry/virtualenvs/vico-analytics-server-GoRiLKSi-py3.8/lib/python3.8/site-packages/urllib3/connectionpool.py", line 386, in _make_request
    self._validate_conn(conn)
  File "/home/roberto/.cache/pypoetry/virtualenvs/vico-analytics-server-GoRiLKSi-py3.8/lib/python3.8/site-packages/urllib3/connectionpool.py", line 1040, in _validate_conn
    conn.connect()
  File "/home/roberto/.cache/pypoetry/virtualenvs/vico-analytics-server-GoRiLKSi-py3.8/lib/python3.8/site-packages/urllib3/connection.py", line 358, in connect
    conn = self._new_conn()
  File "/home/roberto/.cache/pypoetry/virtualenvs/vico-analytics-server-GoRiLKSi-py3.8/lib/python3.8/site-packages/urllib3/connection.py", line 186, in _new_conn
    raise NewConnectionError(
urllib3.exceptions.NewConnectionError: <urllib3.connection.HTTPSConnection object at 0x7fa63f5d23d0>: Failed to establish a new connection: [Errno -3] Temporary failure in name resolution

During handling of the above exception, another exception occurred:

Traceback (most recent call last):
  File "/home/roberto/.cache/pypoetry/virtualenvs/vico-analytics-server-GoRiLKSi-py3.8/lib/python3.8/site-packages/requests/adapters.py", line 440, in send
    resp = conn.urlopen(
  File "/home/roberto/.cache/pypoetry/virtualenvs/vico-analytics-server-GoRiLKSi-py3.8/lib/python3.8/site-packages/urllib3/connectionpool.py", line 785, in urlopen
    retries = retries.increment(
  File "/home/roberto/.cache/pypoetry/virtualenvs/vico-analytics-server-GoRiLKSi-py3.8/lib/python3.8/site-packages/urllib3/util/retry.py", line 592, in increment
    raise MaxRetryError(_pool, url, error or ResponseError(cause))
urllib3.exceptions.MaxRetryError: HTTPSConnectionPool(host='dev.vico.ai', port=443): Max retries exceeded with url: /acquisition/visitor-counter/ (Caused by NewConnectionError('<urllib3.connection.HTTPSConnection object at 0x7fa63f5d23d0>: Failed to establish a new connection: [Errno -3] Temporary failure in name resolution'))

During handling of the above exception, another exception occurred:

Traceback (most recent call last):
  File "/home/roberto/.cache/pypoetry/virtualenvs/vico-analytics-server-GoRiLKSi-py3.8/lib/python3.8/site-packages/werkzeug/serving.py", line 324, in run_wsgi
    execute(self.server.app)
  File "/home/roberto/.cache/pypoetry/virtualenvs/vico-analytics-server-GoRiLKSi-py3.8/lib/python3.8/site-packages/werkzeug/serving.py", line 313, in execute
    application_iter = app(environ, start_response)
  File "/home/roberto/.cache/pypoetry/virtualenvs/vico-analytics-server-GoRiLKSi-py3.8/lib/python3.8/site-packages/flask/app.py", line 2091, in __call__
    return self.wsgi_app(environ, start_response)
  File "/home/roberto/.cache/pypoetry/virtualenvs/vico-analytics-server-GoRiLKSi-py3.8/lib/python3.8/site-packages/flask/app.py", line 2076, in wsgi_app
    response = self.handle_exception(e)
  File "/home/roberto/.cache/pypoetry/virtualenvs/vico-analytics-server-GoRiLKSi-py3.8/lib/python3.8/site-packages/flask/app.py", line 2073, in wsgi_app
    response = self.full_dispatch_request()
  File "/home/roberto/.cache/pypoetry/virtualenvs/vico-analytics-server-GoRiLKSi-py3.8/lib/python3.8/site-packages/flask/app.py", line 1518, in full_dispatch_request
    rv = self.handle_user_exception(e)
  File "/home/roberto/.cache/pypoetry/virtualenvs/vico-analytics-server-GoRiLKSi-py3.8/lib/python3.8/site-packages/flask/app.py", line 1516, in full_dispatch_request
    rv = self.dispatch_request()
  File "/home/roberto/.cache/pypoetry/virtualenvs/vico-analytics-server-GoRiLKSi-py3.8/lib/python3.8/site-packages/flask/app.py", line 1502, in dispatch_request
    return self.ensure_sync(self.view_functions[rule.endpoint])(**req.view_args)
  File "/home/roberto/Documents/Lytica/vico-analytics-server/app.py", line 21, in main_acquisition
    response, status = cls_aquisition.main(data=payload_data, file_=payload_file, path=path)
  File "/home/roberto/Documents/Lytica/vico-analytics-server/src/apis/acquisition_api.py", line 81, in main
    response  = self.send_api_data(payload=data, path=path)
  File "/home/roberto/Documents/Lytica/vico-analytics-server/src/apis/acquisition_api.py", line 32, in send_api_data
    response = requests.post(url=url, files=payload,)
  File "/home/roberto/.cache/pypoetry/virtualenvs/vico-analytics-server-GoRiLKSi-py3.8/lib/python3.8/site-packages/requests/api.py", line 117, in post
    return request('post', url, data=data, json=json, **kwargs)
  File "/home/roberto/.cache/pypoetry/virtualenvs/vico-analytics-server-GoRiLKSi-py3.8/lib/python3.8/site-packages/requests/api.py", line 61, in request
    return session.request(method=method, url=url, **kwargs)
  File "/home/roberto/.cache/pypoetry/virtualenvs/vico-analytics-server-GoRiLKSi-py3.8/lib/python3.8/site-packages/requests/sessions.py", line 529, in request
    resp = self.send(prep, **send_kwargs)
  File "/home/roberto/.cache/pypoetry/virtualenvs/vico-analytics-server-GoRiLKSi-py3.8/lib/python3.8/site-packages/requests/sessions.py", line 645, in send
    r = adapter.send(request, **kwargs)
  File "/home/roberto/.cache/pypoetry/virtualenvs/vico-analytics-server-GoRiLKSi-py3.8/lib/python3.8/site-packages/requests/adapters.py", line 519, in send
    raise ConnectionError(e, request=request)
requests.exceptions.ConnectionError: HTTPSConnectionPool(host='dev.vico.ai', port=443): Max retries exceeded with url: /acquisition/visitor-counter/ (Caused by NewConnectionError('<urllib3.connection.HTTPSConnection object at 0x7fa63f5d23d0>: Failed to establish a new connection: [Errno -3] Temporary failure in name resolution'))
INFO:werkzeug: * Detected change in '/home/roberto/Documents/Lytica/vico-analytics-server/src/apis/acquisition_api.py', reloading
INFO:werkzeug: * Restarting with stat
INFO:werkzeug:127.0.0.1 - - [28/Feb/2022 17:08:37] "[35m[1mPOST /acquisition/visitor-counter/ HTTP/1.1[0m" 500 -
ERROR:werkzeug:Error on request:
Traceback (most recent call last):
  File "/home/roberto/.cache/pypoetry/virtualenvs/vico-analytics-server-GoRiLKSi-py3.8/lib/python3.8/site-packages/urllib3/connection.py", line 174, in _new_conn
    conn = connection.create_connection(
  File "/home/roberto/.cache/pypoetry/virtualenvs/vico-analytics-server-GoRiLKSi-py3.8/lib/python3.8/site-packages/urllib3/util/connection.py", line 72, in create_connection
    for res in socket.getaddrinfo(host, port, family, socket.SOCK_STREAM):
  File "/usr/lib/python3.8/socket.py", line 918, in getaddrinfo
    for res in _socket.getaddrinfo(host, port, family, type, proto, flags):
socket.gaierror: [Errno -3] Temporary failure in name resolution

During handling of the above exception, another exception occurred:

Traceback (most recent call last):
  File "/home/roberto/.cache/pypoetry/virtualenvs/vico-analytics-server-GoRiLKSi-py3.8/lib/python3.8/site-packages/urllib3/connectionpool.py", line 703, in urlopen
    httplib_response = self._make_request(
  File "/home/roberto/.cache/pypoetry/virtualenvs/vico-analytics-server-GoRiLKSi-py3.8/lib/python3.8/site-packages/urllib3/connectionpool.py", line 386, in _make_request
    self._validate_conn(conn)
  File "/home/roberto/.cache/pypoetry/virtualenvs/vico-analytics-server-GoRiLKSi-py3.8/lib/python3.8/site-packages/urllib3/connectionpool.py", line 1040, in _validate_conn
    conn.connect()
  File "/home/roberto/.cache/pypoetry/virtualenvs/vico-analytics-server-GoRiLKSi-py3.8/lib/python3.8/site-packages/urllib3/connection.py", line 358, in connect
    conn = self._new_conn()
  File "/home/roberto/.cache/pypoetry/virtualenvs/vico-analytics-server-GoRiLKSi-py3.8/lib/python3.8/site-packages/urllib3/connection.py", line 186, in _new_conn
    raise NewConnectionError(
urllib3.exceptions.NewConnectionError: <urllib3.connection.HTTPSConnection object at 0x7f7a369e7dc0>: Failed to establish a new connection: [Errno -3] Temporary failure in name resolution

During handling of the above exception, another exception occurred:

Traceback (most recent call last):
  File "/home/roberto/.cache/pypoetry/virtualenvs/vico-analytics-server-GoRiLKSi-py3.8/lib/python3.8/site-packages/requests/adapters.py", line 440, in send
    resp = conn.urlopen(
  File "/home/roberto/.cache/pypoetry/virtualenvs/vico-analytics-server-GoRiLKSi-py3.8/lib/python3.8/site-packages/urllib3/connectionpool.py", line 785, in urlopen
    retries = retries.increment(
  File "/home/roberto/.cache/pypoetry/virtualenvs/vico-analytics-server-GoRiLKSi-py3.8/lib/python3.8/site-packages/urllib3/util/retry.py", line 592, in increment
    raise MaxRetryError(_pool, url, error or ResponseError(cause))
urllib3.exceptions.MaxRetryError: HTTPSConnectionPool(host='dev.vico.ai', port=443): Max retries exceeded with url: /acquisition/visitor-counter/ (Caused by NewConnectionError('<urllib3.connection.HTTPSConnection object at 0x7f7a369e7dc0>: Failed to establish a new connection: [Errno -3] Temporary failure in name resolution'))

During handling of the above exception, another exception occurred:

Traceback (most recent call last):
  File "/home/roberto/.cache/pypoetry/virtualenvs/vico-analytics-server-GoRiLKSi-py3.8/lib/python3.8/site-packages/werkzeug/serving.py", line 324, in run_wsgi
    execute(self.server.app)
  File "/home/roberto/.cache/pypoetry/virtualenvs/vico-analytics-server-GoRiLKSi-py3.8/lib/python3.8/site-packages/werkzeug/serving.py", line 313, in execute
    application_iter = app(environ, start_response)
  File "/home/roberto/.cache/pypoetry/virtualenvs/vico-analytics-server-GoRiLKSi-py3.8/lib/python3.8/site-packages/flask/app.py", line 2091, in __call__
    return self.wsgi_app(environ, start_response)
  File "/home/roberto/.cache/pypoetry/virtualenvs/vico-analytics-server-GoRiLKSi-py3.8/lib/python3.8/site-packages/flask/app.py", line 2076, in wsgi_app
    response = self.handle_exception(e)
  File "/home/roberto/.cache/pypoetry/virtualenvs/vico-analytics-server-GoRiLKSi-py3.8/lib/python3.8/site-packages/flask/app.py", line 2073, in wsgi_app
    response = self.full_dispatch_request()
  File "/home/roberto/.cache/pypoetry/virtualenvs/vico-analytics-server-GoRiLKSi-py3.8/lib/python3.8/site-packages/flask/app.py", line 1518, in full_dispatch_request
    rv = self.handle_user_exception(e)
  File "/home/roberto/.cache/pypoetry/virtualenvs/vico-analytics-server-GoRiLKSi-py3.8/lib/python3.8/site-packages/flask/app.py", line 1516, in full_dispatch_request
    rv = self.dispatch_request()
  File "/home/roberto/.cache/pypoetry/virtualenvs/vico-analytics-server-GoRiLKSi-py3.8/lib/python3.8/site-packages/flask/app.py", line 1502, in dispatch_request
    return self.ensure_sync(self.view_functions[rule.endpoint])(**req.view_args)
  File "/home/roberto/Documents/Lytica/vico-analytics-server/app.py", line 21, in main_acquisition
    response, status = cls_aquisition.main(data=payload_data, file_=payload_file, path=path)
  File "/home/roberto/Documents/Lytica/vico-analytics-server/src/apis/acquisition_api.py", line 81, in main
    response  = self.send_api_data(payload=data, path=path)
  File "/home/roberto/Documents/Lytica/vico-analytics-server/src/apis/acquisition_api.py", line 32, in send_api_data
    response = requests.post(url=url, files=payload,)
  File "/home/roberto/.cache/pypoetry/virtualenvs/vico-analytics-server-GoRiLKSi-py3.8/lib/python3.8/site-packages/requests/api.py", line 117, in post
    return request('post', url, data=data, json=json, **kwargs)
  File "/home/roberto/.cache/pypoetry/virtualenvs/vico-analytics-server-GoRiLKSi-py3.8/lib/python3.8/site-packages/requests/api.py", line 61, in request
    return session.request(method=method, url=url, **kwargs)
  File "/home/roberto/.cache/pypoetry/virtualenvs/vico-analytics-server-GoRiLKSi-py3.8/lib/python3.8/site-packages/requests/sessions.py", line 529, in request
    resp = self.send(prep, **send_kwargs)
  File "/home/roberto/.cache/pypoetry/virtualenvs/vico-analytics-server-GoRiLKSi-py3.8/lib/python3.8/site-packages/requests/sessions.py", line 645, in send
    r = adapter.send(request, **kwargs)
  File "/home/roberto/.cache/pypoetry/virtualenvs/vico-analytics-server-GoRiLKSi-py3.8/lib/python3.8/site-packages/requests/adapters.py", line 519, in send
    raise ConnectionError(e, request=request)
requests.exceptions.ConnectionError: HTTPSConnectionPool(host='dev.vico.ai', port=443): Max retries exceeded with url: /acquisition/visitor-counter/ (Caused by NewConnectionError('<urllib3.connection.HTTPSConnection object at 0x7f7a369e7dc0>: Failed to establish a new connection: [Errno -3] Temporary failure in name resolution'))
INFO:werkzeug: * Detected change in '/home/roberto/Documents/Lytica/vico-analytics-server/src/apis/acquisition_api.py', reloading
INFO:werkzeug: * Restarting with stat
INFO:werkzeug:127.0.0.1 - - [28/Feb/2022 17:10:19] "[35m[1mPOST /acquisition/visitor-counter/ HTTP/1.1[0m" 500 -
ERROR:werkzeug:Error on request:
Traceback (most recent call last):
  File "/home/roberto/.cache/pypoetry/virtualenvs/vico-analytics-server-GoRiLKSi-py3.8/lib/python3.8/site-packages/urllib3/connection.py", line 174, in _new_conn
    conn = connection.create_connection(
  File "/home/roberto/.cache/pypoetry/virtualenvs/vico-analytics-server-GoRiLKSi-py3.8/lib/python3.8/site-packages/urllib3/util/connection.py", line 72, in create_connection
    for res in socket.getaddrinfo(host, port, family, socket.SOCK_STREAM):
  File "/usr/lib/python3.8/socket.py", line 918, in getaddrinfo
    for res in _socket.getaddrinfo(host, port, family, type, proto, flags):
socket.gaierror: [Errno -3] Temporary failure in name resolution

During handling of the above exception, another exception occurred:

Traceback (most recent call last):
  File "/home/roberto/.cache/pypoetry/virtualenvs/vico-analytics-server-GoRiLKSi-py3.8/lib/python3.8/site-packages/urllib3/connectionpool.py", line 703, in urlopen
    httplib_response = self._make_request(
  File "/home/roberto/.cache/pypoetry/virtualenvs/vico-analytics-server-GoRiLKSi-py3.8/lib/python3.8/site-packages/urllib3/connectionpool.py", line 386, in _make_request
    self._validate_conn(conn)
  File "/home/roberto/.cache/pypoetry/virtualenvs/vico-analytics-server-GoRiLKSi-py3.8/lib/python3.8/site-packages/urllib3/connectionpool.py", line 1040, in _validate_conn
    conn.connect()
  File "/home/roberto/.cache/pypoetry/virtualenvs/vico-analytics-server-GoRiLKSi-py3.8/lib/python3.8/site-packages/urllib3/connection.py", line 358, in connect
    conn = self._new_conn()
  File "/home/roberto/.cache/pypoetry/virtualenvs/vico-analytics-server-GoRiLKSi-py3.8/lib/python3.8/site-packages/urllib3/connection.py", line 186, in _new_conn
    raise NewConnectionError(
urllib3.exceptions.NewConnectionError: <urllib3.connection.HTTPSConnection object at 0x7f18b017cc10>: Failed to establish a new connection: [Errno -3] Temporary failure in name resolution

During handling of the above exception, another exception occurred:

Traceback (most recent call last):
  File "/home/roberto/.cache/pypoetry/virtualenvs/vico-analytics-server-GoRiLKSi-py3.8/lib/python3.8/site-packages/requests/adapters.py", line 440, in send
    resp = conn.urlopen(
  File "/home/roberto/.cache/pypoetry/virtualenvs/vico-analytics-server-GoRiLKSi-py3.8/lib/python3.8/site-packages/urllib3/connectionpool.py", line 785, in urlopen
    retries = retries.increment(
  File "/home/roberto/.cache/pypoetry/virtualenvs/vico-analytics-server-GoRiLKSi-py3.8/lib/python3.8/site-packages/urllib3/util/retry.py", line 592, in increment
    raise MaxRetryError(_pool, url, error or ResponseError(cause))
urllib3.exceptions.MaxRetryError: HTTPSConnectionPool(host='dev.vico.ai', port=443): Max retries exceeded with url: /acquisition/visitor-counter/ (Caused by NewConnectionError('<urllib3.connection.HTTPSConnection object at 0x7f18b017cc10>: Failed to establish a new connection: [Errno -3] Temporary failure in name resolution'))

During handling of the above exception, another exception occurred:

Traceback (most recent call last):
  File "/home/roberto/.cache/pypoetry/virtualenvs/vico-analytics-server-GoRiLKSi-py3.8/lib/python3.8/site-packages/werkzeug/serving.py", line 324, in run_wsgi
    execute(self.server.app)
  File "/home/roberto/.cache/pypoetry/virtualenvs/vico-analytics-server-GoRiLKSi-py3.8/lib/python3.8/site-packages/werkzeug/serving.py", line 313, in execute
    application_iter = app(environ, start_response)
  File "/home/roberto/.cache/pypoetry/virtualenvs/vico-analytics-server-GoRiLKSi-py3.8/lib/python3.8/site-packages/flask/app.py", line 2091, in __call__
    return self.wsgi_app(environ, start_response)
  File "/home/roberto/.cache/pypoetry/virtualenvs/vico-analytics-server-GoRiLKSi-py3.8/lib/python3.8/site-packages/flask/app.py", line 2076, in wsgi_app
    response = self.handle_exception(e)
  File "/home/roberto/.cache/pypoetry/virtualenvs/vico-analytics-server-GoRiLKSi-py3.8/lib/python3.8/site-packages/flask/app.py", line 2073, in wsgi_app
    response = self.full_dispatch_request()
  File "/home/roberto/.cache/pypoetry/virtualenvs/vico-analytics-server-GoRiLKSi-py3.8/lib/python3.8/site-packages/flask/app.py", line 1518, in full_dispatch_request
    rv = self.handle_user_exception(e)
  File "/home/roberto/.cache/pypoetry/virtualenvs/vico-analytics-server-GoRiLKSi-py3.8/lib/python3.8/site-packages/flask/app.py", line 1516, in full_dispatch_request
    rv = self.dispatch_request()
  File "/home/roberto/.cache/pypoetry/virtualenvs/vico-analytics-server-GoRiLKSi-py3.8/lib/python3.8/site-packages/flask/app.py", line 1502, in dispatch_request
    return self.ensure_sync(self.view_functions[rule.endpoint])(**req.view_args)
  File "/home/roberto/Documents/Lytica/vico-analytics-server/app.py", line 21, in main_acquisition
    response, status = cls_aquisition.main(data=payload_data, file_=payload_file, path=path)
  File "/home/roberto/Documents/Lytica/vico-analytics-server/src/apis/acquisition_api.py", line 81, in main
    response  = self.send_api_data(payload=data, path=path)
  File "/home/roberto/Documents/Lytica/vico-analytics-server/src/apis/acquisition_api.py", line 32, in send_api_data
    response = requests.post(url=url, files=payload,)
  File "/home/roberto/.cache/pypoetry/virtualenvs/vico-analytics-server-GoRiLKSi-py3.8/lib/python3.8/site-packages/requests/api.py", line 117, in post
    return request('post', url, data=data, json=json, **kwargs)
  File "/home/roberto/.cache/pypoetry/virtualenvs/vico-analytics-server-GoRiLKSi-py3.8/lib/python3.8/site-packages/requests/api.py", line 61, in request
    return session.request(method=method, url=url, **kwargs)
  File "/home/roberto/.cache/pypoetry/virtualenvs/vico-analytics-server-GoRiLKSi-py3.8/lib/python3.8/site-packages/requests/sessions.py", line 529, in request
    resp = self.send(prep, **send_kwargs)
  File "/home/roberto/.cache/pypoetry/virtualenvs/vico-analytics-server-GoRiLKSi-py3.8/lib/python3.8/site-packages/requests/sessions.py", line 645, in send
    r = adapter.send(request, **kwargs)
  File "/home/roberto/.cache/pypoetry/virtualenvs/vico-analytics-server-GoRiLKSi-py3.8/lib/python3.8/site-packages/requests/adapters.py", line 519, in send
    raise ConnectionError(e, request=request)
requests.exceptions.ConnectionError: HTTPSConnectionPool(host='dev.vico.ai', port=443): Max retries exceeded with url: /acquisition/visitor-counter/ (Caused by NewConnectionError('<urllib3.connection.HTTPSConnection object at 0x7f18b017cc10>: Failed to establish a new connection: [Errno -3] Temporary failure in name resolution'))
INFO:werkzeug: * Detected change in '/home/roberto/Documents/Lytica/vico-analytics-server/src/apis/acquisition_api.py', reloading
INFO:werkzeug: * Restarting with stat
INFO:werkzeug:127.0.0.1 - - [28/Feb/2022 17:11:46] "[35m[1mPOST /acquisition/visitor-counter/ HTTP/1.1[0m" 500 -
ERROR:werkzeug:Error on request:
Traceback (most recent call last):
  File "/home/roberto/.cache/pypoetry/virtualenvs/vico-analytics-server-GoRiLKSi-py3.8/lib/python3.8/site-packages/werkzeug/serving.py", line 324, in run_wsgi
    execute(self.server.app)
  File "/home/roberto/.cache/pypoetry/virtualenvs/vico-analytics-server-GoRiLKSi-py3.8/lib/python3.8/site-packages/werkzeug/serving.py", line 313, in execute
    application_iter = app(environ, start_response)
  File "/home/roberto/.cache/pypoetry/virtualenvs/vico-analytics-server-GoRiLKSi-py3.8/lib/python3.8/site-packages/flask/app.py", line 2091, in __call__
    return self.wsgi_app(environ, start_response)
  File "/home/roberto/.cache/pypoetry/virtualenvs/vico-analytics-server-GoRiLKSi-py3.8/lib/python3.8/site-packages/flask/app.py", line 2076, in wsgi_app
    response = self.handle_exception(e)
  File "/home/roberto/.cache/pypoetry/virtualenvs/vico-analytics-server-GoRiLKSi-py3.8/lib/python3.8/site-packages/flask/app.py", line 2073, in wsgi_app
    response = self.full_dispatch_request()
  File "/home/roberto/.cache/pypoetry/virtualenvs/vico-analytics-server-GoRiLKSi-py3.8/lib/python3.8/site-packages/flask/app.py", line 1518, in full_dispatch_request
    rv = self.handle_user_exception(e)
  File "/home/roberto/.cache/pypoetry/virtualenvs/vico-analytics-server-GoRiLKSi-py3.8/lib/python3.8/site-packages/flask/app.py", line 1516, in full_dispatch_request
    rv = self.dispatch_request()
  File "/home/roberto/.cache/pypoetry/virtualenvs/vico-analytics-server-GoRiLKSi-py3.8/lib/python3.8/site-packages/flask/app.py", line 1502, in dispatch_request
    return self.ensure_sync(self.view_functions[rule.endpoint])(**req.view_args)
  File "/home/roberto/Documents/Lytica/vico-analytics-server/app.py", line 21, in main_acquisition
    response, status = cls_aquisition.main(data=payload_data, file_=payload_file, path=path)
  File "/home/roberto/Documents/Lytica/vico-analytics-server/src/apis/acquisition_api.py", line 85, in main
    response, status = self.validate_queue(response=response, data=data, path=path)
UnboundLocalError: local variable 'response' referenced before assignment
INFO:werkzeug:127.0.0.1 - - [28/Feb/2022 17:12:15] "[35m[1mPOST /acquisition/visitor-counter/ HTTP/1.1[0m" 500 -
ERROR:werkzeug:Error on request:
Traceback (most recent call last):
  File "/home/roberto/.cache/pypoetry/virtualenvs/vico-analytics-server-GoRiLKSi-py3.8/lib/python3.8/site-packages/werkzeug/serving.py", line 324, in run_wsgi
    execute(self.server.app)
  File "/home/roberto/.cache/pypoetry/virtualenvs/vico-analytics-server-GoRiLKSi-py3.8/lib/python3.8/site-packages/werkzeug/serving.py", line 313, in execute
    application_iter = app(environ, start_response)
  File "/home/roberto/.cache/pypoetry/virtualenvs/vico-analytics-server-GoRiLKSi-py3.8/lib/python3.8/site-packages/flask/app.py", line 2091, in __call__
    return self.wsgi_app(environ, start_response)
  File "/home/roberto/.cache/pypoetry/virtualenvs/vico-analytics-server-GoRiLKSi-py3.8/lib/python3.8/site-packages/flask/app.py", line 2076, in wsgi_app
    response = self.handle_exception(e)
  File "/home/roberto/.cache/pypoetry/virtualenvs/vico-analytics-server-GoRiLKSi-py3.8/lib/python3.8/site-packages/flask/app.py", line 2073, in wsgi_app
    response = self.full_dispatch_request()
  File "/home/roberto/.cache/pypoetry/virtualenvs/vico-analytics-server-GoRiLKSi-py3.8/lib/python3.8/site-packages/flask/app.py", line 1518, in full_dispatch_request
    rv = self.handle_user_exception(e)
  File "/home/roberto/.cache/pypoetry/virtualenvs/vico-analytics-server-GoRiLKSi-py3.8/lib/python3.8/site-packages/flask/app.py", line 1516, in full_dispatch_request
    rv = self.dispatch_request()
  File "/home/roberto/.cache/pypoetry/virtualenvs/vico-analytics-server-GoRiLKSi-py3.8/lib/python3.8/site-packages/flask/app.py", line 1502, in dispatch_request
    return self.ensure_sync(self.view_functions[rule.endpoint])(**req.view_args)
  File "/home/roberto/Documents/Lytica/vico-analytics-server/app.py", line 21, in main_acquisition
    response, status = cls_aquisition.main(data=payload_data, file_=payload_file, path=path)
  File "/home/roberto/Documents/Lytica/vico-analytics-server/src/apis/acquisition_api.py", line 85, in main
    response, status = self.validate_queue(response=response, data=data, path=path)
UnboundLocalError: local variable 'response' referenced before assignment
INFO:werkzeug: * Detected change in '/home/roberto/Documents/Lytica/vico-analytics-server/src/apis/acquisition_api.py', reloading
INFO:werkzeug: * Restarting with stat
INFO:werkzeug: * Detected change in '/home/roberto/Documents/Lytica/vico-analytics-server/src/apis/acquisition_api.py', reloading
INFO:werkzeug: * Restarting with stat
INFO:werkzeug:127.0.0.1 - - [28/Feb/2022 17:18:32] "[35m[1mPOST /acquisition/visitor-counter/ HTTP/1.1[0m" 500 -
ERROR:werkzeug:Error on request:
Traceback (most recent call last):
  File "/home/roberto/.cache/pypoetry/virtualenvs/vico-analytics-server-GoRiLKSi-py3.8/lib/python3.8/site-packages/urllib3/connection.py", line 174, in _new_conn
    conn = connection.create_connection(
  File "/home/roberto/.cache/pypoetry/virtualenvs/vico-analytics-server-GoRiLKSi-py3.8/lib/python3.8/site-packages/urllib3/util/connection.py", line 72, in create_connection
    for res in socket.getaddrinfo(host, port, family, socket.SOCK_STREAM):
  File "/usr/lib/python3.8/socket.py", line 918, in getaddrinfo
    for res in _socket.getaddrinfo(host, port, family, type, proto, flags):
socket.gaierror: [Errno -3] Temporary failure in name resolution

During handling of the above exception, another exception occurred:

Traceback (most recent call last):
  File "/home/roberto/.cache/pypoetry/virtualenvs/vico-analytics-server-GoRiLKSi-py3.8/lib/python3.8/site-packages/urllib3/connectionpool.py", line 703, in urlopen
    httplib_response = self._make_request(
  File "/home/roberto/.cache/pypoetry/virtualenvs/vico-analytics-server-GoRiLKSi-py3.8/lib/python3.8/site-packages/urllib3/connectionpool.py", line 386, in _make_request
    self._validate_conn(conn)
  File "/home/roberto/.cache/pypoetry/virtualenvs/vico-analytics-server-GoRiLKSi-py3.8/lib/python3.8/site-packages/urllib3/connectionpool.py", line 1040, in _validate_conn
    conn.connect()
  File "/home/roberto/.cache/pypoetry/virtualenvs/vico-analytics-server-GoRiLKSi-py3.8/lib/python3.8/site-packages/urllib3/connection.py", line 358, in connect
    conn = self._new_conn()
  File "/home/roberto/.cache/pypoetry/virtualenvs/vico-analytics-server-GoRiLKSi-py3.8/lib/python3.8/site-packages/urllib3/connection.py", line 186, in _new_conn
    raise NewConnectionError(
urllib3.exceptions.NewConnectionError: <urllib3.connection.HTTPSConnection object at 0x7fe633dd8b20>: Failed to establish a new connection: [Errno -3] Temporary failure in name resolution

During handling of the above exception, another exception occurred:

Traceback (most recent call last):
  File "/home/roberto/.cache/pypoetry/virtualenvs/vico-analytics-server-GoRiLKSi-py3.8/lib/python3.8/site-packages/requests/adapters.py", line 440, in send
    resp = conn.urlopen(
  File "/home/roberto/.cache/pypoetry/virtualenvs/vico-analytics-server-GoRiLKSi-py3.8/lib/python3.8/site-packages/urllib3/connectionpool.py", line 785, in urlopen
    retries = retries.increment(
  File "/home/roberto/.cache/pypoetry/virtualenvs/vico-analytics-server-GoRiLKSi-py3.8/lib/python3.8/site-packages/urllib3/util/retry.py", line 592, in increment
    raise MaxRetryError(_pool, url, error or ResponseError(cause))
urllib3.exceptions.MaxRetryError: HTTPSConnectionPool(host='dev.vico.ai', port=443): Max retries exceeded with url: /acquisition/visitor-counter/ (Caused by NewConnectionError('<urllib3.connection.HTTPSConnection object at 0x7fe633dd8b20>: Failed to establish a new connection: [Errno -3] Temporary failure in name resolution'))

During handling of the above exception, another exception occurred:

Traceback (most recent call last):
  File "/home/roberto/.cache/pypoetry/virtualenvs/vico-analytics-server-GoRiLKSi-py3.8/lib/python3.8/site-packages/werkzeug/serving.py", line 324, in run_wsgi
    execute(self.server.app)
  File "/home/roberto/.cache/pypoetry/virtualenvs/vico-analytics-server-GoRiLKSi-py3.8/lib/python3.8/site-packages/werkzeug/serving.py", line 313, in execute
    application_iter = app(environ, start_response)
  File "/home/roberto/.cache/pypoetry/virtualenvs/vico-analytics-server-GoRiLKSi-py3.8/lib/python3.8/site-packages/flask/app.py", line 2091, in __call__
    return self.wsgi_app(environ, start_response)
  File "/home/roberto/.cache/pypoetry/virtualenvs/vico-analytics-server-GoRiLKSi-py3.8/lib/python3.8/site-packages/flask/app.py", line 2076, in wsgi_app
    response = self.handle_exception(e)
  File "/home/roberto/.cache/pypoetry/virtualenvs/vico-analytics-server-GoRiLKSi-py3.8/lib/python3.8/site-packages/flask/app.py", line 2073, in wsgi_app
    response = self.full_dispatch_request()
  File "/home/roberto/.cache/pypoetry/virtualenvs/vico-analytics-server-GoRiLKSi-py3.8/lib/python3.8/site-packages/flask/app.py", line 1518, in full_dispatch_request
    rv = self.handle_user_exception(e)
  File "/home/roberto/.cache/pypoetry/virtualenvs/vico-analytics-server-GoRiLKSi-py3.8/lib/python3.8/site-packages/flask/app.py", line 1516, in full_dispatch_request
    rv = self.dispatch_request()
  File "/home/roberto/.cache/pypoetry/virtualenvs/vico-analytics-server-GoRiLKSi-py3.8/lib/python3.8/site-packages/flask/app.py", line 1502, in dispatch_request
    return self.ensure_sync(self.view_functions[rule.endpoint])(**req.view_args)
  File "/home/roberto/Documents/Lytica/vico-analytics-server/app.py", line 21, in main_acquisition
    response, status = cls_aquisition.main(data=payload_data, file_=payload_file, path=path)
  File "/home/roberto/Documents/Lytica/vico-analytics-server/src/apis/acquisition_api.py", line 87, in main
    response  = self.send_api_data(payload=data, path=path)
  File "/home/roberto/Documents/Lytica/vico-analytics-server/src/apis/acquisition_api.py", line 33, in send_api_data
    response = requests.post(url=url, files=payload,)
  File "/home/roberto/.cache/pypoetry/virtualenvs/vico-analytics-server-GoRiLKSi-py3.8/lib/python3.8/site-packages/requests/api.py", line 117, in post
    return request('post', url, data=data, json=json, **kwargs)
  File "/home/roberto/.cache/pypoetry/virtualenvs/vico-analytics-server-GoRiLKSi-py3.8/lib/python3.8/site-packages/requests/api.py", line 61, in request
    return session.request(method=method, url=url, **kwargs)
  File "/home/roberto/.cache/pypoetry/virtualenvs/vico-analytics-server-GoRiLKSi-py3.8/lib/python3.8/site-packages/requests/sessions.py", line 529, in request
    resp = self.send(prep, **send_kwargs)
  File "/home/roberto/.cache/pypoetry/virtualenvs/vico-analytics-server-GoRiLKSi-py3.8/lib/python3.8/site-packages/requests/sessions.py", line 645, in send
    r = adapter.send(request, **kwargs)
  File "/home/roberto/.cache/pypoetry/virtualenvs/vico-analytics-server-GoRiLKSi-py3.8/lib/python3.8/site-packages/requests/adapters.py", line 519, in send
    raise ConnectionError(e, request=request)
requests.exceptions.ConnectionError: HTTPSConnectionPool(host='dev.vico.ai', port=443): Max retries exceeded with url: /acquisition/visitor-counter/ (Caused by NewConnectionError('<urllib3.connection.HTTPSConnection object at 0x7fe633dd8b20>: Failed to establish a new connection: [Errno -3] Temporary failure in name resolution'))
INFO:werkzeug: * Detected change in '/home/roberto/Documents/Lytica/vico-analytics-server/src/apis/acquisition_api.py', reloading
INFO:werkzeug: * Restarting with stat
INFO:werkzeug:127.0.0.1 - - [28/Feb/2022 17:19:46] "[35m[1mPOST /acquisition/visitor-counter/ HTTP/1.1[0m" 500 -
ERROR:werkzeug:Error on request:
Traceback (most recent call last):
  File "/home/roberto/.cache/pypoetry/virtualenvs/vico-analytics-server-GoRiLKSi-py3.8/lib/python3.8/site-packages/urllib3/connection.py", line 174, in _new_conn
    conn = connection.create_connection(
  File "/home/roberto/.cache/pypoetry/virtualenvs/vico-analytics-server-GoRiLKSi-py3.8/lib/python3.8/site-packages/urllib3/util/connection.py", line 72, in create_connection
    for res in socket.getaddrinfo(host, port, family, socket.SOCK_STREAM):
  File "/usr/lib/python3.8/socket.py", line 918, in getaddrinfo
    for res in _socket.getaddrinfo(host, port, family, type, proto, flags):
socket.gaierror: [Errno -3] Temporary failure in name resolution

During handling of the above exception, another exception occurred:

Traceback (most recent call last):
  File "/home/roberto/.cache/pypoetry/virtualenvs/vico-analytics-server-GoRiLKSi-py3.8/lib/python3.8/site-packages/urllib3/connectionpool.py", line 703, in urlopen
    httplib_response = self._make_request(
  File "/home/roberto/.cache/pypoetry/virtualenvs/vico-analytics-server-GoRiLKSi-py3.8/lib/python3.8/site-packages/urllib3/connectionpool.py", line 386, in _make_request
    self._validate_conn(conn)
  File "/home/roberto/.cache/pypoetry/virtualenvs/vico-analytics-server-GoRiLKSi-py3.8/lib/python3.8/site-packages/urllib3/connectionpool.py", line 1040, in _validate_conn
    conn.connect()
  File "/home/roberto/.cache/pypoetry/virtualenvs/vico-analytics-server-GoRiLKSi-py3.8/lib/python3.8/site-packages/urllib3/connection.py", line 358, in connect
    conn = self._new_conn()
  File "/home/roberto/.cache/pypoetry/virtualenvs/vico-analytics-server-GoRiLKSi-py3.8/lib/python3.8/site-packages/urllib3/connection.py", line 186, in _new_conn
    raise NewConnectionError(
urllib3.exceptions.NewConnectionError: <urllib3.connection.HTTPSConnection object at 0x7f553e9e2160>: Failed to establish a new connection: [Errno -3] Temporary failure in name resolution

During handling of the above exception, another exception occurred:

Traceback (most recent call last):
  File "/home/roberto/.cache/pypoetry/virtualenvs/vico-analytics-server-GoRiLKSi-py3.8/lib/python3.8/site-packages/requests/adapters.py", line 440, in send
    resp = conn.urlopen(
  File "/home/roberto/.cache/pypoetry/virtualenvs/vico-analytics-server-GoRiLKSi-py3.8/lib/python3.8/site-packages/urllib3/connectionpool.py", line 785, in urlopen
    retries = retries.increment(
  File "/home/roberto/.cache/pypoetry/virtualenvs/vico-analytics-server-GoRiLKSi-py3.8/lib/python3.8/site-packages/urllib3/util/retry.py", line 592, in increment
    raise MaxRetryError(_pool, url, error or ResponseError(cause))
urllib3.exceptions.MaxRetryError: HTTPSConnectionPool(host='dev.vico.ai', port=443): Max retries exceeded with url: /acquisition/visitor-counter/ (Caused by NewConnectionError('<urllib3.connection.HTTPSConnection object at 0x7f553e9e2160>: Failed to establish a new connection: [Errno -3] Temporary failure in name resolution'))

During handling of the above exception, another exception occurred:

Traceback (most recent call last):
  File "/home/roberto/.cache/pypoetry/virtualenvs/vico-analytics-server-GoRiLKSi-py3.8/lib/python3.8/site-packages/werkzeug/serving.py", line 324, in run_wsgi
    execute(self.server.app)
  File "/home/roberto/.cache/pypoetry/virtualenvs/vico-analytics-server-GoRiLKSi-py3.8/lib/python3.8/site-packages/werkzeug/serving.py", line 313, in execute
    application_iter = app(environ, start_response)
  File "/home/roberto/.cache/pypoetry/virtualenvs/vico-analytics-server-GoRiLKSi-py3.8/lib/python3.8/site-packages/flask/app.py", line 2091, in __call__
    return self.wsgi_app(environ, start_response)
  File "/home/roberto/.cache/pypoetry/virtualenvs/vico-analytics-server-GoRiLKSi-py3.8/lib/python3.8/site-packages/flask/app.py", line 2076, in wsgi_app
    response = self.handle_exception(e)
  File "/home/roberto/.cache/pypoetry/virtualenvs/vico-analytics-server-GoRiLKSi-py3.8/lib/python3.8/site-packages/flask/app.py", line 2073, in wsgi_app
    response = self.full_dispatch_request()
  File "/home/roberto/.cache/pypoetry/virtualenvs/vico-analytics-server-GoRiLKSi-py3.8/lib/python3.8/site-packages/flask/app.py", line 1518, in full_dispatch_request
    rv = self.handle_user_exception(e)
  File "/home/roberto/.cache/pypoetry/virtualenvs/vico-analytics-server-GoRiLKSi-py3.8/lib/python3.8/site-packages/flask/app.py", line 1516, in full_dispatch_request
    rv = self.dispatch_request()
  File "/home/roberto/.cache/pypoetry/virtualenvs/vico-analytics-server-GoRiLKSi-py3.8/lib/python3.8/site-packages/flask/app.py", line 1502, in dispatch_request
    return self.ensure_sync(self.view_functions[rule.endpoint])(**req.view_args)
  File "/home/roberto/Documents/Lytica/vico-analytics-server/app.py", line 21, in main_acquisition
    response, status = cls_aquisition.main(data=payload_data, file_=payload_file, path=path)
  File "/home/roberto/Documents/Lytica/vico-analytics-server/src/apis/acquisition_api.py", line 89, in main
    response  = self.send_api_data(payload=data, path=path)
  File "/home/roberto/Documents/Lytica/vico-analytics-server/src/apis/acquisition_api.py", line 34, in send_api_data
    response = requests.post(url=url, files=payload,)
  File "/home/roberto/.cache/pypoetry/virtualenvs/vico-analytics-server-GoRiLKSi-py3.8/lib/python3.8/site-packages/requests/api.py", line 117, in post
    return request('post', url, data=data, json=json, **kwargs)
  File "/home/roberto/.cache/pypoetry/virtualenvs/vico-analytics-server-GoRiLKSi-py3.8/lib/python3.8/site-packages/requests/api.py", line 61, in request
    return session.request(method=method, url=url, **kwargs)
  File "/home/roberto/.cache/pypoetry/virtualenvs/vico-analytics-server-GoRiLKSi-py3.8/lib/python3.8/site-packages/requests/sessions.py", line 529, in request
    resp = self.send(prep, **send_kwargs)
  File "/home/roberto/.cache/pypoetry/virtualenvs/vico-analytics-server-GoRiLKSi-py3.8/lib/python3.8/site-packages/requests/sessions.py", line 645, in send
    r = adapter.send(request, **kwargs)
  File "/home/roberto/.cache/pypoetry/virtualenvs/vico-analytics-server-GoRiLKSi-py3.8/lib/python3.8/site-packages/requests/adapters.py", line 519, in send
    raise ConnectionError(e, request=request)
requests.exceptions.ConnectionError: HTTPSConnectionPool(host='dev.vico.ai', port=443): Max retries exceeded with url: /acquisition/visitor-counter/ (Caused by NewConnectionError('<urllib3.connection.HTTPSConnection object at 0x7f553e9e2160>: Failed to establish a new connection: [Errno -3] Temporary failure in name resolution'))
INFO:werkzeug: * Detected change in '/home/roberto/Documents/Lytica/vico-analytics-server/src/apis/acquisition_api.py', reloading
INFO:werkzeug: * Restarting with stat
INFO:werkzeug: * Detected change in '/home/roberto/Documents/Lytica/vico-analytics-server/src/apis/acquisition_api.py', reloading
INFO:werkzeug: * Restarting with stat
INFO:werkzeug:127.0.0.1 - - [28/Feb/2022 17:21:40] "[35m[1mPOST /acquisition/visitor-counter/ HTTP/1.1[0m" 500 -
ERROR:werkzeug:Error on request:
Traceback (most recent call last):
  File "/home/roberto/.cache/pypoetry/virtualenvs/vico-analytics-server-GoRiLKSi-py3.8/lib/python3.8/site-packages/werkzeug/serving.py", line 324, in run_wsgi
    execute(self.server.app)
  File "/home/roberto/.cache/pypoetry/virtualenvs/vico-analytics-server-GoRiLKSi-py3.8/lib/python3.8/site-packages/werkzeug/serving.py", line 313, in execute
    application_iter = app(environ, start_response)
  File "/home/roberto/.cache/pypoetry/virtualenvs/vico-analytics-server-GoRiLKSi-py3.8/lib/python3.8/site-packages/flask/app.py", line 2091, in __call__
    return self.wsgi_app(environ, start_response)
  File "/home/roberto/.cache/pypoetry/virtualenvs/vico-analytics-server-GoRiLKSi-py3.8/lib/python3.8/site-packages/flask/app.py", line 2076, in wsgi_app
    response = self.handle_exception(e)
  File "/home/roberto/.cache/pypoetry/virtualenvs/vico-analytics-server-GoRiLKSi-py3.8/lib/python3.8/site-packages/flask/app.py", line 2073, in wsgi_app
    response = self.full_dispatch_request()
  File "/home/roberto/.cache/pypoetry/virtualenvs/vico-analytics-server-GoRiLKSi-py3.8/lib/python3.8/site-packages/flask/app.py", line 1518, in full_dispatch_request
    rv = self.handle_user_exception(e)
  File "/home/roberto/.cache/pypoetry/virtualenvs/vico-analytics-server-GoRiLKSi-py3.8/lib/python3.8/site-packages/flask/app.py", line 1516, in full_dispatch_request
    rv = self.dispatch_request()
  File "/home/roberto/.cache/pypoetry/virtualenvs/vico-analytics-server-GoRiLKSi-py3.8/lib/python3.8/site-packages/flask/app.py", line 1502, in dispatch_request
    return self.ensure_sync(self.view_functions[rule.endpoint])(**req.view_args)
  File "/home/roberto/Documents/Lytica/vico-analytics-server/app.py", line 21, in main_acquisition
    response, status = cls_aquisition.main(data=payload_data, file_=payload_file, path=path)
  File "/home/roberto/Documents/Lytica/vico-analytics-server/src/apis/acquisition_api.py", line 93, in main
    response, status = self.validate_queue(response=response, data=data, path=path)
UnboundLocalError: local variable 'response' referenced before assignment
INFO:werkzeug: * Detected change in '/home/roberto/Documents/Lytica/vico-analytics-server/src/apis/acquisition_api.py', reloading
INFO:werkzeug: * Restarting with stat
INFO:werkzeug:127.0.0.1 - - [28/Feb/2022 17:22:32] "[35m[1mPOST /acquisition/visitor-counter/ HTTP/1.1[0m" 500 -
ERROR:werkzeug:Error on request:
Traceback (most recent call last):
  File "/home/roberto/.cache/pypoetry/virtualenvs/vico-analytics-server-GoRiLKSi-py3.8/lib/python3.8/site-packages/werkzeug/serving.py", line 324, in run_wsgi
    execute(self.server.app)
  File "/home/roberto/.cache/pypoetry/virtualenvs/vico-analytics-server-GoRiLKSi-py3.8/lib/python3.8/site-packages/werkzeug/serving.py", line 313, in execute
    application_iter = app(environ, start_response)
  File "/home/roberto/.cache/pypoetry/virtualenvs/vico-analytics-server-GoRiLKSi-py3.8/lib/python3.8/site-packages/flask/app.py", line 2091, in __call__
    return self.wsgi_app(environ, start_response)
  File "/home/roberto/.cache/pypoetry/virtualenvs/vico-analytics-server-GoRiLKSi-py3.8/lib/python3.8/site-packages/flask/app.py", line 2076, in wsgi_app
    response = self.handle_exception(e)
  File "/home/roberto/.cache/pypoetry/virtualenvs/vico-analytics-server-GoRiLKSi-py3.8/lib/python3.8/site-packages/flask/app.py", line 2073, in wsgi_app
    response = self.full_dispatch_request()
  File "/home/roberto/.cache/pypoetry/virtualenvs/vico-analytics-server-GoRiLKSi-py3.8/lib/python3.8/site-packages/flask/app.py", line 1518, in full_dispatch_request
    rv = self.handle_user_exception(e)
  File "/home/roberto/.cache/pypoetry/virtualenvs/vico-analytics-server-GoRiLKSi-py3.8/lib/python3.8/site-packages/flask/app.py", line 1516, in full_dispatch_request
    rv = self.dispatch_request()
  File "/home/roberto/.cache/pypoetry/virtualenvs/vico-analytics-server-GoRiLKSi-py3.8/lib/python3.8/site-packages/flask/app.py", line 1502, in dispatch_request
    return self.ensure_sync(self.view_functions[rule.endpoint])(**req.view_args)
  File "/home/roberto/Documents/Lytica/vico-analytics-server/app.py", line 21, in main_acquisition
    response, status = cls_aquisition.main(data=payload_data, file_=payload_file, path=path)
  File "/home/roberto/Documents/Lytica/vico-analytics-server/src/apis/acquisition_api.py", line 93, in main
    response, status = self.validate_queue(response=response, data=data, path=path)
UnboundLocalError: local variable 'response' referenced before assignment
INFO:werkzeug: * Detected change in '/home/roberto/Documents/Lytica/vico-analytics-server/src/apis/acquisition_api.py', reloading
INFO:werkzeug: * Restarting with stat
INFO:werkzeug:127.0.0.1 - - [28/Feb/2022 17:23:05] "[35m[1mPOST /acquisition/visitor-counter/ HTTP/1.1[0m" 500 -
ERROR:werkzeug:Error on request:
Traceback (most recent call last):
  File "/home/roberto/.cache/pypoetry/virtualenvs/vico-analytics-server-GoRiLKSi-py3.8/lib/python3.8/site-packages/werkzeug/serving.py", line 324, in run_wsgi
    execute(self.server.app)
  File "/home/roberto/.cache/pypoetry/virtualenvs/vico-analytics-server-GoRiLKSi-py3.8/lib/python3.8/site-packages/werkzeug/serving.py", line 313, in execute
    application_iter = app(environ, start_response)
  File "/home/roberto/.cache/pypoetry/virtualenvs/vico-analytics-server-GoRiLKSi-py3.8/lib/python3.8/site-packages/flask/app.py", line 2091, in __call__
    return self.wsgi_app(environ, start_response)
  File "/home/roberto/.cache/pypoetry/virtualenvs/vico-analytics-server-GoRiLKSi-py3.8/lib/python3.8/site-packages/flask/app.py", line 2076, in wsgi_app
    response = self.handle_exception(e)
  File "/home/roberto/.cache/pypoetry/virtualenvs/vico-analytics-server-GoRiLKSi-py3.8/lib/python3.8/site-packages/flask/app.py", line 2073, in wsgi_app
    response = self.full_dispatch_request()
  File "/home/roberto/.cache/pypoetry/virtualenvs/vico-analytics-server-GoRiLKSi-py3.8/lib/python3.8/site-packages/flask/app.py", line 1518, in full_dispatch_request
    rv = self.handle_user_exception(e)
  File "/home/roberto/.cache/pypoetry/virtualenvs/vico-analytics-server-GoRiLKSi-py3.8/lib/python3.8/site-packages/flask/app.py", line 1516, in full_dispatch_request
    rv = self.dispatch_request()
  File "/home/roberto/.cache/pypoetry/virtualenvs/vico-analytics-server-GoRiLKSi-py3.8/lib/python3.8/site-packages/flask/app.py", line 1502, in dispatch_request
    return self.ensure_sync(self.view_functions[rule.endpoint])(**req.view_args)
  File "/home/roberto/Documents/Lytica/vico-analytics-server/app.py", line 21, in main_acquisition
    response, status = cls_aquisition.main(data=payload_data, file_=payload_file, path=path)
  File "/home/roberto/Documents/Lytica/vico-analytics-server/src/apis/acquisition_api.py", line 93, in main
    response, status = self.validate_queue(response=response, data=data, path=path)
UnboundLocalError: local variable 'response' referenced before assignment
INFO:root:Empty queue
INFO:root:Empty queue
INFO:root:Empty queue
INFO:root:Empty queue
INFO:root:Empty queue
INFO:root:Empty queue
INFO:root:Empty queue
INFO:root:Empty queue
INFO:root:Empty queue
INFO:root:Empty queue
INFO:root:Empty queue
INFO:root:Empty queue
INFO:root:Empty queue
INFO:root:Empty queue
INFO:root:Queued request
INFO:root:Dequeue
INFO:root:Queued request
INFO:root:Dequeue
INFO:root:Queued request
INFO:root:Dequeue
INFO:root:Queued request
INFO:root:Queued request
INFO:root:Dequeue
INFO:root:Queued request
INFO:root:Dequeue
INFO:root:Queued request
INFO:root:Dequeue
INFO:root:Queued request
INFO:root:Dequeue
INFO:root:Queued request
INFO:root:Dequeue
INFO:root:Queued request
INFO:root:Dequeue
INFO:root:Queued request
INFO:root:Dequeue
INFO:root:Queued request
INFO:root:Dequeue
INFO:root:Queued request
INFO:root:Dequeue
INFO:root:Queued request
INFO:root:Dequeue
INFO:root:Queued request
INFO:root:Dequeue
INFO:root:Queued request
INFO:root:Dequeue
INFO:root:Queued request
INFO:root:Dequeue
INFO:root:Queued request
INFO:root:Dequeue
INFO:root:Queued request
INFO:root:Dequeue
INFO:root:Queued request
INFO:root:Dequeue
INFO:root:Queued request
INFO:root:Dequeue
INFO:root:Queued request
INFO:root:Dequeue
INFO:root:Queued request
INFO:root:Dequeue
INFO:root:Queued request
INFO:root:Dequeue
INFO:root:Queued request
INFO:root:Dequeue
INFO:root:Queued request
INFO:root:Dequeue
INFO:root:Queued request
INFO:root:Dequeue
INFO:root:Queued request
INFO:root:Dequeue
INFO:root:Queued request
INFO:root:Dequeue
INFO:root:Queued request
INFO:root:Dequeue
INFO:root:Queued request
INFO:root:Dequeue
INFO:root:Queued request
INFO:root:Dequeue
INFO:root:Queued request
INFO:root:Dequeue
INFO:root:Queued request
INFO:root:Dequeue
INFO:root:Queued request
INFO:root:Dequeue
INFO:root:Queued request
INFO:root:Dequeue
INFO:root:Queued request
INFO:root:Dequeue
INFO:root:Queued request
INFO:root:Dequeue
INFO:root:Queued request
INFO:root:Dequeue
INFO:root:Queued request
INFO:root:Dequeue
INFO:root:Queued request
INFO:root:Dequeue
INFO:root:Queued request
INFO:root:Dequeue
INFO:root:Queued request
INFO:root:Dequeue
INFO:root:Queued request
INFO:root:Dequeue
INFO:root:Queued request
INFO:root:Dequeue
INFO:root:Queued request
INFO:root:Dequeue
INFO:root:Queued request
INFO:root:Dequeue
INFO:root:Queued request
INFO:root:Dequeue
INFO:root:Queued request
INFO:root:Dequeue
INFO:root:Queued request
INFO:root:Dequeue
INFO:root:Queued request
INFO:root:Dequeue
INFO:root:Queued request
INFO:root:Dequeue
INFO:root:Queued request
INFO:root:Dequeue
INFO:root:Queued request
INFO:root:Dequeue
INFO:root:Queued request
INFO:root:Dequeue
INFO:root:Queued request
INFO:root:Dequeue
INFO:root:Queued request
INFO:root:Dequeue
INFO:root:Queued request
INFO:root:Dequeue
INFO:root:Queued request
INFO:root:Dequeue
INFO:root:Queued request
INFO:root:Dequeue
INFO:root:Queued request
INFO:root:Dequeue
INFO:root:Queued request
INFO:root:Dequeue
INFO:root:Queued request
INFO:root:Dequeue
INFO:root:Queued request
INFO:root:Dequeue
INFO:root:Queued request
INFO:root:Dequeue
INFO:root:Queued request
INFO:root:Dequeue
INFO:root:Queued request
INFO:root:Dequeue
INFO:root:Queued request
INFO:root:Dequeue
INFO:root:Queued request
INFO:root:Dequeue
INFO:root:Queued request
INFO:root:Dequeue
INFO:root:Queued request
INFO:root:Dequeue
INFO:root:Queued request
INFO:root:Dequeue
INFO:root:Queued request
INFO:root:Dequeue
INFO:root:Queued request
INFO:root:Dequeue
INFO:root:Queued request
INFO:root:Dequeue
INFO:root:Queued request
INFO:root:Dequeue
INFO:root:Queued request
INFO:root:Dequeue
INFO:root:Queued request
INFO:root:Dequeue
INFO:root:Queued request
INFO:root:Dequeue
INFO:root:Queued request
INFO:root:Dequeue
INFO:root:Queued request
INFO:root:Dequeue
INFO:root:Queued request
INFO:root:Dequeue
INFO:root:Queued request
INFO:root:Dequeue
INFO:root:Queued request
INFO:root:Dequeue
INFO:root:Queued request
INFO:root:Dequeue
INFO:root:Queued request
INFO:root:Dequeue
INFO:root:Queued request
INFO:root:Dequeue
INFO:root:Queued request
INFO:root:Dequeue
INFO:root:Queued request
INFO:root:Dequeue
INFO:root:Queued request
INFO:root:Dequeue
INFO:root:Queued request
INFO:root:Dequeue
INFO:root:Queued request
INFO:root:Dequeue
INFO:root:Queued request
INFO:root:Dequeue
INFO:root:Queued request
INFO:root:Dequeue
INFO:root:Queued request
INFO:root:Dequeue
INFO:root:Queued request
INFO:root:Dequeue
INFO:root:Queued request
INFO:root:Dequeue
INFO:root:Queued request
INFO:root:Dequeue
INFO:root:Queued request
INFO:root:Dequeue
INFO:root:Queued request
INFO:root:Dequeue
INFO:root:Queued request
INFO:root:Dequeue
INFO:root:Queued request
INFO:root:Dequeue
INFO:root:Queued request
INFO:root:Dequeue
INFO:root:Queued request
INFO:root:Dequeue
INFO:root:Queued request
INFO:root:Dequeue
INFO:root:Queued request
INFO:root:Dequeue
INFO:root:Queued request
INFO:root:Dequeue
INFO:root:Queued request
INFO:root:Dequeue
INFO:root:Queued request
INFO:root:Dequeue
INFO:root:Queued request
INFO:root:Dequeue
INFO:root:Queued request
INFO:root:Dequeue
INFO:root:Queued request
INFO:root:Dequeue
INFO:root:Queued request
INFO:root:Dequeue
INFO:root:Queued request
INFO:root:Dequeue
INFO:root:Queued request
INFO:root:Dequeue
INFO:root:Queued request
INFO:root:Dequeue
INFO:root:Queued request
INFO:root:Dequeue
INFO:root:Queued request
INFO:root:Dequeue
INFO:root:Queued request
INFO:root:Dequeue
INFO:root:Queued request
INFO:root:Dequeue
INFO:root:Queued request
INFO:root:Dequeue
INFO:root:Queued request
INFO:root:Dequeue
INFO:root:Queued request
INFO:root:Dequeue
INFO:root:Queued request
INFO:root:Dequeue
INFO:root:Queued request
INFO:root:Dequeue
INFO:root:Queued request
INFO:root:Dequeue
INFO:root:Queued request
INFO:root:Dequeue
INFO:root:Queued request
INFO:root:Dequeue
INFO:root:Queued request
INFO:root:Dequeue
INFO:root:Queued request
INFO:root:Dequeue
INFO:root:Queued request
INFO:root:Dequeue
INFO:root:Queued request
INFO:root:Dequeue
INFO:root:Queued request
INFO:root:Dequeue
INFO:root:Queued request
INFO:root:Dequeue
INFO:root:Queued request
INFO:root:Dequeue
INFO:root:Queued request
INFO:root:Dequeue
INFO:root:Queued request
INFO:root:Dequeue
INFO:root:Queued request
INFO:root:Dequeue
INFO:root:Queued request
INFO:root:Dequeue
INFO:root:Queued request
INFO:root:Dequeue
INFO:root:Queued request
INFO:root:Dequeue
INFO:root:Queued request
INFO:root:Dequeue
INFO:root:Queued request
INFO:root:Dequeue
INFO:root:Queued request
INFO:root:Dequeue
INFO:root:Queued request
INFO:root:Dequeue
INFO:root:Queued request
INFO:root:Dequeue
INFO:root:Queued request
INFO:root:Dequeue
INFO:root:Queued request
INFO:root:Dequeue
INFO:root:Queued request
INFO:root:Dequeue
INFO:root:Queued request
INFO:root:Dequeue
INFO:root:Queued request
INFO:root:Dequeue
INFO:root:Queued request
INFO:root:Dequeue
INFO:root:Queued request
INFO:root:Dequeue
INFO:root:Queued request
INFO:root:Dequeue
INFO:root:Queued request
INFO:root:Dequeue
INFO:root:Queued request
INFO:root:Dequeue
INFO:root:Queued request
INFO:root:Dequeue
INFO:root:Queued request
INFO:root:Dequeue
INFO:root:Queued request
INFO:root:Dequeue
INFO:root:Queued request
INFO:root:Dequeue
INFO:root:Queued request
INFO:root:Dequeue
INFO:root:Queued request
INFO:root:Dequeue
INFO:root:Queued request
INFO:root:Dequeue
INFO:root:Queued request
INFO:root:Dequeue
INFO:root:Queued request
INFO:root:Dequeue
INFO:root:Queued request
INFO:root:Dequeue
INFO:root:Queued request
INFO:root:Dequeue
INFO:root:Queued request
INFO:root:Dequeue
INFO:root:Queued request
INFO:root:Dequeue
INFO:root:Queued request
INFO:root:Dequeue
INFO:root:Queued request
INFO:root:Dequeue
INFO:root:Queued request
INFO:root:Dequeue
INFO:root:Queued request
INFO:root:Dequeue
INFO:root:Queued request
INFO:root:Dequeue
INFO:root:Queued request
INFO:root:Dequeue
INFO:root:Queued request
INFO:root:Dequeue
INFO:root:Queued request
INFO:root:Dequeue
INFO:root:Queued request
INFO:root:Dequeue
INFO:root:Queued request
INFO:root:Dequeue
INFO:root:Queued request
INFO:root:Dequeue
INFO:root:Queued request
INFO:root:Dequeue
INFO:root:Queued request
INFO:root:Dequeue
INFO:root:Queued request
INFO:root:Dequeue
INFO:root:Queued request
INFO:root:Dequeue
INFO:root:Queued request
INFO:root:Dequeue
INFO:root:Queued request
INFO:root:Dequeue
INFO:root:Queued request
INFO:root:Dequeue
INFO:root:Queued request
INFO:root:Dequeue
INFO:root:Queued request
INFO:root:Dequeue
INFO:root:Queued request
INFO:root:Dequeue
INFO:root:Queued request
INFO:root:Dequeue
INFO:root:Queued request
INFO:root:Dequeue
INFO:root:Queued request
INFO:root:Dequeue
INFO:root:Queued request
INFO:root:Dequeue
INFO:root:Queued request
INFO:root:Dequeue
INFO:root:Queued request
INFO:root:Dequeue
INFO:root:Queued request
INFO:root:Dequeue
INFO:root:Queued request
INFO:root:Dequeue
INFO:root:Queued request
INFO:root:Dequeue
INFO:root:Queued request
INFO:root:Dequeue
INFO:root:Queued request
INFO:root:Dequeue
INFO:root:Queued request
INFO:root:Dequeue
INFO:root:Queued request
INFO:root:Dequeue
INFO:root:Queued request
INFO:root:Dequeue
INFO:root:Queued request
INFO:root:Dequeue
INFO:root:Queued request
INFO:root:Dequeue
INFO:root:Queued request
INFO:root:Dequeue
INFO:root:Queued request
INFO:root:Dequeue
INFO:root:Queued request
INFO:root:Dequeue
INFO:root:Queued request
INFO:root:Dequeue
INFO:root:Queued request
INFO:root:Dequeue
INFO:root:Queued request
INFO:root:Dequeue
INFO:root:Queued request
INFO:root:Dequeue
INFO:root:Queued request
INFO:root:Dequeue
INFO:root:Queued request
INFO:root:Dequeue
INFO:root:Queued request
INFO:root:Dequeue
INFO:root:Queued request
INFO:root:Dequeue
INFO:root:Queued request
INFO:root:Dequeue
INFO:root:Queued request
INFO:root:Dequeue
INFO:root:Queued request
INFO:root:Dequeue
INFO:root:Queued request
INFO:root:Dequeue
INFO:root:Queued request
INFO:root:Dequeue
INFO:root:Queued request
INFO:root:Dequeue
INFO:root:Queued request
INFO:root:Dequeue
INFO:root:Queued request
INFO:root:Dequeue
INFO:root:Queued request
INFO:root:Dequeue
INFO:root:Queued request
INFO:root:Dequeue
INFO:root:Queued request
INFO:root:Dequeue
INFO:root:Queued request
INFO:root:Dequeue
INFO:root:Queued request
INFO:root:Dequeue
INFO:root:Queued request
INFO:root:Dequeue
INFO:root:Queued request
INFO:root:Dequeue
INFO:root:Queued request
INFO:root:Dequeue
INFO:root:Queued request
INFO:root:Dequeue
INFO:root:Queued request
INFO:root:Dequeue
INFO:root:Queued request
INFO:root:Dequeue
INFO:root:Queued request
INFO:root:Dequeue
INFO:root:Queued request
INFO:root:Dequeue
INFO:root:Queued request
INFO:root:Dequeue
INFO:root:Queued request
INFO:root:Dequeue
INFO:root:Queued request
INFO:root:Dequeue
INFO:root:Queued request
INFO:root:Dequeue
INFO:root:Queued request
INFO:root:Dequeue
INFO:root:Queued request
INFO:root:Dequeue
INFO:root:Queued request
INFO:root:Dequeue
INFO:root:Queued request
INFO:root:Dequeue
INFO:root:Queued request
INFO:root:Dequeue
INFO:root:Queued request
INFO:root:Dequeue
INFO:root:Queued request
INFO:root:Dequeue
INFO:root:Queued request
INFO:root:Dequeue
INFO:root:Queued request
INFO:root:Dequeue
INFO:root:Queued request
INFO:root:Dequeue
INFO:root:Queued request
INFO:root:Dequeue
INFO:root:Queued request
INFO:root:Dequeue
INFO:root:Queued request
INFO:root:Dequeue
INFO:root:Queued request
INFO:root:Dequeue
INFO:root:Queued request
INFO:root:Dequeue
INFO:root:Queued request
INFO:root:Dequeue
INFO:root:Queued request
INFO:root:Dequeue
INFO:root:Queued request
INFO:root:Dequeue
INFO:root:Queued request
INFO:root:Dequeue
INFO:root:Queued request
INFO:root:Dequeue
INFO:root:Queued request
INFO:root:Dequeue
INFO:root:Queued request
INFO:root:Dequeue
INFO:root:Queued request
INFO:root:Dequeue
INFO:root:Queued request
INFO:root:Dequeue
INFO:root:Queued request
INFO:root:Dequeue
INFO:root:Queued request
INFO:root:Dequeue
INFO:root:Queued request
INFO:root:Dequeue
INFO:root:Queued request
INFO:root:Dequeue
INFO:root:Queued request
INFO:root:Dequeue
INFO:root:Queued request
INFO:root:Dequeue
INFO:root:Queued request
INFO:root:Dequeue
INFO:root:Queued request
INFO:root:Dequeue
INFO:root:Queued request
INFO:root:Dequeue
INFO:root:Queued request
INFO:root:Dequeue
INFO:root:Queued request
INFO:root:Dequeue
INFO:root:Queued request
INFO:root:Dequeue
INFO:root:Queued request
INFO:root:Dequeue
INFO:root:Queued request
INFO:root:Dequeue
INFO:root:Queued request
INFO:root:Dequeue
INFO:root:Queued request
INFO:root:Dequeue
INFO:root:Queued request
INFO:root:Dequeue
INFO:root:Queued request
INFO:root:Dequeue
INFO:root:Queued request
INFO:root:Dequeue
INFO:root:Queued request
INFO:root:Dequeue
INFO:root:Queued request
INFO:root:Dequeue
INFO:root:Queued request
INFO:root:Dequeue
INFO:root:Queued request
INFO:root:Dequeue
INFO:root:Queued request
INFO:root:Dequeue
INFO:root:Queued request
INFO:root:Dequeue
INFO:root:Queued request
INFO:root:Dequeue
INFO:root:Queued request
INFO:root:Dequeue
INFO:root:Queued request
INFO:root:Dequeue
INFO:root:Queued request
INFO:root:Dequeue
INFO:root:Queued request
INFO:root:Dequeue
INFO:root:Queued request
INFO:root:Dequeue
INFO:root:Queued request
INFO:root:Dequeue
INFO:root:Queued request
INFO:root:Dequeue
INFO:root:Queued request
INFO:root:Dequeue
INFO:root:Queued request
INFO:root:Dequeue
INFO:root:Queued request
INFO:root:Dequeue
INFO:root:Queued request
INFO:root:Dequeue
INFO:root:Queued request
INFO:root:Dequeue
INFO:root:Queued request
INFO:root:Dequeue
INFO:root:Queued request
INFO:root:Dequeue
INFO:root:Queued request
INFO:root:Dequeue
INFO:root:Queued request
INFO:root:Dequeue
INFO:root:Queued request
INFO:root:Dequeue
INFO:root:Queued request
INFO:root:Dequeue
INFO:root:Queued request
INFO:root:Dequeue
INFO:root:Queued request
INFO:root:Dequeue
INFO:root:Queued request
INFO:root:Dequeue
INFO:root:Queued request
INFO:root:Dequeue
INFO:root:Queued request
INFO:root:Dequeue
INFO:root:Queued request
INFO:root:Dequeue
INFO:root:Queued request
INFO:root:Dequeue
INFO:root:Queued request
INFO:root:Dequeue
INFO:root:Queued request
INFO:root:Dequeue
INFO:root:Queued request
INFO:root:Dequeue
INFO:root:Queued request
INFO:root:Dequeue
INFO:root:Queued request
INFO:root:Dequeue
INFO:root:Queued request
INFO:root:Dequeue
INFO:root:Queued request
INFO:root:Dequeue
INFO:root:Queued request
INFO:root:Dequeue
INFO:root:Queued request
INFO:root:Dequeue
INFO:root:Queued request
INFO:root:Dequeue
INFO:root:Queued request
INFO:root:Dequeue
INFO:root:Queued request
INFO:root:Dequeue
INFO:root:Queued request
INFO:root:Dequeue
INFO:root:Queued request
INFO:root:Dequeue
INFO:root:Queued request
INFO:root:Dequeue
INFO:root:Queued request
INFO:root:Dequeue
INFO:root:Queued request
INFO:root:Dequeue
INFO:root:Queued request
INFO:root:Dequeue
INFO:root:Queued request
INFO:root:Dequeue
INFO:root:Queued request
INFO:root:Dequeue
INFO:root:Queued request
INFO:root:Dequeue
INFO:root:Queued request
INFO:root:Dequeue
INFO:root:Queued request
INFO:root:Dequeue
INFO:root:Queued request
INFO:root:Dequeue
INFO:root:Queued request
INFO:root:Dequeue
INFO:root:Queued request
INFO:root:Dequeue
INFO:root:Queued request
INFO:root:Dequeue
INFO:root:Queued request
INFO:root:Dequeue
INFO:root:Queued request
INFO:root:Dequeue
INFO:root:Queued request
INFO:root:Dequeue
INFO:root:Queued request
INFO:root:Dequeue
INFO:root:Queued request
INFO:root:Dequeue
INFO:root:Queued request
INFO:root:Dequeue
INFO:root:Queued request
INFO:root:Dequeue
INFO:root:Queued request
INFO:root:Dequeue
INFO:root:Queued request
INFO:root:Dequeue
INFO:root:Queued request
INFO:root:Dequeue
INFO:root:Queued request
INFO:root:Dequeue
INFO:root:Queued request
INFO:root:Dequeue
INFO:root:Queued request
INFO:root:Dequeue
INFO:root:Queued request
INFO:root:Dequeue
INFO:root:Queued request
INFO:root:Dequeue
INFO:root:Queued request
INFO:root:Dequeue
INFO:root:Queued request
INFO:root:Dequeue
INFO:root:Queued request
INFO:root:Dequeue
INFO:root:Queued request
INFO:root:Dequeue
INFO:root:Queued request
INFO:root:Dequeue
INFO:root:Queued request
INFO:root:Dequeue
INFO:root:Queued request
INFO:root:Dequeue
INFO:root:Queued request
INFO:root:Dequeue
INFO:root:Queued request
INFO:root:Dequeue
INFO:root:Queued request
INFO:root:Dequeue
INFO:root:Queued request
INFO:root:Dequeue
INFO:root:Queued request
INFO:root:Dequeue
INFO:root:Queued request
INFO:root:Dequeue
INFO:root:Queued request
INFO:root:Dequeue
INFO:root:Queued request
INFO:root:Dequeue
INFO:root:Queued request
INFO:root:Dequeue
INFO:root:Queued request
INFO:root:Dequeue
INFO:root:Queued request
INFO:root:Dequeue
INFO:root:Queued request
INFO:root:Dequeue
INFO:root:Queued request
INFO:root:Dequeue
INFO:root:Queued request
INFO:root:Dequeue
INFO:root:Queued request
INFO:root:Dequeue
INFO:root:Queued request
INFO:root:Dequeue
INFO:root:Queued request
INFO:root:Dequeue
INFO:root:Queued request
INFO:root:Dequeue
INFO:root:Queued request
INFO:root:Dequeue
INFO:root:Queued request
INFO:root:Dequeue
INFO:root:Queued request
INFO:root:Dequeue
INFO:root:Queued request
INFO:root:Dequeue
INFO:root:Queued request
INFO:root:Dequeue
INFO:root:Queued request
INFO:root:Dequeue
INFO:root:Queued request
INFO:root:Dequeue
INFO:root:Queued request
INFO:root:Dequeue
INFO:root:Queued request
INFO:root:Dequeue
INFO:root:Queued request
INFO:root:Dequeue
INFO:root:Queued request
INFO:root:Dequeue
INFO:root:Queued request
INFO:root:Dequeue
INFO:root:Queued request
INFO:root:Dequeue
INFO:root:Queued request
INFO:root:Dequeue
INFO:root:Queued request
INFO:root:Dequeue
INFO:root:Queued request
INFO:root:Dequeue
INFO:root:Queued request
INFO:root:Dequeue
INFO:root:Queued request
INFO:root:Dequeue
INFO:root:Queued request
INFO:root:Dequeue
INFO:root:Queued request
INFO:root:Dequeue
INFO:root:Queued request
INFO:root:Dequeue
INFO:root:Queued request
INFO:root:Dequeue
INFO:root:Queued request
INFO:root:Dequeue
INFO:root:Queued request
INFO:root:Dequeue
INFO:root:Queued request
INFO:root:Dequeue
INFO:root:Queued request
INFO:root:Dequeue
INFO:root:Queued request
INFO:root:Dequeue
INFO:root:Queued request
INFO:root:Dequeue
INFO:root:Queued request
INFO:root:Dequeue
INFO:root:Queued request
INFO:root:Dequeue
INFO:root:Queued request
INFO:root:Dequeue
INFO:root:Queued request
INFO:root:Dequeue
INFO:root:Queued request
INFO:root:Dequeue
INFO:root:Queued request
INFO:root:Dequeue
INFO:root:Queued request
INFO:root:Dequeue
INFO:root:Queued request
INFO:root:Dequeue
INFO:root:Queued request
INFO:root:Dequeue
INFO:root:Queued request
INFO:root:Dequeue
INFO:root:Queued request
INFO:root:Dequeue
INFO:root:Queued request
INFO:root:Dequeue
INFO:root:Queued request
INFO:root:Dequeue
INFO:root:Queued request
INFO:root:Dequeue
INFO:root:Queued request
INFO:root:Dequeue
INFO:root:Queued request
INFO:root:Dequeue
INFO:root:Queued request
INFO:root:Dequeue
INFO:root:Queued request
INFO:root:Dequeue
INFO:root:Queued request
INFO:root:Dequeue
INFO:root:Queued request
INFO:root:Dequeue
INFO:root:Queued request
INFO:root:Dequeue
INFO:root:Queued request
INFO:root:Dequeue
INFO:root:Queued request
INFO:root:Dequeue
INFO:root:Queued request
INFO:root:Dequeue
INFO:root:Queued request
INFO:root:Dequeue
INFO:root:Queued request
INFO:root:Dequeue
INFO:root:Queued request
INFO:root:Dequeue
INFO:root:Queued request
INFO:root:Dequeue
INFO:root:Queued request
INFO:root:Dequeue
INFO:root:Queued request
INFO:root:Dequeue
INFO:root:Queued request
INFO:root:Dequeue
INFO:root:Queued request
INFO:root:Dequeue
INFO:root:Queued request
INFO:root:Dequeue
INFO:root:Queued request
INFO:root:Dequeue
INFO:root:Queued request
INFO:root:Dequeue
INFO:root:Queued request
INFO:root:Dequeue
INFO:root:Queued request
INFO:root:Dequeue
INFO:root:Queued request
INFO:root:Dequeue
INFO:root:Queued request
INFO:root:Dequeue
INFO:root:Queued request
INFO:root:Dequeue
INFO:root:Queued request
INFO:root:Dequeue
INFO:root:Queued request
INFO:root:Dequeue
INFO:root:Queued request
INFO:root:Dequeue
INFO:root:Queued request
INFO:root:Dequeue
INFO:root:Queued request
INFO:root:Dequeue
INFO:root:Queued request
INFO:root:Dequeue
INFO:root:Queued request
INFO:root:Dequeue
INFO:root:Queued request
INFO:root:Dequeue
INFO:root:Queued request
INFO:root:Dequeue
INFO:root:Queued request
INFO:root:Dequeue
INFO:root:Queued request
INFO:root:Dequeue
INFO:root:Queued request
INFO:root:Dequeue
INFO:root:Queued request
INFO:root:Dequeue
INFO:root:Queued request
INFO:root:Dequeue
INFO:root:Queued request
INFO:root:Dequeue
INFO:root:Queued request
INFO:root:Dequeue
INFO:root:Queued request
INFO:root:Dequeue
INFO:root:Queued request
INFO:root:Dequeue
INFO:root:Queued request
INFO:root:Dequeue
INFO:root:Queued request
INFO:root:Dequeue
INFO:root:Queued request
INFO:root:Dequeue
INFO:root:Queued request
INFO:root:Dequeue
INFO:root:Dequeue
INFO:root:Queued request
INFO:root:Dequeue
INFO:root:Queued request
INFO:root:Dequeue
INFO:root:Empty queue
INFO:root:Empty queue
INFO:root:Empty queue
INFO:root:Empty queue
INFO:root:Empty queue
INFO:root:Empty queue
INFO:root:Empty queue
INFO:root:Empty queue
INFO:root:Empty queue
INFO:root:Empty queue
INFO:root:Empty queue
INFO:root:Empty queue
INFO:root:Empty queue
INFO:root:Empty queue
INFO:root:Empty queue
INFO:root:Empty queue
INFO:root:Empty queue
INFO:root:Empty queue
INFO:root:Empty queue
INFO:root:Empty queue
INFO:root:Empty queue
INFO:root:Empty queue
INFO:root:Empty queue
INFO:root:Empty queue
INFO:root:Empty queue
INFO:root:Empty queue
INFO:root:Empty queue
INFO:root:Empty queue
INFO:root:Empty queue
INFO:root:Empty queue
INFO:root:Empty queue
INFO:root:Empty queue
INFO:root:Empty queue
INFO:root:Empty queue
INFO:root:Empty queue
INFO:root:Empty queue
INFO:root:Empty queue
INFO:root:Empty queue
INFO:root:Empty queue
INFO:root:Empty queue
INFO:root:Empty queue
INFO:root:Empty queue
INFO:root:Empty queue
INFO:root:Empty queue
INFO:root:Empty queue
INFO:root:Empty queue
INFO:root:Empty queue
INFO:root:Empty queue
INFO:root:Empty queue
INFO:root:Empty queue
INFO:root:Empty queue
INFO:root:Empty queue
INFO:root:Empty queue
INFO:root:Empty queue
INFO:root:Empty queue
INFO:root:Empty queue
INFO:root:Empty queue
INFO:root:Empty queue
INFO:root:Empty queue
INFO:root:Empty queue
INFO:root:Empty queue
INFO:root:Empty queue
INFO:root:Empty queue
INFO:root:Empty queue
INFO:root:Empty queue
INFO:root:Empty queue
INFO:root:Empty queue
INFO:root:Empty queue
INFO:root:Empty queue
INFO:root:Empty queue
INFO:root:Empty queue
INFO:root:Empty queue
INFO:root:Empty queue
INFO:root:Empty queue
INFO:root:Empty queue
INFO:root:Empty queue
INFO:root:Empty queue
INFO:root:Empty queue
INFO:root:Empty queue
INFO:root:Empty queue
INFO:root:Empty queue
INFO:root:Empty queue
INFO:root:Empty queue
INFO:root:Empty queue
INFO:root:Empty queue
INFO:root:Empty queue
INFO:root:Empty queue
INFO:root:Empty queue
INFO:root:Empty queue
INFO:root:Empty queue
INFO:root:Empty queue
INFO:root:Empty queue
INFO:root:Empty queue
INFO:root:Empty queue
INFO:root:Empty queue
INFO:root:Empty queue
INFO:root:Empty queue
INFO:root:Empty queue
INFO:root:Empty queue
INFO:root:Empty queue
INFO:root:Empty queue
INFO:root:Empty queue
INFO:root:Empty queue
INFO:root:Empty queue
INFO:root:Empty queue
INFO:root:Empty queue
INFO:root:Empty queue
INFO:root:Empty queue
INFO:root:Empty queue
INFO:root:Empty queue
INFO:root:Empty queue
INFO:root:Empty queue
INFO:root:Empty queue
INFO:root:Empty queue
INFO:root:Empty queue
INFO:root:Empty queue
INFO:root:Empty queue
INFO:root:Empty queue
INFO:root:Empty queue
INFO:root:Empty queue
INFO:root:Empty queue
INFO:root:Empty queue
INFO:root:Empty queue
INFO:root:Empty queue
INFO:root:Empty queue
INFO:root:Empty queue
INFO:root:Empty queue
INFO:root:Empty queue
INFO:root:Empty queue
INFO:root:Empty queue
INFO:root:Empty queue
INFO:root:Empty queue
INFO:root:Empty queue
INFO:root:Empty queue
INFO:root:Empty queue
INFO:root:Empty queue
INFO:root:Empty queue
INFO:root:Empty queue
INFO:root:Empty queue
INFO:root:Empty queue
INFO:root:Empty queue
INFO:root:Empty queue
INFO:werkzeug: * Running on http://127.0.0.1:5000/ (Press CTRL+C to quit)
INFO:werkzeug: * Restarting with stat
INFO:werkzeug: * Running on http://127.0.0.1:5000/ (Press CTRL+C to quit)
INFO:werkzeug: * Restarting with stat
INFO:werkzeug: * Detected change in '/home/roberto/Documents/Lytica/vico-analytics-server/src/apis/acquisition_api.py', reloading
INFO:werkzeug: * Restarting with stat
INFO:werkzeug: * Detected change in '/home/roberto/Documents/Lytica/vico-analytics-server/src/apis/acquisition_api.py', reloading
INFO:werkzeug: * Restarting with stat
INFO:werkzeug: * Running on http://127.0.0.1:5000/ (Press CTRL+C to quit)
INFO:werkzeug: * Restarting with stat
INFO:werkzeug: * Detected change in '/home/roberto/Documents/Lytica/vico-analytics-server/src/apis/acquisition_api.py', reloading
INFO:werkzeug: * Restarting with stat
INFO:werkzeug:127.0.0.1 - - [01/Mar/2022 12:35:29] "[35m[1mPOST /acquisition/visitor-counter/ HTTP/1.1[0m" 500 -
ERROR:werkzeug:Error on request:
Traceback (most recent call last):
  File "/home/roberto/.cache/pypoetry/virtualenvs/vico-analytics-server-GoRiLKSi-py3.8/lib/python3.8/site-packages/werkzeug/serving.py", line 324, in run_wsgi
    execute(self.server.app)
  File "/home/roberto/.cache/pypoetry/virtualenvs/vico-analytics-server-GoRiLKSi-py3.8/lib/python3.8/site-packages/werkzeug/serving.py", line 313, in execute
    application_iter = app(environ, start_response)
  File "/home/roberto/.cache/pypoetry/virtualenvs/vico-analytics-server-GoRiLKSi-py3.8/lib/python3.8/site-packages/flask/app.py", line 2091, in __call__
    return self.wsgi_app(environ, start_response)
  File "/home/roberto/.cache/pypoetry/virtualenvs/vico-analytics-server-GoRiLKSi-py3.8/lib/python3.8/site-packages/flask/app.py", line 2076, in wsgi_app
    response = self.handle_exception(e)
  File "/home/roberto/.cache/pypoetry/virtualenvs/vico-analytics-server-GoRiLKSi-py3.8/lib/python3.8/site-packages/flask/app.py", line 2073, in wsgi_app
    response = self.full_dispatch_request()
  File "/home/roberto/.cache/pypoetry/virtualenvs/vico-analytics-server-GoRiLKSi-py3.8/lib/python3.8/site-packages/flask/app.py", line 1518, in full_dispatch_request
    rv = self.handle_user_exception(e)
  File "/home/roberto/.cache/pypoetry/virtualenvs/vico-analytics-server-GoRiLKSi-py3.8/lib/python3.8/site-packages/flask/app.py", line 1516, in full_dispatch_request
    rv = self.dispatch_request()
  File "/home/roberto/.cache/pypoetry/virtualenvs/vico-analytics-server-GoRiLKSi-py3.8/lib/python3.8/site-packages/flask/app.py", line 1502, in dispatch_request
    return self.ensure_sync(self.view_functions[rule.endpoint])(**req.view_args)
  File "/home/roberto/Documents/Lytica/vico-analytics-server/app.py", line 21, in main_acquisition
    response, status = cls_aquisition.main(data=payload_data, file_=payload_file, path=path)
  File "/home/roberto/Documents/Lytica/vico-analytics-server/src/apis/acquisition_api.py", line 90, in main
    response, status = self.validate_queue(response=response, data=data, path=path)
UnboundLocalError: local variable 'response' referenced before assignment
INFO:werkzeug: * Detected change in '/home/roberto/Documents/Lytica/vico-analytics-server/src/apis/acquisition_api.py', reloading
INFO:werkzeug: * Restarting with stat
INFO:werkzeug:127.0.0.1 - - [01/Mar/2022 12:36:27] "[35m[1mPOST /acquisition/visitor-counter/ HTTP/1.1[0m" 500 -
ERROR:werkzeug:Error on request:
Traceback (most recent call last):
  File "/home/roberto/.cache/pypoetry/virtualenvs/vico-analytics-server-GoRiLKSi-py3.8/lib/python3.8/site-packages/werkzeug/serving.py", line 324, in run_wsgi
    execute(self.server.app)
  File "/home/roberto/.cache/pypoetry/virtualenvs/vico-analytics-server-GoRiLKSi-py3.8/lib/python3.8/site-packages/werkzeug/serving.py", line 313, in execute
    application_iter = app(environ, start_response)
  File "/home/roberto/.cache/pypoetry/virtualenvs/vico-analytics-server-GoRiLKSi-py3.8/lib/python3.8/site-packages/flask/app.py", line 2091, in __call__
    return self.wsgi_app(environ, start_response)
  File "/home/roberto/.cache/pypoetry/virtualenvs/vico-analytics-server-GoRiLKSi-py3.8/lib/python3.8/site-packages/flask/app.py", line 2076, in wsgi_app
    response = self.handle_exception(e)
  File "/home/roberto/.cache/pypoetry/virtualenvs/vico-analytics-server-GoRiLKSi-py3.8/lib/python3.8/site-packages/flask/app.py", line 2073, in wsgi_app
    response = self.full_dispatch_request()
  File "/home/roberto/.cache/pypoetry/virtualenvs/vico-analytics-server-GoRiLKSi-py3.8/lib/python3.8/site-packages/flask/app.py", line 1518, in full_dispatch_request
    rv = self.handle_user_exception(e)
  File "/home/roberto/.cache/pypoetry/virtualenvs/vico-analytics-server-GoRiLKSi-py3.8/lib/python3.8/site-packages/flask/app.py", line 1516, in full_dispatch_request
    rv = self.dispatch_request()
  File "/home/roberto/.cache/pypoetry/virtualenvs/vico-analytics-server-GoRiLKSi-py3.8/lib/python3.8/site-packages/flask/app.py", line 1502, in dispatch_request
    return self.ensure_sync(self.view_functions[rule.endpoint])(**req.view_args)
  File "/home/roberto/Documents/Lytica/vico-analytics-server/app.py", line 21, in main_acquisition
    response, status = cls_aquisition.main(data=payload_data, file_=payload_file, path=path)
  File "/home/roberto/Documents/Lytica/vico-analytics-server/src/apis/acquisition_api.py", line 90, in main
    response, status = self.validate_queue(response=response, data=data, path=path)
UnboundLocalError: local variable 'response' referenced before assignment
INFO:werkzeug: * Detected change in '/home/roberto/Documents/Lytica/vico-analytics-server/src/apis/acquisition_api.py', reloading
INFO:werkzeug: * Restarting with stat
INFO:root:Queued request
INFO:werkzeug:127.0.0.1 - - [01/Mar/2022 12:38:31] "[35m[1mPOST /acquisition/visitor-counter/ HTTP/1.1[0m" 500 -
ERROR:werkzeug:Error on request:
Traceback (most recent call last):
  File "/home/roberto/.cache/pypoetry/virtualenvs/vico-analytics-server-GoRiLKSi-py3.8/lib/python3.8/site-packages/urllib3/connection.py", line 174, in _new_conn
    conn = connection.create_connection(
  File "/home/roberto/.cache/pypoetry/virtualenvs/vico-analytics-server-GoRiLKSi-py3.8/lib/python3.8/site-packages/urllib3/util/connection.py", line 72, in create_connection
    for res in socket.getaddrinfo(host, port, family, socket.SOCK_STREAM):
  File "/usr/lib/python3.8/socket.py", line 918, in getaddrinfo
    for res in _socket.getaddrinfo(host, port, family, type, proto, flags):
socket.gaierror: [Errno -3] Temporary failure in name resolution

During handling of the above exception, another exception occurred:

Traceback (most recent call last):
  File "/home/roberto/.cache/pypoetry/virtualenvs/vico-analytics-server-GoRiLKSi-py3.8/lib/python3.8/site-packages/urllib3/connectionpool.py", line 703, in urlopen
    httplib_response = self._make_request(
  File "/home/roberto/.cache/pypoetry/virtualenvs/vico-analytics-server-GoRiLKSi-py3.8/lib/python3.8/site-packages/urllib3/connectionpool.py", line 386, in _make_request
    self._validate_conn(conn)
  File "/home/roberto/.cache/pypoetry/virtualenvs/vico-analytics-server-GoRiLKSi-py3.8/lib/python3.8/site-packages/urllib3/connectionpool.py", line 1040, in _validate_conn
    conn.connect()
  File "/home/roberto/.cache/pypoetry/virtualenvs/vico-analytics-server-GoRiLKSi-py3.8/lib/python3.8/site-packages/urllib3/connection.py", line 358, in connect
    conn = self._new_conn()
  File "/home/roberto/.cache/pypoetry/virtualenvs/vico-analytics-server-GoRiLKSi-py3.8/lib/python3.8/site-packages/urllib3/connection.py", line 186, in _new_conn
    raise NewConnectionError(
urllib3.exceptions.NewConnectionError: <urllib3.connection.HTTPSConnection object at 0x7fc216f3c490>: Failed to establish a new connection: [Errno -3] Temporary failure in name resolution

During handling of the above exception, another exception occurred:

Traceback (most recent call last):
  File "/home/roberto/.cache/pypoetry/virtualenvs/vico-analytics-server-GoRiLKSi-py3.8/lib/python3.8/site-packages/requests/adapters.py", line 440, in send
    resp = conn.urlopen(
  File "/home/roberto/.cache/pypoetry/virtualenvs/vico-analytics-server-GoRiLKSi-py3.8/lib/python3.8/site-packages/urllib3/connectionpool.py", line 785, in urlopen
    retries = retries.increment(
  File "/home/roberto/.cache/pypoetry/virtualenvs/vico-analytics-server-GoRiLKSi-py3.8/lib/python3.8/site-packages/urllib3/util/retry.py", line 592, in increment
    raise MaxRetryError(_pool, url, error or ResponseError(cause))
urllib3.exceptions.MaxRetryError: HTTPSConnectionPool(host='dev.vico.ai', port=443): Max retries exceeded with url: /acquisition/visitor-counter/ (Caused by NewConnectionError('<urllib3.connection.HTTPSConnection object at 0x7fc216f3c490>: Failed to establish a new connection: [Errno -3] Temporary failure in name resolution'))

During handling of the above exception, another exception occurred:

Traceback (most recent call last):
  File "/home/roberto/Documents/Lytica/vico-analytics-server/src/apis/acquisition_api.py", line 64, in validate_queue
    response = requests.post(url=url, files=data,)
  File "/home/roberto/.cache/pypoetry/virtualenvs/vico-analytics-server-GoRiLKSi-py3.8/lib/python3.8/site-packages/requests/api.py", line 117, in post
    return request('post', url, data=data, json=json, **kwargs)
  File "/home/roberto/.cache/pypoetry/virtualenvs/vico-analytics-server-GoRiLKSi-py3.8/lib/python3.8/site-packages/requests/api.py", line 61, in request
    return session.request(method=method, url=url, **kwargs)
  File "/home/roberto/.cache/pypoetry/virtualenvs/vico-analytics-server-GoRiLKSi-py3.8/lib/python3.8/site-packages/requests/sessions.py", line 529, in request
    resp = self.send(prep, **send_kwargs)
  File "/home/roberto/.cache/pypoetry/virtualenvs/vico-analytics-server-GoRiLKSi-py3.8/lib/python3.8/site-packages/requests/sessions.py", line 645, in send
    r = adapter.send(request, **kwargs)
  File "/home/roberto/.cache/pypoetry/virtualenvs/vico-analytics-server-GoRiLKSi-py3.8/lib/python3.8/site-packages/requests/adapters.py", line 519, in send
    raise ConnectionError(e, request=request)
requests.exceptions.ConnectionError: HTTPSConnectionPool(host='dev.vico.ai', port=443): Max retries exceeded with url: /acquisition/visitor-counter/ (Caused by NewConnectionError('<urllib3.connection.HTTPSConnection object at 0x7fc216f3c490>: Failed to establish a new connection: [Errno -3] Temporary failure in name resolution'))

During handling of the above exception, another exception occurred:

Traceback (most recent call last):
  File "/home/roberto/.cache/pypoetry/virtualenvs/vico-analytics-server-GoRiLKSi-py3.8/lib/python3.8/site-packages/werkzeug/serving.py", line 324, in run_wsgi
    execute(self.server.app)
  File "/home/roberto/.cache/pypoetry/virtualenvs/vico-analytics-server-GoRiLKSi-py3.8/lib/python3.8/site-packages/werkzeug/serving.py", line 313, in execute
    application_iter = app(environ, start_response)
  File "/home/roberto/.cache/pypoetry/virtualenvs/vico-analytics-server-GoRiLKSi-py3.8/lib/python3.8/site-packages/flask/app.py", line 2091, in __call__
    return self.wsgi_app(environ, start_response)
  File "/home/roberto/.cache/pypoetry/virtualenvs/vico-analytics-server-GoRiLKSi-py3.8/lib/python3.8/site-packages/flask/app.py", line 2076, in wsgi_app
    response = self.handle_exception(e)
  File "/home/roberto/.cache/pypoetry/virtualenvs/vico-analytics-server-GoRiLKSi-py3.8/lib/python3.8/site-packages/flask/app.py", line 2073, in wsgi_app
    response = self.full_dispatch_request()
  File "/home/roberto/.cache/pypoetry/virtualenvs/vico-analytics-server-GoRiLKSi-py3.8/lib/python3.8/site-packages/flask/app.py", line 1518, in full_dispatch_request
    rv = self.handle_user_exception(e)
  File "/home/roberto/.cache/pypoetry/virtualenvs/vico-analytics-server-GoRiLKSi-py3.8/lib/python3.8/site-packages/flask/app.py", line 1516, in full_dispatch_request
    rv = self.dispatch_request()
  File "/home/roberto/.cache/pypoetry/virtualenvs/vico-analytics-server-GoRiLKSi-py3.8/lib/python3.8/site-packages/flask/app.py", line 1502, in dispatch_request
    return self.ensure_sync(self.view_functions[rule.endpoint])(**req.view_args)
  File "/home/roberto/Documents/Lytica/vico-analytics-server/app.py", line 21, in main_acquisition
    response, status = cls_aquisition.main(data=payload_data, file_=payload_file, path=path)
  File "/home/roberto/Documents/Lytica/vico-analytics-server/src/apis/acquisition_api.py", line 90, in main
    response, status = self.validate_queue(data=data, path=path)
  File "/home/roberto/Documents/Lytica/vico-analytics-server/src/apis/acquisition_api.py", line 75, in validate_queue
    return response.content, response.status_code
UnboundLocalError: local variable 'response' referenced before assignment
INFO:werkzeug:127.0.0.1 - - [01/Mar/2022 12:44:58] "[35m[1mPOST /acquisition/visitor-counter/ HTTP/1.1[0m" 201 -
INFO:werkzeug:127.0.0.1 - - [01/Mar/2022 12:46:13] "[35m[1mPOST /acquisition/visitor-counter/ HTTP/1.1[0m" 201 -
INFO:werkzeug: * Detected change in '/home/roberto/Documents/Lytica/vico-analytics-server/src/apis/acquisition_api.py', reloading
INFO:werkzeug: * Restarting with stat
INFO:werkzeug: * Detected change in '/home/roberto/Documents/Lytica/vico-analytics-server/src/apis/acquisition_api.py', reloading
INFO:werkzeug: * Restarting with stat
INFO:werkzeug:127.0.0.1 - - [01/Mar/2022 12:49:33] "[35m[1mPOST /acquisition/visitor-counter/ HTTP/1.1[0m" 201 -
INFO:root:Queued request
INFO:werkzeug:127.0.0.1 - - [01/Mar/2022 12:50:51] "[35m[1mPOST /acquisition/visitor-counter/ HTTP/1.1[0m" 500 -
ERROR:werkzeug:Error on request:
Traceback (most recent call last):
  File "/home/roberto/.cache/pypoetry/virtualenvs/vico-analytics-server-GoRiLKSi-py3.8/lib/python3.8/site-packages/urllib3/connection.py", line 174, in _new_conn
    conn = connection.create_connection(
  File "/home/roberto/.cache/pypoetry/virtualenvs/vico-analytics-server-GoRiLKSi-py3.8/lib/python3.8/site-packages/urllib3/util/connection.py", line 72, in create_connection
    for res in socket.getaddrinfo(host, port, family, socket.SOCK_STREAM):
  File "/usr/lib/python3.8/socket.py", line 918, in getaddrinfo
    for res in _socket.getaddrinfo(host, port, family, type, proto, flags):
socket.gaierror: [Errno -3] Temporary failure in name resolution

During handling of the above exception, another exception occurred:

Traceback (most recent call last):
  File "/home/roberto/.cache/pypoetry/virtualenvs/vico-analytics-server-GoRiLKSi-py3.8/lib/python3.8/site-packages/urllib3/connectionpool.py", line 703, in urlopen
    httplib_response = self._make_request(
  File "/home/roberto/.cache/pypoetry/virtualenvs/vico-analytics-server-GoRiLKSi-py3.8/lib/python3.8/site-packages/urllib3/connectionpool.py", line 386, in _make_request
    self._validate_conn(conn)
  File "/home/roberto/.cache/pypoetry/virtualenvs/vico-analytics-server-GoRiLKSi-py3.8/lib/python3.8/site-packages/urllib3/connectionpool.py", line 1040, in _validate_conn
    conn.connect()
  File "/home/roberto/.cache/pypoetry/virtualenvs/vico-analytics-server-GoRiLKSi-py3.8/lib/python3.8/site-packages/urllib3/connection.py", line 358, in connect
    conn = self._new_conn()
  File "/home/roberto/.cache/pypoetry/virtualenvs/vico-analytics-server-GoRiLKSi-py3.8/lib/python3.8/site-packages/urllib3/connection.py", line 186, in _new_conn
    raise NewConnectionError(
urllib3.exceptions.NewConnectionError: <urllib3.connection.HTTPSConnection object at 0x7fb4a5e4c730>: Failed to establish a new connection: [Errno -3] Temporary failure in name resolution

During handling of the above exception, another exception occurred:

Traceback (most recent call last):
  File "/home/roberto/.cache/pypoetry/virtualenvs/vico-analytics-server-GoRiLKSi-py3.8/lib/python3.8/site-packages/requests/adapters.py", line 440, in send
    resp = conn.urlopen(
  File "/home/roberto/.cache/pypoetry/virtualenvs/vico-analytics-server-GoRiLKSi-py3.8/lib/python3.8/site-packages/urllib3/connectionpool.py", line 785, in urlopen
    retries = retries.increment(
  File "/home/roberto/.cache/pypoetry/virtualenvs/vico-analytics-server-GoRiLKSi-py3.8/lib/python3.8/site-packages/urllib3/util/retry.py", line 592, in increment
    raise MaxRetryError(_pool, url, error or ResponseError(cause))
urllib3.exceptions.MaxRetryError: HTTPSConnectionPool(host='dev.vico.ai', port=443): Max retries exceeded with url: /acquisition/visitor-counter/ (Caused by NewConnectionError('<urllib3.connection.HTTPSConnection object at 0x7fb4a5e4c730>: Failed to establish a new connection: [Errno -3] Temporary failure in name resolution'))

During handling of the above exception, another exception occurred:

Traceback (most recent call last):
  File "/home/roberto/Documents/Lytica/vico-analytics-server/src/apis/acquisition_api.py", line 62, in validate_queue
    response = self.send_api_data(payload=data, path=path)
  File "/home/roberto/Documents/Lytica/vico-analytics-server/src/apis/acquisition_api.py", line 34, in send_api_data
    response = requests.post(url=url, files=payload,)
  File "/home/roberto/.cache/pypoetry/virtualenvs/vico-analytics-server-GoRiLKSi-py3.8/lib/python3.8/site-packages/requests/api.py", line 117, in post
    return request('post', url, data=data, json=json, **kwargs)
  File "/home/roberto/.cache/pypoetry/virtualenvs/vico-analytics-server-GoRiLKSi-py3.8/lib/python3.8/site-packages/requests/api.py", line 61, in request
    return session.request(method=method, url=url, **kwargs)
  File "/home/roberto/.cache/pypoetry/virtualenvs/vico-analytics-server-GoRiLKSi-py3.8/lib/python3.8/site-packages/requests/sessions.py", line 529, in request
    resp = self.send(prep, **send_kwargs)
  File "/home/roberto/.cache/pypoetry/virtualenvs/vico-analytics-server-GoRiLKSi-py3.8/lib/python3.8/site-packages/requests/sessions.py", line 645, in send
    r = adapter.send(request, **kwargs)
  File "/home/roberto/.cache/pypoetry/virtualenvs/vico-analytics-server-GoRiLKSi-py3.8/lib/python3.8/site-packages/requests/adapters.py", line 519, in send
    raise ConnectionError(e, request=request)
requests.exceptions.ConnectionError: HTTPSConnectionPool(host='dev.vico.ai', port=443): Max retries exceeded with url: /acquisition/visitor-counter/ (Caused by NewConnectionError('<urllib3.connection.HTTPSConnection object at 0x7fb4a5e4c730>: Failed to establish a new connection: [Errno -3] Temporary failure in name resolution'))

During handling of the above exception, another exception occurred:

Traceback (most recent call last):
  File "/home/roberto/.cache/pypoetry/virtualenvs/vico-analytics-server-GoRiLKSi-py3.8/lib/python3.8/site-packages/werkzeug/serving.py", line 324, in run_wsgi
    execute(self.server.app)
  File "/home/roberto/.cache/pypoetry/virtualenvs/vico-analytics-server-GoRiLKSi-py3.8/lib/python3.8/site-packages/werkzeug/serving.py", line 313, in execute
    application_iter = app(environ, start_response)
  File "/home/roberto/.cache/pypoetry/virtualenvs/vico-analytics-server-GoRiLKSi-py3.8/lib/python3.8/site-packages/flask/app.py", line 2091, in __call__
    return self.wsgi_app(environ, start_response)
  File "/home/roberto/.cache/pypoetry/virtualenvs/vico-analytics-server-GoRiLKSi-py3.8/lib/python3.8/site-packages/flask/app.py", line 2076, in wsgi_app
    response = self.handle_exception(e)
  File "/home/roberto/.cache/pypoetry/virtualenvs/vico-analytics-server-GoRiLKSi-py3.8/lib/python3.8/site-packages/flask/app.py", line 2073, in wsgi_app
    response = self.full_dispatch_request()
  File "/home/roberto/.cache/pypoetry/virtualenvs/vico-analytics-server-GoRiLKSi-py3.8/lib/python3.8/site-packages/flask/app.py", line 1518, in full_dispatch_request
    rv = self.handle_user_exception(e)
  File "/home/roberto/.cache/pypoetry/virtualenvs/vico-analytics-server-GoRiLKSi-py3.8/lib/python3.8/site-packages/flask/app.py", line 1516, in full_dispatch_request
    rv = self.dispatch_request()
  File "/home/roberto/.cache/pypoetry/virtualenvs/vico-analytics-server-GoRiLKSi-py3.8/lib/python3.8/site-packages/flask/app.py", line 1502, in dispatch_request
    return self.ensure_sync(self.view_functions[rule.endpoint])(**req.view_args)
  File "/home/roberto/Documents/Lytica/vico-analytics-server/app.py", line 21, in main_acquisition
    response, status = cls_aquisition.main(data=payload_data, file_=payload_file, path=path)
  File "/home/roberto/Documents/Lytica/vico-analytics-server/src/apis/acquisition_api.py", line 88, in main
    response, status = self.validate_queue(data=data, path=path)
  File "/home/roberto/Documents/Lytica/vico-analytics-server/src/apis/acquisition_api.py", line 74, in validate_queue
    return response.content, response.status_code
UnboundLocalError: local variable 'response' referenced before assignment
INFO:root:Queued request
INFO:werkzeug:127.0.0.1 - - [01/Mar/2022 12:55:30] "[35m[1mPOST /acquisition/visitor-counter/ HTTP/1.1[0m" 500 -
ERROR:werkzeug:Error on request:
Traceback (most recent call last):
  File "/home/roberto/.cache/pypoetry/virtualenvs/vico-analytics-server-GoRiLKSi-py3.8/lib/python3.8/site-packages/urllib3/connection.py", line 174, in _new_conn
    conn = connection.create_connection(
  File "/home/roberto/.cache/pypoetry/virtualenvs/vico-analytics-server-GoRiLKSi-py3.8/lib/python3.8/site-packages/urllib3/util/connection.py", line 72, in create_connection
    for res in socket.getaddrinfo(host, port, family, socket.SOCK_STREAM):
  File "/usr/lib/python3.8/socket.py", line 918, in getaddrinfo
    for res in _socket.getaddrinfo(host, port, family, type, proto, flags):
socket.gaierror: [Errno -3] Temporary failure in name resolution

During handling of the above exception, another exception occurred:

Traceback (most recent call last):
  File "/home/roberto/.cache/pypoetry/virtualenvs/vico-analytics-server-GoRiLKSi-py3.8/lib/python3.8/site-packages/urllib3/connectionpool.py", line 703, in urlopen
    httplib_response = self._make_request(
  File "/home/roberto/.cache/pypoetry/virtualenvs/vico-analytics-server-GoRiLKSi-py3.8/lib/python3.8/site-packages/urllib3/connectionpool.py", line 386, in _make_request
    self._validate_conn(conn)
  File "/home/roberto/.cache/pypoetry/virtualenvs/vico-analytics-server-GoRiLKSi-py3.8/lib/python3.8/site-packages/urllib3/connectionpool.py", line 1040, in _validate_conn
    conn.connect()
  File "/home/roberto/.cache/pypoetry/virtualenvs/vico-analytics-server-GoRiLKSi-py3.8/lib/python3.8/site-packages/urllib3/connection.py", line 358, in connect
    conn = self._new_conn()
  File "/home/roberto/.cache/pypoetry/virtualenvs/vico-analytics-server-GoRiLKSi-py3.8/lib/python3.8/site-packages/urllib3/connection.py", line 186, in _new_conn
    raise NewConnectionError(
urllib3.exceptions.NewConnectionError: <urllib3.connection.HTTPSConnection object at 0x7fb4a4e4fd00>: Failed to establish a new connection: [Errno -3] Temporary failure in name resolution

During handling of the above exception, another exception occurred:

Traceback (most recent call last):
  File "/home/roberto/.cache/pypoetry/virtualenvs/vico-analytics-server-GoRiLKSi-py3.8/lib/python3.8/site-packages/requests/adapters.py", line 440, in send
    resp = conn.urlopen(
  File "/home/roberto/.cache/pypoetry/virtualenvs/vico-analytics-server-GoRiLKSi-py3.8/lib/python3.8/site-packages/urllib3/connectionpool.py", line 785, in urlopen
    retries = retries.increment(
  File "/home/roberto/.cache/pypoetry/virtualenvs/vico-analytics-server-GoRiLKSi-py3.8/lib/python3.8/site-packages/urllib3/util/retry.py", line 592, in increment
    raise MaxRetryError(_pool, url, error or ResponseError(cause))
urllib3.exceptions.MaxRetryError: HTTPSConnectionPool(host='dev.vico.ai', port=443): Max retries exceeded with url: /acquisition/visitor-counter/ (Caused by NewConnectionError('<urllib3.connection.HTTPSConnection object at 0x7fb4a4e4fd00>: Failed to establish a new connection: [Errno -3] Temporary failure in name resolution'))

During handling of the above exception, another exception occurred:

Traceback (most recent call last):
  File "/home/roberto/Documents/Lytica/vico-analytics-server/src/apis/acquisition_api.py", line 62, in validate_queue
    response = self.send_api_data(payload=data, path=path)
  File "/home/roberto/Documents/Lytica/vico-analytics-server/src/apis/acquisition_api.py", line 34, in send_api_data
    response = requests.post(url=url, files=payload,)
  File "/home/roberto/.cache/pypoetry/virtualenvs/vico-analytics-server-GoRiLKSi-py3.8/lib/python3.8/site-packages/requests/api.py", line 117, in post
    return request('post', url, data=data, json=json, **kwargs)
  File "/home/roberto/.cache/pypoetry/virtualenvs/vico-analytics-server-GoRiLKSi-py3.8/lib/python3.8/site-packages/requests/api.py", line 61, in request
    return session.request(method=method, url=url, **kwargs)
  File "/home/roberto/.cache/pypoetry/virtualenvs/vico-analytics-server-GoRiLKSi-py3.8/lib/python3.8/site-packages/requests/sessions.py", line 529, in request
    resp = self.send(prep, **send_kwargs)
  File "/home/roberto/.cache/pypoetry/virtualenvs/vico-analytics-server-GoRiLKSi-py3.8/lib/python3.8/site-packages/requests/sessions.py", line 645, in send
    r = adapter.send(request, **kwargs)
  File "/home/roberto/.cache/pypoetry/virtualenvs/vico-analytics-server-GoRiLKSi-py3.8/lib/python3.8/site-packages/requests/adapters.py", line 519, in send
    raise ConnectionError(e, request=request)
requests.exceptions.ConnectionError: HTTPSConnectionPool(host='dev.vico.ai', port=443): Max retries exceeded with url: /acquisition/visitor-counter/ (Caused by NewConnectionError('<urllib3.connection.HTTPSConnection object at 0x7fb4a4e4fd00>: Failed to establish a new connection: [Errno -3] Temporary failure in name resolution'))

During handling of the above exception, another exception occurred:

Traceback (most recent call last):
  File "/home/roberto/.cache/pypoetry/virtualenvs/vico-analytics-server-GoRiLKSi-py3.8/lib/python3.8/site-packages/werkzeug/serving.py", line 324, in run_wsgi
    execute(self.server.app)
  File "/home/roberto/.cache/pypoetry/virtualenvs/vico-analytics-server-GoRiLKSi-py3.8/lib/python3.8/site-packages/werkzeug/serving.py", line 313, in execute
    application_iter = app(environ, start_response)
  File "/home/roberto/.cache/pypoetry/virtualenvs/vico-analytics-server-GoRiLKSi-py3.8/lib/python3.8/site-packages/flask/app.py", line 2091, in __call__
    return self.wsgi_app(environ, start_response)
  File "/home/roberto/.cache/pypoetry/virtualenvs/vico-analytics-server-GoRiLKSi-py3.8/lib/python3.8/site-packages/flask/app.py", line 2076, in wsgi_app
    response = self.handle_exception(e)
  File "/home/roberto/.cache/pypoetry/virtualenvs/vico-analytics-server-GoRiLKSi-py3.8/lib/python3.8/site-packages/flask/app.py", line 2073, in wsgi_app
    response = self.full_dispatch_request()
  File "/home/roberto/.cache/pypoetry/virtualenvs/vico-analytics-server-GoRiLKSi-py3.8/lib/python3.8/site-packages/flask/app.py", line 1518, in full_dispatch_request
    rv = self.handle_user_exception(e)
  File "/home/roberto/.cache/pypoetry/virtualenvs/vico-analytics-server-GoRiLKSi-py3.8/lib/python3.8/site-packages/flask/app.py", line 1516, in full_dispatch_request
    rv = self.dispatch_request()
  File "/home/roberto/.cache/pypoetry/virtualenvs/vico-analytics-server-GoRiLKSi-py3.8/lib/python3.8/site-packages/flask/app.py", line 1502, in dispatch_request
    return self.ensure_sync(self.view_functions[rule.endpoint])(**req.view_args)
  File "/home/roberto/Documents/Lytica/vico-analytics-server/app.py", line 21, in main_acquisition
    response, status = cls_aquisition.main(data=payload_data, file_=payload_file, path=path)
  File "/home/roberto/Documents/Lytica/vico-analytics-server/src/apis/acquisition_api.py", line 88, in main
    response, status = self.validate_queue(data=data, path=path)
  File "/home/roberto/Documents/Lytica/vico-analytics-server/src/apis/acquisition_api.py", line 74, in validate_queue
    return response.content, response.status_code
UnboundLocalError: local variable 'response' referenced before assignment
INFO:werkzeug: * Running on http://127.0.0.1:5000/ (Press CTRL+C to quit)
INFO:werkzeug: * Restarting with stat
INFO:werkzeug: * Detected change in '/home/roberto/Documents/Lytica/vico-analytics-server/src/apis/acquisition_api.py', reloading
INFO:root:Queued request
INFO:werkzeug:127.0.0.1 - - [01/Mar/2022 12:59:39] "[35m[1mPOST /acquisition/visitor-counter/ HTTP/1.1[0m" 500 -
ERROR:werkzeug:Error on request:
Traceback (most recent call last):
  File "/home/roberto/.cache/pypoetry/virtualenvs/vico-analytics-server-GoRiLKSi-py3.8/lib/python3.8/site-packages/urllib3/connection.py", line 174, in _new_conn
    conn = connection.create_connection(
  File "/home/roberto/.cache/pypoetry/virtualenvs/vico-analytics-server-GoRiLKSi-py3.8/lib/python3.8/site-packages/urllib3/util/connection.py", line 72, in create_connection
    for res in socket.getaddrinfo(host, port, family, socket.SOCK_STREAM):
  File "/usr/lib/python3.8/socket.py", line 918, in getaddrinfo
    for res in _socket.getaddrinfo(host, port, family, type, proto, flags):
socket.gaierror: [Errno -3] Temporary failure in name resolution

During handling of the above exception, another exception occurred:

Traceback (most recent call last):
  File "/home/roberto/.cache/pypoetry/virtualenvs/vico-analytics-server-GoRiLKSi-py3.8/lib/python3.8/site-packages/urllib3/connectionpool.py", line 703, in urlopen
    httplib_response = self._make_request(
  File "/home/roberto/.cache/pypoetry/virtualenvs/vico-analytics-server-GoRiLKSi-py3.8/lib/python3.8/site-packages/urllib3/connectionpool.py", line 386, in _make_request
    self._validate_conn(conn)
  File "/home/roberto/.cache/pypoetry/virtualenvs/vico-analytics-server-GoRiLKSi-py3.8/lib/python3.8/site-packages/urllib3/connectionpool.py", line 1040, in _validate_conn
    conn.connect()
  File "/home/roberto/.cache/pypoetry/virtualenvs/vico-analytics-server-GoRiLKSi-py3.8/lib/python3.8/site-packages/urllib3/connection.py", line 358, in connect
    conn = self._new_conn()
  File "/home/roberto/.cache/pypoetry/virtualenvs/vico-analytics-server-GoRiLKSi-py3.8/lib/python3.8/site-packages/urllib3/connection.py", line 186, in _new_conn
    raise NewConnectionError(
urllib3.exceptions.NewConnectionError: <urllib3.connection.HTTPSConnection object at 0x7f406ffbf8b0>: Failed to establish a new connection: [Errno -3] Temporary failure in name resolution

During handling of the above exception, another exception occurred:

Traceback (most recent call last):
  File "/home/roberto/.cache/pypoetry/virtualenvs/vico-analytics-server-GoRiLKSi-py3.8/lib/python3.8/site-packages/requests/adapters.py", line 440, in send
    resp = conn.urlopen(
  File "/home/roberto/.cache/pypoetry/virtualenvs/vico-analytics-server-GoRiLKSi-py3.8/lib/python3.8/site-packages/urllib3/connectionpool.py", line 785, in urlopen
    retries = retries.increment(
  File "/home/roberto/.cache/pypoetry/virtualenvs/vico-analytics-server-GoRiLKSi-py3.8/lib/python3.8/site-packages/urllib3/util/retry.py", line 592, in increment
    raise MaxRetryError(_pool, url, error or ResponseError(cause))
urllib3.exceptions.MaxRetryError: HTTPSConnectionPool(host='dev.vico.ai', port=443): Max retries exceeded with url: /acquisition/visitor-counter/ (Caused by NewConnectionError('<urllib3.connection.HTTPSConnection object at 0x7f406ffbf8b0>: Failed to establish a new connection: [Errno -3] Temporary failure in name resolution'))

During handling of the above exception, another exception occurred:

Traceback (most recent call last):
  File "/home/roberto/Documents/Lytica/vico-analytics-server/src/apis/acquisition_api.py", line 62, in validate_queue
    response = self.send_api_data(payload=data, path=path)
  File "/home/roberto/Documents/Lytica/vico-analytics-server/src/apis/acquisition_api.py", line 34, in send_api_data
    response = requests.post(url=url, files=payload,)
  File "/home/roberto/.cache/pypoetry/virtualenvs/vico-analytics-server-GoRiLKSi-py3.8/lib/python3.8/site-packages/requests/api.py", line 117, in post
    return request('post', url, data=data, json=json, **kwargs)
  File "/home/roberto/.cache/pypoetry/virtualenvs/vico-analytics-server-GoRiLKSi-py3.8/lib/python3.8/site-packages/requests/api.py", line 61, in request
    return session.request(method=method, url=url, **kwargs)
  File "/home/roberto/.cache/pypoetry/virtualenvs/vico-analytics-server-GoRiLKSi-py3.8/lib/python3.8/site-packages/requests/sessions.py", line 529, in request
    resp = self.send(prep, **send_kwargs)
  File "/home/roberto/.cache/pypoetry/virtualenvs/vico-analytics-server-GoRiLKSi-py3.8/lib/python3.8/site-packages/requests/sessions.py", line 645, in send
    r = adapter.send(request, **kwargs)
  File "/home/roberto/.cache/pypoetry/virtualenvs/vico-analytics-server-GoRiLKSi-py3.8/lib/python3.8/site-packages/requests/adapters.py", line 519, in send
    raise ConnectionError(e, request=request)
requests.exceptions.ConnectionError: HTTPSConnectionPool(host='dev.vico.ai', port=443): Max retries exceeded with url: /acquisition/visitor-counter/ (Caused by NewConnectionError('<urllib3.connection.HTTPSConnection object at 0x7f406ffbf8b0>: Failed to establish a new connection: [Errno -3] Temporary failure in name resolution'))

During handling of the above exception, another exception occurred:

Traceback (most recent call last):
  File "/home/roberto/.cache/pypoetry/virtualenvs/vico-analytics-server-GoRiLKSi-py3.8/lib/python3.8/site-packages/werkzeug/serving.py", line 324, in run_wsgi
    execute(self.server.app)
  File "/home/roberto/.cache/pypoetry/virtualenvs/vico-analytics-server-GoRiLKSi-py3.8/lib/python3.8/site-packages/werkzeug/serving.py", line 313, in execute
    application_iter = app(environ, start_response)
  File "/home/roberto/.cache/pypoetry/virtualenvs/vico-analytics-server-GoRiLKSi-py3.8/lib/python3.8/site-packages/flask/app.py", line 2091, in __call__
    return self.wsgi_app(environ, start_response)
  File "/home/roberto/.cache/pypoetry/virtualenvs/vico-analytics-server-GoRiLKSi-py3.8/lib/python3.8/site-packages/flask/app.py", line 2076, in wsgi_app
    response = self.handle_exception(e)
  File "/home/roberto/.cache/pypoetry/virtualenvs/vico-analytics-server-GoRiLKSi-py3.8/lib/python3.8/site-packages/flask/app.py", line 2073, in wsgi_app
    response = self.full_dispatch_request()
  File "/home/roberto/.cache/pypoetry/virtualenvs/vico-analytics-server-GoRiLKSi-py3.8/lib/python3.8/site-packages/flask/app.py", line 1518, in full_dispatch_request
    rv = self.handle_user_exception(e)
  File "/home/roberto/.cache/pypoetry/virtualenvs/vico-analytics-server-GoRiLKSi-py3.8/lib/python3.8/site-packages/flask/app.py", line 1516, in full_dispatch_request
    rv = self.dispatch_request()
  File "/home/roberto/.cache/pypoetry/virtualenvs/vico-analytics-server-GoRiLKSi-py3.8/lib/python3.8/site-packages/flask/app.py", line 1502, in dispatch_request
    return self.ensure_sync(self.view_functions[rule.endpoint])(**req.view_args)
  File "/home/roberto/Documents/Lytica/vico-analytics-server/app.py", line 21, in main_acquisition
    response, status = cls_aquisition.main(data=payload_data, file_=payload_file, path=path)
  File "/home/roberto/Documents/Lytica/vico-analytics-server/src/apis/acquisition_api.py", line 88, in main
    response, status = self.validate_queue(data=data, path=path)
  File "/home/roberto/Documents/Lytica/vico-analytics-server/src/apis/acquisition_api.py", line 74, in validate_queue
    return response.content, response.status_code
UnboundLocalError: local variable 'response' referenced before assignment
INFO:werkzeug: * Restarting with stat
INFO:werkzeug: * Detected change in '/home/roberto/Documents/Lytica/vico-analytics-server/src/apis/acquisition_api.py', reloading
INFO:werkzeug: * Restarting with stat
INFO:root:Queued request
INFO:werkzeug:127.0.0.1 - - [01/Mar/2022 13:05:45] "[35m[1mPOST /acquisition/visitor-counter/ HTTP/1.1[0m" 500 -
ERROR:werkzeug:Error on request:
Traceback (most recent call last):
  File "/home/roberto/.cache/pypoetry/virtualenvs/vico-analytics-server-GoRiLKSi-py3.8/lib/python3.8/site-packages/urllib3/connection.py", line 174, in _new_conn
    conn = connection.create_connection(
  File "/home/roberto/.cache/pypoetry/virtualenvs/vico-analytics-server-GoRiLKSi-py3.8/lib/python3.8/site-packages/urllib3/util/connection.py", line 72, in create_connection
    for res in socket.getaddrinfo(host, port, family, socket.SOCK_STREAM):
  File "/usr/lib/python3.8/socket.py", line 918, in getaddrinfo
    for res in _socket.getaddrinfo(host, port, family, type, proto, flags):
socket.gaierror: [Errno -3] Temporary failure in name resolution

During handling of the above exception, another exception occurred:

Traceback (most recent call last):
  File "/home/roberto/.cache/pypoetry/virtualenvs/vico-analytics-server-GoRiLKSi-py3.8/lib/python3.8/site-packages/urllib3/connectionpool.py", line 703, in urlopen
    httplib_response = self._make_request(
  File "/home/roberto/.cache/pypoetry/virtualenvs/vico-analytics-server-GoRiLKSi-py3.8/lib/python3.8/site-packages/urllib3/connectionpool.py", line 386, in _make_request
    self._validate_conn(conn)
  File "/home/roberto/.cache/pypoetry/virtualenvs/vico-analytics-server-GoRiLKSi-py3.8/lib/python3.8/site-packages/urllib3/connectionpool.py", line 1040, in _validate_conn
    conn.connect()
  File "/home/roberto/.cache/pypoetry/virtualenvs/vico-analytics-server-GoRiLKSi-py3.8/lib/python3.8/site-packages/urllib3/connection.py", line 358, in connect
    conn = self._new_conn()
  File "/home/roberto/.cache/pypoetry/virtualenvs/vico-analytics-server-GoRiLKSi-py3.8/lib/python3.8/site-packages/urllib3/connection.py", line 186, in _new_conn
    raise NewConnectionError(
urllib3.exceptions.NewConnectionError: <urllib3.connection.HTTPSConnection object at 0x7fca6c689100>: Failed to establish a new connection: [Errno -3] Temporary failure in name resolution

During handling of the above exception, another exception occurred:

Traceback (most recent call last):
  File "/home/roberto/.cache/pypoetry/virtualenvs/vico-analytics-server-GoRiLKSi-py3.8/lib/python3.8/site-packages/requests/adapters.py", line 440, in send
    resp = conn.urlopen(
  File "/home/roberto/.cache/pypoetry/virtualenvs/vico-analytics-server-GoRiLKSi-py3.8/lib/python3.8/site-packages/urllib3/connectionpool.py", line 785, in urlopen
    retries = retries.increment(
  File "/home/roberto/.cache/pypoetry/virtualenvs/vico-analytics-server-GoRiLKSi-py3.8/lib/python3.8/site-packages/urllib3/util/retry.py", line 592, in increment
    raise MaxRetryError(_pool, url, error or ResponseError(cause))
urllib3.exceptions.MaxRetryError: HTTPSConnectionPool(host='dev.vico.ai', port=443): Max retries exceeded with url: /acquisition/visitor-counter/ (Caused by NewConnectionError('<urllib3.connection.HTTPSConnection object at 0x7fca6c689100>: Failed to establish a new connection: [Errno -3] Temporary failure in name resolution'))

During handling of the above exception, another exception occurred:

Traceback (most recent call last):
  File "/home/roberto/Documents/Lytica/vico-analytics-server/src/apis/acquisition_api.py", line 62, in validate_queue
    response = self.send_api_data(payload=data, path=path)
  File "/home/roberto/Documents/Lytica/vico-analytics-server/src/apis/acquisition_api.py", line 34, in send_api_data
    response = requests.post(url=url, files=payload,)
  File "/home/roberto/.cache/pypoetry/virtualenvs/vico-analytics-server-GoRiLKSi-py3.8/lib/python3.8/site-packages/requests/api.py", line 117, in post
    return request('post', url, data=data, json=json, **kwargs)
  File "/home/roberto/.cache/pypoetry/virtualenvs/vico-analytics-server-GoRiLKSi-py3.8/lib/python3.8/site-packages/requests/api.py", line 61, in request
    return session.request(method=method, url=url, **kwargs)
  File "/home/roberto/.cache/pypoetry/virtualenvs/vico-analytics-server-GoRiLKSi-py3.8/lib/python3.8/site-packages/requests/sessions.py", line 529, in request
    resp = self.send(prep, **send_kwargs)
  File "/home/roberto/.cache/pypoetry/virtualenvs/vico-analytics-server-GoRiLKSi-py3.8/lib/python3.8/site-packages/requests/sessions.py", line 645, in send
    r = adapter.send(request, **kwargs)
  File "/home/roberto/.cache/pypoetry/virtualenvs/vico-analytics-server-GoRiLKSi-py3.8/lib/python3.8/site-packages/requests/adapters.py", line 519, in send
    raise ConnectionError(e, request=request)
requests.exceptions.ConnectionError: HTTPSConnectionPool(host='dev.vico.ai', port=443): Max retries exceeded with url: /acquisition/visitor-counter/ (Caused by NewConnectionError('<urllib3.connection.HTTPSConnection object at 0x7fca6c689100>: Failed to establish a new connection: [Errno -3] Temporary failure in name resolution'))

During handling of the above exception, another exception occurred:

Traceback (most recent call last):
  File "/home/roberto/.cache/pypoetry/virtualenvs/vico-analytics-server-GoRiLKSi-py3.8/lib/python3.8/site-packages/werkzeug/serving.py", line 324, in run_wsgi
    execute(self.server.app)
  File "/home/roberto/.cache/pypoetry/virtualenvs/vico-analytics-server-GoRiLKSi-py3.8/lib/python3.8/site-packages/werkzeug/serving.py", line 313, in execute
    application_iter = app(environ, start_response)
  File "/home/roberto/.cache/pypoetry/virtualenvs/vico-analytics-server-GoRiLKSi-py3.8/lib/python3.8/site-packages/flask/app.py", line 2091, in __call__
    return self.wsgi_app(environ, start_response)
  File "/home/roberto/.cache/pypoetry/virtualenvs/vico-analytics-server-GoRiLKSi-py3.8/lib/python3.8/site-packages/flask/app.py", line 2076, in wsgi_app
    response = self.handle_exception(e)
  File "/home/roberto/.cache/pypoetry/virtualenvs/vico-analytics-server-GoRiLKSi-py3.8/lib/python3.8/site-packages/flask/app.py", line 2073, in wsgi_app
    response = self.full_dispatch_request()
  File "/home/roberto/.cache/pypoetry/virtualenvs/vico-analytics-server-GoRiLKSi-py3.8/lib/python3.8/site-packages/flask/app.py", line 1518, in full_dispatch_request
    rv = self.handle_user_exception(e)
  File "/home/roberto/.cache/pypoetry/virtualenvs/vico-analytics-server-GoRiLKSi-py3.8/lib/python3.8/site-packages/flask/app.py", line 1516, in full_dispatch_request
    rv = self.dispatch_request()
  File "/home/roberto/.cache/pypoetry/virtualenvs/vico-analytics-server-GoRiLKSi-py3.8/lib/python3.8/site-packages/flask/app.py", line 1502, in dispatch_request
    return self.ensure_sync(self.view_functions[rule.endpoint])(**req.view_args)
  File "/home/roberto/Documents/Lytica/vico-analytics-server/app.py", line 21, in main_acquisition
    response, status = cls_aquisition.main(data=payload_data, file_=payload_file, path=path)
  File "/home/roberto/Documents/Lytica/vico-analytics-server/src/apis/acquisition_api.py", line 88, in main
    response, status = self.validate_queue(data=data, path=path)
  File "/home/roberto/Documents/Lytica/vico-analytics-server/src/apis/acquisition_api.py", line 74, in validate_queue
    return response.content, response.status_code
UnboundLocalError: local variable 'response' referenced before assignment
INFO:root:Dequeue
INFO:root:Queued request
INFO:root:Dequeue
INFO:root:Dequeue
INFO:root:Dequeue
INFO:root:Dequeue
INFO:root:Dequeue
INFO:root:Empty queue
INFO:root:Empty queue
INFO:root:Empty queue
INFO:root:Empty queue
INFO:root:Empty queue
INFO:root:Empty queue
INFO:root:Empty queue
INFO:root:Empty queue
INFO:root:Empty queue
INFO:root:Empty queue
INFO:root:Empty queue
INFO:root:Empty queue
INFO:root:Empty queue
INFO:root:Empty queue
INFO:root:Empty queue
INFO:root:Empty queue
INFO:root:Empty queue
INFO:root:Empty queue
INFO:root:Empty queue
INFO:root:Empty queue
INFO:werkzeug: * Running on http://127.0.0.1:5000/ (Press CTRL+C to quit)
INFO:werkzeug: * Restarting with stat
INFO:root:Queued request
INFO:werkzeug:127.0.0.1 - - [01/Mar/2022 13:13:52] "[35m[1mPOST /acquisition/visitor-counter/ HTTP/1.1[0m" 500 -
ERROR:werkzeug:Error on request:
Traceback (most recent call last):
  File "/home/roberto/.cache/pypoetry/virtualenvs/vico-analytics-server-GoRiLKSi-py3.8/lib/python3.8/site-packages/urllib3/connection.py", line 174, in _new_conn
    conn = connection.create_connection(
  File "/home/roberto/.cache/pypoetry/virtualenvs/vico-analytics-server-GoRiLKSi-py3.8/lib/python3.8/site-packages/urllib3/util/connection.py", line 72, in create_connection
    for res in socket.getaddrinfo(host, port, family, socket.SOCK_STREAM):
  File "/usr/lib/python3.8/socket.py", line 918, in getaddrinfo
    for res in _socket.getaddrinfo(host, port, family, type, proto, flags):
socket.gaierror: [Errno -3] Temporary failure in name resolution

During handling of the above exception, another exception occurred:

Traceback (most recent call last):
  File "/home/roberto/.cache/pypoetry/virtualenvs/vico-analytics-server-GoRiLKSi-py3.8/lib/python3.8/site-packages/urllib3/connectionpool.py", line 703, in urlopen
    httplib_response = self._make_request(
  File "/home/roberto/.cache/pypoetry/virtualenvs/vico-analytics-server-GoRiLKSi-py3.8/lib/python3.8/site-packages/urllib3/connectionpool.py", line 386, in _make_request
    self._validate_conn(conn)
  File "/home/roberto/.cache/pypoetry/virtualenvs/vico-analytics-server-GoRiLKSi-py3.8/lib/python3.8/site-packages/urllib3/connectionpool.py", line 1040, in _validate_conn
    conn.connect()
  File "/home/roberto/.cache/pypoetry/virtualenvs/vico-analytics-server-GoRiLKSi-py3.8/lib/python3.8/site-packages/urllib3/connection.py", line 358, in connect
    conn = self._new_conn()
  File "/home/roberto/.cache/pypoetry/virtualenvs/vico-analytics-server-GoRiLKSi-py3.8/lib/python3.8/site-packages/urllib3/connection.py", line 186, in _new_conn
    raise NewConnectionError(
urllib3.exceptions.NewConnectionError: <urllib3.connection.HTTPSConnection object at 0x7fc33afbd8b0>: Failed to establish a new connection: [Errno -3] Temporary failure in name resolution

During handling of the above exception, another exception occurred:

Traceback (most recent call last):
  File "/home/roberto/.cache/pypoetry/virtualenvs/vico-analytics-server-GoRiLKSi-py3.8/lib/python3.8/site-packages/requests/adapters.py", line 440, in send
    resp = conn.urlopen(
  File "/home/roberto/.cache/pypoetry/virtualenvs/vico-analytics-server-GoRiLKSi-py3.8/lib/python3.8/site-packages/urllib3/connectionpool.py", line 785, in urlopen
    retries = retries.increment(
  File "/home/roberto/.cache/pypoetry/virtualenvs/vico-analytics-server-GoRiLKSi-py3.8/lib/python3.8/site-packages/urllib3/util/retry.py", line 592, in increment
    raise MaxRetryError(_pool, url, error or ResponseError(cause))
urllib3.exceptions.MaxRetryError: HTTPSConnectionPool(host='dev.vico.ai', port=443): Max retries exceeded with url: /acquisition/visitor-counter/ (Caused by NewConnectionError('<urllib3.connection.HTTPSConnection object at 0x7fc33afbd8b0>: Failed to establish a new connection: [Errno -3] Temporary failure in name resolution'))

During handling of the above exception, another exception occurred:

Traceback (most recent call last):
  File "/home/roberto/Documents/Lytica/vico-analytics-server/src/apis/acquisition_api.py", line 59, in validate_queue
    response = self.send_api_data(payload=data, path=path)
  File "/home/roberto/Documents/Lytica/vico-analytics-server/src/apis/acquisition_api.py", line 31, in send_api_data
    response = requests.post(url=url, files=payload,)
  File "/home/roberto/.cache/pypoetry/virtualenvs/vico-analytics-server-GoRiLKSi-py3.8/lib/python3.8/site-packages/requests/api.py", line 117, in post
    return request('post', url, data=data, json=json, **kwargs)
  File "/home/roberto/.cache/pypoetry/virtualenvs/vico-analytics-server-GoRiLKSi-py3.8/lib/python3.8/site-packages/requests/api.py", line 61, in request
    return session.request(method=method, url=url, **kwargs)
  File "/home/roberto/.cache/pypoetry/virtualenvs/vico-analytics-server-GoRiLKSi-py3.8/lib/python3.8/site-packages/requests/sessions.py", line 529, in request
    resp = self.send(prep, **send_kwargs)
  File "/home/roberto/.cache/pypoetry/virtualenvs/vico-analytics-server-GoRiLKSi-py3.8/lib/python3.8/site-packages/requests/sessions.py", line 645, in send
    r = adapter.send(request, **kwargs)
  File "/home/roberto/.cache/pypoetry/virtualenvs/vico-analytics-server-GoRiLKSi-py3.8/lib/python3.8/site-packages/requests/adapters.py", line 519, in send
    raise ConnectionError(e, request=request)
requests.exceptions.ConnectionError: HTTPSConnectionPool(host='dev.vico.ai', port=443): Max retries exceeded with url: /acquisition/visitor-counter/ (Caused by NewConnectionError('<urllib3.connection.HTTPSConnection object at 0x7fc33afbd8b0>: Failed to establish a new connection: [Errno -3] Temporary failure in name resolution'))

During handling of the above exception, another exception occurred:

Traceback (most recent call last):
  File "/home/roberto/.cache/pypoetry/virtualenvs/vico-analytics-server-GoRiLKSi-py3.8/lib/python3.8/site-packages/werkzeug/serving.py", line 324, in run_wsgi
    execute(self.server.app)
  File "/home/roberto/.cache/pypoetry/virtualenvs/vico-analytics-server-GoRiLKSi-py3.8/lib/python3.8/site-packages/werkzeug/serving.py", line 313, in execute
    application_iter = app(environ, start_response)
  File "/home/roberto/.cache/pypoetry/virtualenvs/vico-analytics-server-GoRiLKSi-py3.8/lib/python3.8/site-packages/flask/app.py", line 2091, in __call__
    return self.wsgi_app(environ, start_response)
  File "/home/roberto/.cache/pypoetry/virtualenvs/vico-analytics-server-GoRiLKSi-py3.8/lib/python3.8/site-packages/flask/app.py", line 2076, in wsgi_app
    response = self.handle_exception(e)
  File "/home/roberto/.cache/pypoetry/virtualenvs/vico-analytics-server-GoRiLKSi-py3.8/lib/python3.8/site-packages/flask/app.py", line 2073, in wsgi_app
    response = self.full_dispatch_request()
  File "/home/roberto/.cache/pypoetry/virtualenvs/vico-analytics-server-GoRiLKSi-py3.8/lib/python3.8/site-packages/flask/app.py", line 1518, in full_dispatch_request
    rv = self.handle_user_exception(e)
  File "/home/roberto/.cache/pypoetry/virtualenvs/vico-analytics-server-GoRiLKSi-py3.8/lib/python3.8/site-packages/flask/app.py", line 1516, in full_dispatch_request
    rv = self.dispatch_request()
  File "/home/roberto/.cache/pypoetry/virtualenvs/vico-analytics-server-GoRiLKSi-py3.8/lib/python3.8/site-packages/flask/app.py", line 1502, in dispatch_request
    return self.ensure_sync(self.view_functions[rule.endpoint])(**req.view_args)
  File "/home/roberto/Documents/Lytica/vico-analytics-server/app.py", line 21, in main_acquisition
    response, status = cls_aquisition.main(data=payload_data, file_=payload_file, path=path)
  File "/home/roberto/Documents/Lytica/vico-analytics-server/src/apis/acquisition_api.py", line 84, in main
    response, status = self.validate_queue(data=data, path=path)
  File "/home/roberto/Documents/Lytica/vico-analytics-server/src/apis/acquisition_api.py", line 70, in validate_queue
    return response.content, response.status_code
UnboundLocalError: local variable 'response' referenced before assignment
INFO:root:Queued request
INFO:werkzeug:127.0.0.1 - - [01/Mar/2022 13:14:13] "[35m[1mPOST /acquisition/visitor-counter/ HTTP/1.1[0m" 500 -
ERROR:werkzeug:Error on request:
Traceback (most recent call last):
  File "/home/roberto/.cache/pypoetry/virtualenvs/vico-analytics-server-GoRiLKSi-py3.8/lib/python3.8/site-packages/urllib3/connection.py", line 174, in _new_conn
    conn = connection.create_connection(
  File "/home/roberto/.cache/pypoetry/virtualenvs/vico-analytics-server-GoRiLKSi-py3.8/lib/python3.8/site-packages/urllib3/util/connection.py", line 72, in create_connection
    for res in socket.getaddrinfo(host, port, family, socket.SOCK_STREAM):
  File "/usr/lib/python3.8/socket.py", line 918, in getaddrinfo
    for res in _socket.getaddrinfo(host, port, family, type, proto, flags):
socket.gaierror: [Errno -3] Temporary failure in name resolution

During handling of the above exception, another exception occurred:

Traceback (most recent call last):
  File "/home/roberto/.cache/pypoetry/virtualenvs/vico-analytics-server-GoRiLKSi-py3.8/lib/python3.8/site-packages/urllib3/connectionpool.py", line 703, in urlopen
    httplib_response = self._make_request(
  File "/home/roberto/.cache/pypoetry/virtualenvs/vico-analytics-server-GoRiLKSi-py3.8/lib/python3.8/site-packages/urllib3/connectionpool.py", line 386, in _make_request
    self._validate_conn(conn)
  File "/home/roberto/.cache/pypoetry/virtualenvs/vico-analytics-server-GoRiLKSi-py3.8/lib/python3.8/site-packages/urllib3/connectionpool.py", line 1040, in _validate_conn
    conn.connect()
  File "/home/roberto/.cache/pypoetry/virtualenvs/vico-analytics-server-GoRiLKSi-py3.8/lib/python3.8/site-packages/urllib3/connection.py", line 358, in connect
    conn = self._new_conn()
  File "/home/roberto/.cache/pypoetry/virtualenvs/vico-analytics-server-GoRiLKSi-py3.8/lib/python3.8/site-packages/urllib3/connection.py", line 186, in _new_conn
    raise NewConnectionError(
urllib3.exceptions.NewConnectionError: <urllib3.connection.HTTPSConnection object at 0x7fc33a710c10>: Failed to establish a new connection: [Errno -3] Temporary failure in name resolution

During handling of the above exception, another exception occurred:

Traceback (most recent call last):
  File "/home/roberto/.cache/pypoetry/virtualenvs/vico-analytics-server-GoRiLKSi-py3.8/lib/python3.8/site-packages/requests/adapters.py", line 440, in send
    resp = conn.urlopen(
  File "/home/roberto/.cache/pypoetry/virtualenvs/vico-analytics-server-GoRiLKSi-py3.8/lib/python3.8/site-packages/urllib3/connectionpool.py", line 785, in urlopen
    retries = retries.increment(
  File "/home/roberto/.cache/pypoetry/virtualenvs/vico-analytics-server-GoRiLKSi-py3.8/lib/python3.8/site-packages/urllib3/util/retry.py", line 592, in increment
    raise MaxRetryError(_pool, url, error or ResponseError(cause))
urllib3.exceptions.MaxRetryError: HTTPSConnectionPool(host='dev.vico.ai', port=443): Max retries exceeded with url: /acquisition/visitor-counter/ (Caused by NewConnectionError('<urllib3.connection.HTTPSConnection object at 0x7fc33a710c10>: Failed to establish a new connection: [Errno -3] Temporary failure in name resolution'))

During handling of the above exception, another exception occurred:

Traceback (most recent call last):
  File "/home/roberto/Documents/Lytica/vico-analytics-server/src/apis/acquisition_api.py", line 59, in validate_queue
    response = self.send_api_data(payload=data, path=path)
  File "/home/roberto/Documents/Lytica/vico-analytics-server/src/apis/acquisition_api.py", line 31, in send_api_data
    response = requests.post(url=url, files=payload,)
  File "/home/roberto/.cache/pypoetry/virtualenvs/vico-analytics-server-GoRiLKSi-py3.8/lib/python3.8/site-packages/requests/api.py", line 117, in post
    return request('post', url, data=data, json=json, **kwargs)
  File "/home/roberto/.cache/pypoetry/virtualenvs/vico-analytics-server-GoRiLKSi-py3.8/lib/python3.8/site-packages/requests/api.py", line 61, in request
    return session.request(method=method, url=url, **kwargs)
  File "/home/roberto/.cache/pypoetry/virtualenvs/vico-analytics-server-GoRiLKSi-py3.8/lib/python3.8/site-packages/requests/sessions.py", line 529, in request
    resp = self.send(prep, **send_kwargs)
  File "/home/roberto/.cache/pypoetry/virtualenvs/vico-analytics-server-GoRiLKSi-py3.8/lib/python3.8/site-packages/requests/sessions.py", line 645, in send
    r = adapter.send(request, **kwargs)
  File "/home/roberto/.cache/pypoetry/virtualenvs/vico-analytics-server-GoRiLKSi-py3.8/lib/python3.8/site-packages/requests/adapters.py", line 519, in send
    raise ConnectionError(e, request=request)
requests.exceptions.ConnectionError: HTTPSConnectionPool(host='dev.vico.ai', port=443): Max retries exceeded with url: /acquisition/visitor-counter/ (Caused by NewConnectionError('<urllib3.connection.HTTPSConnection object at 0x7fc33a710c10>: Failed to establish a new connection: [Errno -3] Temporary failure in name resolution'))

During handling of the above exception, another exception occurred:

Traceback (most recent call last):
  File "/home/roberto/.cache/pypoetry/virtualenvs/vico-analytics-server-GoRiLKSi-py3.8/lib/python3.8/site-packages/werkzeug/serving.py", line 324, in run_wsgi
    execute(self.server.app)
  File "/home/roberto/.cache/pypoetry/virtualenvs/vico-analytics-server-GoRiLKSi-py3.8/lib/python3.8/site-packages/werkzeug/serving.py", line 313, in execute
    application_iter = app(environ, start_response)
  File "/home/roberto/.cache/pypoetry/virtualenvs/vico-analytics-server-GoRiLKSi-py3.8/lib/python3.8/site-packages/flask/app.py", line 2091, in __call__
    return self.wsgi_app(environ, start_response)
  File "/home/roberto/.cache/pypoetry/virtualenvs/vico-analytics-server-GoRiLKSi-py3.8/lib/python3.8/site-packages/flask/app.py", line 2076, in wsgi_app
    response = self.handle_exception(e)
  File "/home/roberto/.cache/pypoetry/virtualenvs/vico-analytics-server-GoRiLKSi-py3.8/lib/python3.8/site-packages/flask/app.py", line 2073, in wsgi_app
    response = self.full_dispatch_request()
  File "/home/roberto/.cache/pypoetry/virtualenvs/vico-analytics-server-GoRiLKSi-py3.8/lib/python3.8/site-packages/flask/app.py", line 1518, in full_dispatch_request
    rv = self.handle_user_exception(e)
  File "/home/roberto/.cache/pypoetry/virtualenvs/vico-analytics-server-GoRiLKSi-py3.8/lib/python3.8/site-packages/flask/app.py", line 1516, in full_dispatch_request
    rv = self.dispatch_request()
  File "/home/roberto/.cache/pypoetry/virtualenvs/vico-analytics-server-GoRiLKSi-py3.8/lib/python3.8/site-packages/flask/app.py", line 1502, in dispatch_request
    return self.ensure_sync(self.view_functions[rule.endpoint])(**req.view_args)
  File "/home/roberto/Documents/Lytica/vico-analytics-server/app.py", line 21, in main_acquisition
    response, status = cls_aquisition.main(data=payload_data, file_=payload_file, path=path)
  File "/home/roberto/Documents/Lytica/vico-analytics-server/src/apis/acquisition_api.py", line 84, in main
    response, status = self.validate_queue(data=data, path=path)
  File "/home/roberto/Documents/Lytica/vico-analytics-server/src/apis/acquisition_api.py", line 70, in validate_queue
    return response.content, response.status_code
UnboundLocalError: local variable 'response' referenced before assignment
INFO:root:Queued request
INFO:werkzeug:127.0.0.1 - - [01/Mar/2022 13:14:39] "[35m[1mPOST /acquisition/visitor-counter/ HTTP/1.1[0m" 500 -
ERROR:werkzeug:Error on request:
Traceback (most recent call last):
  File "/home/roberto/.cache/pypoetry/virtualenvs/vico-analytics-server-GoRiLKSi-py3.8/lib/python3.8/site-packages/urllib3/connection.py", line 174, in _new_conn
    conn = connection.create_connection(
  File "/home/roberto/.cache/pypoetry/virtualenvs/vico-analytics-server-GoRiLKSi-py3.8/lib/python3.8/site-packages/urllib3/util/connection.py", line 72, in create_connection
    for res in socket.getaddrinfo(host, port, family, socket.SOCK_STREAM):
  File "/usr/lib/python3.8/socket.py", line 918, in getaddrinfo
    for res in _socket.getaddrinfo(host, port, family, type, proto, flags):
socket.gaierror: [Errno -3] Temporary failure in name resolution

During handling of the above exception, another exception occurred:

Traceback (most recent call last):
  File "/home/roberto/.cache/pypoetry/virtualenvs/vico-analytics-server-GoRiLKSi-py3.8/lib/python3.8/site-packages/urllib3/connectionpool.py", line 703, in urlopen
    httplib_response = self._make_request(
  File "/home/roberto/.cache/pypoetry/virtualenvs/vico-analytics-server-GoRiLKSi-py3.8/lib/python3.8/site-packages/urllib3/connectionpool.py", line 386, in _make_request
    self._validate_conn(conn)
  File "/home/roberto/.cache/pypoetry/virtualenvs/vico-analytics-server-GoRiLKSi-py3.8/lib/python3.8/site-packages/urllib3/connectionpool.py", line 1040, in _validate_conn
    conn.connect()
  File "/home/roberto/.cache/pypoetry/virtualenvs/vico-analytics-server-GoRiLKSi-py3.8/lib/python3.8/site-packages/urllib3/connection.py", line 358, in connect
    conn = self._new_conn()
  File "/home/roberto/.cache/pypoetry/virtualenvs/vico-analytics-server-GoRiLKSi-py3.8/lib/python3.8/site-packages/urllib3/connection.py", line 186, in _new_conn
    raise NewConnectionError(
urllib3.exceptions.NewConnectionError: <urllib3.connection.HTTPSConnection object at 0x7fc33997b280>: Failed to establish a new connection: [Errno -3] Temporary failure in name resolution

During handling of the above exception, another exception occurred:

Traceback (most recent call last):
  File "/home/roberto/.cache/pypoetry/virtualenvs/vico-analytics-server-GoRiLKSi-py3.8/lib/python3.8/site-packages/requests/adapters.py", line 440, in send
    resp = conn.urlopen(
  File "/home/roberto/.cache/pypoetry/virtualenvs/vico-analytics-server-GoRiLKSi-py3.8/lib/python3.8/site-packages/urllib3/connectionpool.py", line 785, in urlopen
    retries = retries.increment(
  File "/home/roberto/.cache/pypoetry/virtualenvs/vico-analytics-server-GoRiLKSi-py3.8/lib/python3.8/site-packages/urllib3/util/retry.py", line 592, in increment
    raise MaxRetryError(_pool, url, error or ResponseError(cause))
urllib3.exceptions.MaxRetryError: HTTPSConnectionPool(host='dev.vico.ai', port=443): Max retries exceeded with url: /acquisition/visitor-counter/ (Caused by NewConnectionError('<urllib3.connection.HTTPSConnection object at 0x7fc33997b280>: Failed to establish a new connection: [Errno -3] Temporary failure in name resolution'))

During handling of the above exception, another exception occurred:

Traceback (most recent call last):
  File "/home/roberto/Documents/Lytica/vico-analytics-server/src/apis/acquisition_api.py", line 59, in validate_queue
    response = self.send_api_data(payload=data, path=path)
  File "/home/roberto/Documents/Lytica/vico-analytics-server/src/apis/acquisition_api.py", line 31, in send_api_data
    response = requests.post(url=url, files=payload,)
  File "/home/roberto/.cache/pypoetry/virtualenvs/vico-analytics-server-GoRiLKSi-py3.8/lib/python3.8/site-packages/requests/api.py", line 117, in post
    return request('post', url, data=data, json=json, **kwargs)
  File "/home/roberto/.cache/pypoetry/virtualenvs/vico-analytics-server-GoRiLKSi-py3.8/lib/python3.8/site-packages/requests/api.py", line 61, in request
    return session.request(method=method, url=url, **kwargs)
  File "/home/roberto/.cache/pypoetry/virtualenvs/vico-analytics-server-GoRiLKSi-py3.8/lib/python3.8/site-packages/requests/sessions.py", line 529, in request
    resp = self.send(prep, **send_kwargs)
  File "/home/roberto/.cache/pypoetry/virtualenvs/vico-analytics-server-GoRiLKSi-py3.8/lib/python3.8/site-packages/requests/sessions.py", line 645, in send
    r = adapter.send(request, **kwargs)
  File "/home/roberto/.cache/pypoetry/virtualenvs/vico-analytics-server-GoRiLKSi-py3.8/lib/python3.8/site-packages/requests/adapters.py", line 519, in send
    raise ConnectionError(e, request=request)
requests.exceptions.ConnectionError: HTTPSConnectionPool(host='dev.vico.ai', port=443): Max retries exceeded with url: /acquisition/visitor-counter/ (Caused by NewConnectionError('<urllib3.connection.HTTPSConnection object at 0x7fc33997b280>: Failed to establish a new connection: [Errno -3] Temporary failure in name resolution'))

During handling of the above exception, another exception occurred:

Traceback (most recent call last):
  File "/home/roberto/.cache/pypoetry/virtualenvs/vico-analytics-server-GoRiLKSi-py3.8/lib/python3.8/site-packages/werkzeug/serving.py", line 324, in run_wsgi
    execute(self.server.app)
  File "/home/roberto/.cache/pypoetry/virtualenvs/vico-analytics-server-GoRiLKSi-py3.8/lib/python3.8/site-packages/werkzeug/serving.py", line 313, in execute
    application_iter = app(environ, start_response)
  File "/home/roberto/.cache/pypoetry/virtualenvs/vico-analytics-server-GoRiLKSi-py3.8/lib/python3.8/site-packages/flask/app.py", line 2091, in __call__
    return self.wsgi_app(environ, start_response)
  File "/home/roberto/.cache/pypoetry/virtualenvs/vico-analytics-server-GoRiLKSi-py3.8/lib/python3.8/site-packages/flask/app.py", line 2076, in wsgi_app
    response = self.handle_exception(e)
  File "/home/roberto/.cache/pypoetry/virtualenvs/vico-analytics-server-GoRiLKSi-py3.8/lib/python3.8/site-packages/flask/app.py", line 2073, in wsgi_app
    response = self.full_dispatch_request()
  File "/home/roberto/.cache/pypoetry/virtualenvs/vico-analytics-server-GoRiLKSi-py3.8/lib/python3.8/site-packages/flask/app.py", line 1518, in full_dispatch_request
    rv = self.handle_user_exception(e)
  File "/home/roberto/.cache/pypoetry/virtualenvs/vico-analytics-server-GoRiLKSi-py3.8/lib/python3.8/site-packages/flask/app.py", line 1516, in full_dispatch_request
    rv = self.dispatch_request()
  File "/home/roberto/.cache/pypoetry/virtualenvs/vico-analytics-server-GoRiLKSi-py3.8/lib/python3.8/site-packages/flask/app.py", line 1502, in dispatch_request
    return self.ensure_sync(self.view_functions[rule.endpoint])(**req.view_args)
  File "/home/roberto/Documents/Lytica/vico-analytics-server/app.py", line 21, in main_acquisition
    response, status = cls_aquisition.main(data=payload_data, file_=payload_file, path=path)
  File "/home/roberto/Documents/Lytica/vico-analytics-server/src/apis/acquisition_api.py", line 84, in main
    response, status = self.validate_queue(data=data, path=path)
  File "/home/roberto/Documents/Lytica/vico-analytics-server/src/apis/acquisition_api.py", line 70, in validate_queue
    return response.content, response.status_code
UnboundLocalError: local variable 'response' referenced before assignment
INFO:root:Queued request
INFO:werkzeug:127.0.0.1 - - [01/Mar/2022 13:15:19] "[35m[1mPOST /acquisition/visitor-counter/ HTTP/1.1[0m" 500 -
ERROR:werkzeug:Error on request:
Traceback (most recent call last):
  File "/home/roberto/.cache/pypoetry/virtualenvs/vico-analytics-server-GoRiLKSi-py3.8/lib/python3.8/site-packages/urllib3/connection.py", line 174, in _new_conn
    conn = connection.create_connection(
  File "/home/roberto/.cache/pypoetry/virtualenvs/vico-analytics-server-GoRiLKSi-py3.8/lib/python3.8/site-packages/urllib3/util/connection.py", line 72, in create_connection
    for res in socket.getaddrinfo(host, port, family, socket.SOCK_STREAM):
  File "/usr/lib/python3.8/socket.py", line 918, in getaddrinfo
    for res in _socket.getaddrinfo(host, port, family, type, proto, flags):
socket.gaierror: [Errno -3] Temporary failure in name resolution

During handling of the above exception, another exception occurred:

Traceback (most recent call last):
  File "/home/roberto/.cache/pypoetry/virtualenvs/vico-analytics-server-GoRiLKSi-py3.8/lib/python3.8/site-packages/urllib3/connectionpool.py", line 703, in urlopen
    httplib_response = self._make_request(
  File "/home/roberto/.cache/pypoetry/virtualenvs/vico-analytics-server-GoRiLKSi-py3.8/lib/python3.8/site-packages/urllib3/connectionpool.py", line 386, in _make_request
    self._validate_conn(conn)
  File "/home/roberto/.cache/pypoetry/virtualenvs/vico-analytics-server-GoRiLKSi-py3.8/lib/python3.8/site-packages/urllib3/connectionpool.py", line 1040, in _validate_conn
    conn.connect()
  File "/home/roberto/.cache/pypoetry/virtualenvs/vico-analytics-server-GoRiLKSi-py3.8/lib/python3.8/site-packages/urllib3/connection.py", line 358, in connect
    conn = self._new_conn()
  File "/home/roberto/.cache/pypoetry/virtualenvs/vico-analytics-server-GoRiLKSi-py3.8/lib/python3.8/site-packages/urllib3/connection.py", line 186, in _new_conn
    raise NewConnectionError(
urllib3.exceptions.NewConnectionError: <urllib3.connection.HTTPSConnection object at 0x7fc3393612b0>: Failed to establish a new connection: [Errno -3] Temporary failure in name resolution

During handling of the above exception, another exception occurred:

Traceback (most recent call last):
  File "/home/roberto/.cache/pypoetry/virtualenvs/vico-analytics-server-GoRiLKSi-py3.8/lib/python3.8/site-packages/requests/adapters.py", line 440, in send
    resp = conn.urlopen(
  File "/home/roberto/.cache/pypoetry/virtualenvs/vico-analytics-server-GoRiLKSi-py3.8/lib/python3.8/site-packages/urllib3/connectionpool.py", line 785, in urlopen
    retries = retries.increment(
  File "/home/roberto/.cache/pypoetry/virtualenvs/vico-analytics-server-GoRiLKSi-py3.8/lib/python3.8/site-packages/urllib3/util/retry.py", line 592, in increment
    raise MaxRetryError(_pool, url, error or ResponseError(cause))
urllib3.exceptions.MaxRetryError: HTTPSConnectionPool(host='dev.vico.ai', port=443): Max retries exceeded with url: /acquisition/visitor-counter/ (Caused by NewConnectionError('<urllib3.connection.HTTPSConnection object at 0x7fc3393612b0>: Failed to establish a new connection: [Errno -3] Temporary failure in name resolution'))

During handling of the above exception, another exception occurred:

Traceback (most recent call last):
  File "/home/roberto/Documents/Lytica/vico-analytics-server/src/apis/acquisition_api.py", line 59, in validate_queue
    response = self.send_api_data(payload=data, path=path)
  File "/home/roberto/Documents/Lytica/vico-analytics-server/src/apis/acquisition_api.py", line 31, in send_api_data
    response = requests.post(url=url, files=payload,)
  File "/home/roberto/.cache/pypoetry/virtualenvs/vico-analytics-server-GoRiLKSi-py3.8/lib/python3.8/site-packages/requests/api.py", line 117, in post
    return request('post', url, data=data, json=json, **kwargs)
  File "/home/roberto/.cache/pypoetry/virtualenvs/vico-analytics-server-GoRiLKSi-py3.8/lib/python3.8/site-packages/requests/api.py", line 61, in request
    return session.request(method=method, url=url, **kwargs)
  File "/home/roberto/.cache/pypoetry/virtualenvs/vico-analytics-server-GoRiLKSi-py3.8/lib/python3.8/site-packages/requests/sessions.py", line 529, in request
    resp = self.send(prep, **send_kwargs)
  File "/home/roberto/.cache/pypoetry/virtualenvs/vico-analytics-server-GoRiLKSi-py3.8/lib/python3.8/site-packages/requests/sessions.py", line 645, in send
    r = adapter.send(request, **kwargs)
  File "/home/roberto/.cache/pypoetry/virtualenvs/vico-analytics-server-GoRiLKSi-py3.8/lib/python3.8/site-packages/requests/adapters.py", line 519, in send
    raise ConnectionError(e, request=request)
requests.exceptions.ConnectionError: HTTPSConnectionPool(host='dev.vico.ai', port=443): Max retries exceeded with url: /acquisition/visitor-counter/ (Caused by NewConnectionError('<urllib3.connection.HTTPSConnection object at 0x7fc3393612b0>: Failed to establish a new connection: [Errno -3] Temporary failure in name resolution'))

During handling of the above exception, another exception occurred:

Traceback (most recent call last):
  File "/home/roberto/.cache/pypoetry/virtualenvs/vico-analytics-server-GoRiLKSi-py3.8/lib/python3.8/site-packages/werkzeug/serving.py", line 324, in run_wsgi
    execute(self.server.app)
  File "/home/roberto/.cache/pypoetry/virtualenvs/vico-analytics-server-GoRiLKSi-py3.8/lib/python3.8/site-packages/werkzeug/serving.py", line 313, in execute
    application_iter = app(environ, start_response)
  File "/home/roberto/.cache/pypoetry/virtualenvs/vico-analytics-server-GoRiLKSi-py3.8/lib/python3.8/site-packages/flask/app.py", line 2091, in __call__
    return self.wsgi_app(environ, start_response)
  File "/home/roberto/.cache/pypoetry/virtualenvs/vico-analytics-server-GoRiLKSi-py3.8/lib/python3.8/site-packages/flask/app.py", line 2076, in wsgi_app
    response = self.handle_exception(e)
  File "/home/roberto/.cache/pypoetry/virtualenvs/vico-analytics-server-GoRiLKSi-py3.8/lib/python3.8/site-packages/flask/app.py", line 2073, in wsgi_app
    response = self.full_dispatch_request()
  File "/home/roberto/.cache/pypoetry/virtualenvs/vico-analytics-server-GoRiLKSi-py3.8/lib/python3.8/site-packages/flask/app.py", line 1518, in full_dispatch_request
    rv = self.handle_user_exception(e)
  File "/home/roberto/.cache/pypoetry/virtualenvs/vico-analytics-server-GoRiLKSi-py3.8/lib/python3.8/site-packages/flask/app.py", line 1516, in full_dispatch_request
    rv = self.dispatch_request()
  File "/home/roberto/.cache/pypoetry/virtualenvs/vico-analytics-server-GoRiLKSi-py3.8/lib/python3.8/site-packages/flask/app.py", line 1502, in dispatch_request
    return self.ensure_sync(self.view_functions[rule.endpoint])(**req.view_args)
  File "/home/roberto/Documents/Lytica/vico-analytics-server/app.py", line 21, in main_acquisition
    response, status = cls_aquisition.main(data=payload_data, file_=payload_file, path=path)
  File "/home/roberto/Documents/Lytica/vico-analytics-server/src/apis/acquisition_api.py", line 84, in main
    response, status = self.validate_queue(data=data, path=path)
  File "/home/roberto/Documents/Lytica/vico-analytics-server/src/apis/acquisition_api.py", line 70, in validate_queue
    return response.content, response.status_code
UnboundLocalError: local variable 'response' referenced before assignment
INFO:root:Queued request
INFO:werkzeug:127.0.0.1 - - [01/Mar/2022 13:15:43] "[35m[1mPOST /acquisition/visitor-counter/ HTTP/1.1[0m" 500 -
ERROR:werkzeug:Error on request:
Traceback (most recent call last):
  File "/home/roberto/.cache/pypoetry/virtualenvs/vico-analytics-server-GoRiLKSi-py3.8/lib/python3.8/site-packages/urllib3/connection.py", line 174, in _new_conn
    conn = connection.create_connection(
  File "/home/roberto/.cache/pypoetry/virtualenvs/vico-analytics-server-GoRiLKSi-py3.8/lib/python3.8/site-packages/urllib3/util/connection.py", line 72, in create_connection
    for res in socket.getaddrinfo(host, port, family, socket.SOCK_STREAM):
  File "/usr/lib/python3.8/socket.py", line 918, in getaddrinfo
    for res in _socket.getaddrinfo(host, port, family, type, proto, flags):
socket.gaierror: [Errno -3] Temporary failure in name resolution

During handling of the above exception, another exception occurred:

Traceback (most recent call last):
  File "/home/roberto/.cache/pypoetry/virtualenvs/vico-analytics-server-GoRiLKSi-py3.8/lib/python3.8/site-packages/urllib3/connectionpool.py", line 703, in urlopen
    httplib_response = self._make_request(
  File "/home/roberto/.cache/pypoetry/virtualenvs/vico-analytics-server-GoRiLKSi-py3.8/lib/python3.8/site-packages/urllib3/connectionpool.py", line 386, in _make_request
    self._validate_conn(conn)
  File "/home/roberto/.cache/pypoetry/virtualenvs/vico-analytics-server-GoRiLKSi-py3.8/lib/python3.8/site-packages/urllib3/connectionpool.py", line 1040, in _validate_conn
    conn.connect()
  File "/home/roberto/.cache/pypoetry/virtualenvs/vico-analytics-server-GoRiLKSi-py3.8/lib/python3.8/site-packages/urllib3/connection.py", line 358, in connect
    conn = self._new_conn()
  File "/home/roberto/.cache/pypoetry/virtualenvs/vico-analytics-server-GoRiLKSi-py3.8/lib/python3.8/site-packages/urllib3/connection.py", line 186, in _new_conn
    raise NewConnectionError(
urllib3.exceptions.NewConnectionError: <urllib3.connection.HTTPSConnection object at 0x7fc33997bf10>: Failed to establish a new connection: [Errno -3] Temporary failure in name resolution

During handling of the above exception, another exception occurred:

Traceback (most recent call last):
  File "/home/roberto/.cache/pypoetry/virtualenvs/vico-analytics-server-GoRiLKSi-py3.8/lib/python3.8/site-packages/requests/adapters.py", line 440, in send
    resp = conn.urlopen(
  File "/home/roberto/.cache/pypoetry/virtualenvs/vico-analytics-server-GoRiLKSi-py3.8/lib/python3.8/site-packages/urllib3/connectionpool.py", line 785, in urlopen
    retries = retries.increment(
  File "/home/roberto/.cache/pypoetry/virtualenvs/vico-analytics-server-GoRiLKSi-py3.8/lib/python3.8/site-packages/urllib3/util/retry.py", line 592, in increment
    raise MaxRetryError(_pool, url, error or ResponseError(cause))
urllib3.exceptions.MaxRetryError: HTTPSConnectionPool(host='dev.vico.ai', port=443): Max retries exceeded with url: /acquisition/visitor-counter/ (Caused by NewConnectionError('<urllib3.connection.HTTPSConnection object at 0x7fc33997bf10>: Failed to establish a new connection: [Errno -3] Temporary failure in name resolution'))

During handling of the above exception, another exception occurred:

Traceback (most recent call last):
  File "/home/roberto/Documents/Lytica/vico-analytics-server/src/apis/acquisition_api.py", line 59, in validate_queue
    response = self.send_api_data(payload=data, path=path)
  File "/home/roberto/Documents/Lytica/vico-analytics-server/src/apis/acquisition_api.py", line 31, in send_api_data
    response = requests.post(url=url, files=payload,)
  File "/home/roberto/.cache/pypoetry/virtualenvs/vico-analytics-server-GoRiLKSi-py3.8/lib/python3.8/site-packages/requests/api.py", line 117, in post
    return request('post', url, data=data, json=json, **kwargs)
  File "/home/roberto/.cache/pypoetry/virtualenvs/vico-analytics-server-GoRiLKSi-py3.8/lib/python3.8/site-packages/requests/api.py", line 61, in request
    return session.request(method=method, url=url, **kwargs)
  File "/home/roberto/.cache/pypoetry/virtualenvs/vico-analytics-server-GoRiLKSi-py3.8/lib/python3.8/site-packages/requests/sessions.py", line 529, in request
    resp = self.send(prep, **send_kwargs)
  File "/home/roberto/.cache/pypoetry/virtualenvs/vico-analytics-server-GoRiLKSi-py3.8/lib/python3.8/site-packages/requests/sessions.py", line 645, in send
    r = adapter.send(request, **kwargs)
  File "/home/roberto/.cache/pypoetry/virtualenvs/vico-analytics-server-GoRiLKSi-py3.8/lib/python3.8/site-packages/requests/adapters.py", line 519, in send
    raise ConnectionError(e, request=request)
requests.exceptions.ConnectionError: HTTPSConnectionPool(host='dev.vico.ai', port=443): Max retries exceeded with url: /acquisition/visitor-counter/ (Caused by NewConnectionError('<urllib3.connection.HTTPSConnection object at 0x7fc33997bf10>: Failed to establish a new connection: [Errno -3] Temporary failure in name resolution'))

During handling of the above exception, another exception occurred:

Traceback (most recent call last):
  File "/home/roberto/.cache/pypoetry/virtualenvs/vico-analytics-server-GoRiLKSi-py3.8/lib/python3.8/site-packages/werkzeug/serving.py", line 324, in run_wsgi
    execute(self.server.app)
  File "/home/roberto/.cache/pypoetry/virtualenvs/vico-analytics-server-GoRiLKSi-py3.8/lib/python3.8/site-packages/werkzeug/serving.py", line 313, in execute
    application_iter = app(environ, start_response)
  File "/home/roberto/.cache/pypoetry/virtualenvs/vico-analytics-server-GoRiLKSi-py3.8/lib/python3.8/site-packages/flask/app.py", line 2091, in __call__
    return self.wsgi_app(environ, start_response)
  File "/home/roberto/.cache/pypoetry/virtualenvs/vico-analytics-server-GoRiLKSi-py3.8/lib/python3.8/site-packages/flask/app.py", line 2076, in wsgi_app
    response = self.handle_exception(e)
  File "/home/roberto/.cache/pypoetry/virtualenvs/vico-analytics-server-GoRiLKSi-py3.8/lib/python3.8/site-packages/flask/app.py", line 2073, in wsgi_app
    response = self.full_dispatch_request()
  File "/home/roberto/.cache/pypoetry/virtualenvs/vico-analytics-server-GoRiLKSi-py3.8/lib/python3.8/site-packages/flask/app.py", line 1518, in full_dispatch_request
    rv = self.handle_user_exception(e)
  File "/home/roberto/.cache/pypoetry/virtualenvs/vico-analytics-server-GoRiLKSi-py3.8/lib/python3.8/site-packages/flask/app.py", line 1516, in full_dispatch_request
    rv = self.dispatch_request()
  File "/home/roberto/.cache/pypoetry/virtualenvs/vico-analytics-server-GoRiLKSi-py3.8/lib/python3.8/site-packages/flask/app.py", line 1502, in dispatch_request
    return self.ensure_sync(self.view_functions[rule.endpoint])(**req.view_args)
  File "/home/roberto/Documents/Lytica/vico-analytics-server/app.py", line 21, in main_acquisition
    response, status = cls_aquisition.main(data=payload_data, file_=payload_file, path=path)
  File "/home/roberto/Documents/Lytica/vico-analytics-server/src/apis/acquisition_api.py", line 84, in main
    response, status = self.validate_queue(data=data, path=path)
  File "/home/roberto/Documents/Lytica/vico-analytics-server/src/apis/acquisition_api.py", line 70, in validate_queue
    return response.content, response.status_code
UnboundLocalError: local variable 'response' referenced before assignment
INFO:root:Dequeue
INFO:root:A dequeue request was sent
INFO:root:Dequeue
INFO:root:A dequeue request was sent
INFO:root:Dequeue
INFO:root:A dequeue request was sent
INFO:root:Dequeue
INFO:root:A dequeue request was sent
INFO:root:Dequeue
INFO:root:A dequeue request was sent
INFO:root:Empty queue
INFO:root:Empty queue
INFO:root:Empty queue
INFO:root:Empty queue
INFO:root:Queued request
INFO:root:Dequeue
INFO:root:Queued request
INFO:root:A dequeue request was sent
INFO:root:Dequeue
INFO:root:Queued request
INFO:root:A dequeue request was sent
INFO:root:Dequeue
INFO:root:Queued request
INFO:root:A dequeue request was sent
INFO:root:Dequeue
INFO:root:Queued request
INFO:root:A dequeue request was sent
INFO:root:Dequeue
INFO:root:Queued request
INFO:root:A dequeue request was sent
INFO:root:Dequeue
INFO:root:Queued request
INFO:root:A dequeue request was sent
INFO:root:Dequeue
INFO:root:Queued request
INFO:root:A dequeue request was sent
INFO:root:Dequeue
INFO:root:Empty queue
INFO:root:Empty queue
INFO:root:Empty queue
INFO:root:Empty queue
INFO:root:Empty queue
INFO:root:Empty queue
INFO:root:Empty queue
INFO:root:Empty queue
INFO:root:Empty queue
INFO:root:Empty queue
INFO:root:Empty queue
INFO:root:Empty queue
INFO:root:Empty queue
INFO:root:Queued request
INFO:root:Dequeue
INFO:root:Queued request
INFO:root:Dequeue
INFO:root:Queued request
INFO:root:Dequeue
INFO:root:Queued request
INFO:root:Dequeue
INFO:root:Queued request
INFO:root:Dequeue
INFO:root:Queued request
INFO:root:Dequeue
INFO:root:Queued request
INFO:root:Queued request
INFO:root:Queued request
INFO:root:Queued request
INFO:root:Queued request
INFO:root:Dequeue
INFO:root:Queued request
INFO:root:Dequeue
INFO:root:Queued request
INFO:root:Dequeue
INFO:root:Queued request
INFO:root:Dequeue
INFO:root:Queued request
INFO:root:Queued request
INFO:root:Queued request
INFO:root:Queued request
INFO:root:Queued request
INFO:root:Queued request
INFO:root:Queued request
INFO:root:Queued request
INFO:root:Queued request
INFO:root:Dequeue
INFO:root:Queued request
INFO:root:Queued request
INFO:root:Queued request
INFO:root:Dequeue
INFO:root:Queued request
INFO:root:Dequeue
INFO:root:Queued request
INFO:root:Dequeue
INFO:root:Queued request
INFO:root:Dequeue
INFO:root:Queued request
INFO:root:Dequeue
INFO:root:Queued request
INFO:root:Queued request
INFO:root:Queued request
INFO:root:Queued request
INFO:root:Queued request
INFO:root:Queued request
INFO:root:Queued request
INFO:root:Queued request
INFO:root:Queued request
INFO:root:Queued request
INFO:root:Queued request
INFO:root:Queued request
INFO:root:Dequeue
INFO:root:Queued request
INFO:root:Queued request
INFO:werkzeug: * Running on http://127.0.0.1:5000/ (Press CTRL+C to quit)
INFO:werkzeug: * Restarting with stat
